[Mon Oct 30 17:15:27.103621 2023] [wsgi:error] [pid 19844:tid 1224] [client 127.0.0.1:58549] Not Found: /favicon.ico\r, referer: http://127.0.0.1:90/
[Mon Oct 30 17:30:56.209648 2023] [wsgi:error] [pid 23180:tid 1196] [client ::1:59706] Not Found: /favicon.ico\r, referer: http://localhost:90/
[Mon Oct 30 17:46:15.966180 2023] [authz_core:error] [pid 22244:tid 1268] [client ::1:61668] AH01630: client denied by server configuration: D:/Kuldeep(Python)/Project/piinfo/staticflies, referer: http://localhost:90/admin/auth/user/
[Mon Oct 30 17:46:15.974180 2023] [authz_core:error] [pid 22244:tid 1268] [client ::1:61668] AH01630: client denied by server configuration: D:/Kuldeep(Python)/Project/piinfo/staticflies, referer: http://localhost:90/admin/auth/user/
[Mon Oct 30 17:46:15.974180 2023] [authz_core:error] [pid 22244:tid 1248] [client ::1:61671] AH01630: client denied by server configuration: D:/Kuldeep(Python)/Project/piinfo/staticflies, referer: http://localhost:90/admin/auth/user/
[Mon Oct 30 17:46:15.974180 2023] [authz_core:error] [pid 22244:tid 1256] [client ::1:61670] AH01630: client denied by server configuration: D:/Kuldeep(Python)/Project/piinfo/staticflies, referer: http://localhost:90/admin/auth/user/
[Mon Oct 30 17:46:15.974180 2023] [authz_core:error] [pid 22244:tid 1240] [client ::1:61672] AH01630: client denied by server configuration: D:/Kuldeep(Python)/Project/piinfo/staticflies, referer: http://localhost:90/admin/auth/user/
[Mon Oct 30 17:46:15.974180 2023] [authz_core:error] [pid 22244:tid 1232] [client ::1:61673] AH01630: client denied by server configuration: D:/Kuldeep(Python)/Project/piinfo/staticflies, referer: http://localhost:90/admin/auth/user/
[Mon Oct 30 17:46:15.995180 2023] [authz_core:error] [pid 22244:tid 1240] [client ::1:61672] AH01630: client denied by server configuration: D:/Kuldeep(Python)/Project/piinfo/staticflies, referer: http://localhost:90/admin/auth/user/
[Mon Oct 30 17:46:15.995180 2023] [authz_core:error] [pid 22244:tid 1248] [client ::1:61671] AH01630: client denied by server configuration: D:/Kuldeep(Python)/Project/piinfo/staticflies, referer: http://localhost:90/admin/auth/user/
[Mon Oct 30 17:46:15.995180 2023] [authz_core:error] [pid 22244:tid 1256] [client ::1:61670] AH01630: client denied by server configuration: D:/Kuldeep(Python)/Project/piinfo/staticflies, referer: http://localhost:90/admin/auth/user/
[Mon Oct 30 17:46:15.996178 2023] [authz_core:error] [pid 22244:tid 1268] [client ::1:61668] AH01630: client denied by server configuration: D:/Kuldeep(Python)/Project/piinfo/staticflies, referer: http://localhost:90/admin/auth/user/
[Mon Oct 30 17:46:15.996178 2023] [authz_core:error] [pid 22244:tid 1232] [client ::1:61673] AH01630: client denied by server configuration: D:/Kuldeep(Python)/Project/piinfo/staticflies, referer: http://localhost:90/admin/auth/user/
[Mon Oct 30 17:46:16.001187 2023] [authz_core:error] [pid 22244:tid 1268] [client ::1:61668] AH01630: client denied by server configuration: D:/Kuldeep(Python)/Project/piinfo/staticflies, referer: http://localhost:90/admin/auth/user/
[Mon Oct 30 17:46:16.001187 2023] [authz_core:error] [pid 22244:tid 1232] [client ::1:61673] AH01630: client denied by server configuration: D:/Kuldeep(Python)/Project/piinfo/staticflies, referer: http://localhost:90/admin/auth/user/
[Mon Oct 30 17:46:16.039209 2023] [authz_core:error] [pid 22244:tid 1264] [client ::1:61669] AH01630: client denied by server configuration: D:/Kuldeep(Python)/Project/piinfo/staticflies, referer: http://localhost:90/admin/auth/user/
[Mon Oct 30 17:47:24.510187 2023] [authz_core:error] [pid 7972:tid 1236] [client ::1:61731] AH01630: client denied by server configuration: D:/Kuldeep(Python)/Project/piinfo/staticflies, referer: http://localhost:90/
[Mon Oct 30 17:47:24.517178 2023] [authz_core:error] [pid 7972:tid 1236] [client ::1:61731] AH01630: client denied by server configuration: D:/Kuldeep(Python)/Project/piinfo/staticflies, referer: http://localhost:90/
[Mon Oct 30 17:47:24.524179 2023] [authz_core:error] [pid 7972:tid 1224] [client ::1:61732] AH01630: client denied by server configuration: D:/Kuldeep(Python)/Project/piinfo/staticflies, referer: http://localhost:90/
[Mon Oct 30 17:47:24.527219 2023] [authz_core:error] [pid 7972:tid 1236] [client ::1:61731] AH01630: client denied by server configuration: D:/Kuldeep(Python)/Project/piinfo/staticflies, referer: http://localhost:90/
[Mon Oct 30 17:47:24.528179 2023] [authz_core:error] [pid 7972:tid 1220] [client ::1:61733] AH01630: client denied by server configuration: D:/Kuldeep(Python)/Project/piinfo/staticflies, referer: http://localhost:90/
[Mon Oct 30 17:47:24.528179 2023] [authz_core:error] [pid 7972:tid 1200] [client ::1:61736] AH01630: client denied by server configuration: D:/Kuldeep(Python)/Project/piinfo/staticflies, referer: http://localhost:90/
[Mon Oct 30 17:47:24.530178 2023] [authz_core:error] [pid 7972:tid 1216] [client ::1:61734] AH01630: client denied by server configuration: D:/Kuldeep(Python)/Project/piinfo/staticflies, referer: http://localhost:90/
[Mon Oct 30 17:47:24.530178 2023] [authz_core:error] [pid 7972:tid 1208] [client ::1:61735] AH01630: client denied by server configuration: D:/Kuldeep(Python)/Project/piinfo/staticflies, referer: http://localhost:90/
[Mon Oct 30 17:47:24.536179 2023] [authz_core:error] [pid 7972:tid 1220] [client ::1:61733] AH01630: client denied by server configuration: D:/Kuldeep(Python)/Project/piinfo/staticflies, referer: http://localhost:90/
[Mon Oct 30 17:47:24.537188 2023] [authz_core:error] [pid 7972:tid 1208] [client ::1:61735] AH01630: client denied by server configuration: D:/Kuldeep(Python)/Project/piinfo/staticflies, referer: http://localhost:90/
[Mon Oct 30 17:47:24.537188 2023] [authz_core:error] [pid 7972:tid 1216] [client ::1:61734] AH01630: client denied by server configuration: D:/Kuldeep(Python)/Project/piinfo/staticflies, referer: http://localhost:90/
[Mon Oct 30 17:47:24.537188 2023] [authz_core:error] [pid 7972:tid 1200] [client ::1:61736] AH01630: client denied by server configuration: D:/Kuldeep(Python)/Project/piinfo/staticflies, referer: http://localhost:90/
[Mon Oct 30 17:47:24.538181 2023] [authz_core:error] [pid 7972:tid 1236] [client ::1:61731] AH01630: client denied by server configuration: D:/Kuldeep(Python)/Project/piinfo/staticflies, referer: http://localhost:90/
[Mon Oct 30 17:47:24.541191 2023] [authz_core:error] [pid 7972:tid 1200] [client ::1:61736] AH01630: client denied by server configuration: D:/Kuldeep(Python)/Project/piinfo/staticflies, referer: http://localhost:90/
[Mon Oct 30 17:47:24.541191 2023] [authz_core:error] [pid 7972:tid 1216] [client ::1:61734] AH01630: client denied by server configuration: D:/Kuldeep(Python)/Project/piinfo/staticflies, referer: http://localhost:90/
[Mon Oct 30 17:47:24.542179 2023] [authz_core:error] [pid 7972:tid 1208] [client ::1:61735] AH01630: client denied by server configuration: D:/Kuldeep(Python)/Project/piinfo/staticflies, referer: http://localhost:90/
[Mon Oct 30 17:47:24.542179 2023] [authz_core:error] [pid 7972:tid 1236] [client ::1:61731] AH01630: client denied by server configuration: D:/Kuldeep(Python)/Project/piinfo/staticflies, referer: http://localhost:90/
[Mon Oct 30 17:47:24.545180 2023] [authz_core:error] [pid 7972:tid 1208] [client ::1:61735] AH01630: client denied by server configuration: D:/Kuldeep(Python)/Project/piinfo/staticflies, referer: http://localhost:90/
[Mon Oct 30 17:47:24.545180 2023] [authz_core:error] [pid 7972:tid 1236] [client ::1:61731] AH01630: client denied by server configuration: D:/Kuldeep(Python)/Project/piinfo/staticflies, referer: http://localhost:90/
[Mon Oct 30 17:47:24.546183 2023] [authz_core:error] [pid 7972:tid 1216] [client ::1:61734] AH01630: client denied by server configuration: D:/Kuldeep(Python)/Project/piinfo/staticflies, referer: http://localhost:90/
[Mon Oct 30 17:47:24.546183 2023] [authz_core:error] [pid 7972:tid 1200] [client ::1:61736] AH01630: client denied by server configuration: D:/Kuldeep(Python)/Project/piinfo/staticflies, referer: http://localhost:90/
[Mon Oct 30 17:47:24.549212 2023] [authz_core:error] [pid 7972:tid 1216] [client ::1:61734] AH01630: client denied by server configuration: D:/Kuldeep(Python)/Project/piinfo/staticflies, referer: http://localhost:90/
[Mon Oct 30 17:47:24.550179 2023] [authz_core:error] [pid 7972:tid 1200] [client ::1:61736] AH01630: client denied by server configuration: D:/Kuldeep(Python)/Project/piinfo/staticflies, referer: http://localhost:90/
[Mon Oct 30 17:47:24.550179 2023] [authz_core:error] [pid 7972:tid 1236] [client ::1:61731] AH01630: client denied by server configuration: D:/Kuldeep(Python)/Project/piinfo/staticflies, referer: http://localhost:90/
[Mon Oct 30 17:47:24.550179 2023] [authz_core:error] [pid 7972:tid 1208] [client ::1:61735] AH01630: client denied by server configuration: D:/Kuldeep(Python)/Project/piinfo/staticflies, referer: http://localhost:90/
[Mon Oct 30 17:47:24.553247 2023] [authz_core:error] [pid 7972:tid 1216] [client ::1:61734] AH01630: client denied by server configuration: D:/Kuldeep(Python)/Project/piinfo/staticflies, referer: http://localhost:90/
[Mon Oct 30 17:47:24.555178 2023] [authz_core:error] [pid 7972:tid 1208] [client ::1:61735] AH01630: client denied by server configuration: D:/Kuldeep(Python)/Project/piinfo/staticflies, referer: http://localhost:90/
[Mon Oct 30 17:47:24.555178 2023] [authz_core:error] [pid 7972:tid 1236] [client ::1:61731] AH01630: client denied by server configuration: D:/Kuldeep(Python)/Project/piinfo/staticflies, referer: http://localhost:90/
[Mon Oct 30 17:47:24.555178 2023] [authz_core:error] [pid 7972:tid 1200] [client ::1:61736] AH01630: client denied by server configuration: D:/Kuldeep(Python)/Project/piinfo/staticflies, referer: http://localhost:90/
[Mon Oct 30 17:47:24.558178 2023] [authz_core:error] [pid 7972:tid 1236] [client ::1:61731] AH01630: client denied by server configuration: D:/Kuldeep(Python)/Project/piinfo/staticflies, referer: http://localhost:90/
[Mon Oct 30 17:47:24.559186 2023] [authz_core:error] [pid 7972:tid 1236] [client ::1:61731] AH01630: client denied by server configuration: D:/Kuldeep(Python)/Project/piinfo/staticflies, referer: http://localhost:90/
[Mon Oct 30 17:47:24.561179 2023] [authz_core:error] [pid 7972:tid 1236] [client ::1:61731] AH01630: client denied by server configuration: D:/Kuldeep(Python)/Project/piinfo/staticflies, referer: http://localhost:90/
[Mon Oct 30 17:47:24.562179 2023] [authz_core:error] [pid 7972:tid 1236] [client ::1:61731] AH01630: client denied by server configuration: D:/Kuldeep(Python)/Project/piinfo/staticflies, referer: http://localhost:90/
[Mon Oct 30 17:47:24.564178 2023] [authz_core:error] [pid 7972:tid 1236] [client ::1:61731] AH01630: client denied by server configuration: D:/Kuldeep(Python)/Project/piinfo/staticflies, referer: http://localhost:90/
[Mon Oct 30 17:47:24.565178 2023] [authz_core:error] [pid 7972:tid 1236] [client ::1:61731] AH01630: client denied by server configuration: D:/Kuldeep(Python)/Project/piinfo/staticflies, referer: http://localhost:90/
[Mon Oct 30 17:55:13.159178 2023] [wsgi:error] [pid 13608:tid 1204] [client ::1:62191] Not Found: /favicon.ico\r, referer: http://localhost:90/
[Tue Oct 31 11:12:43.312981 2023] [wsgi:error] [pid 5736:tid 1224] [client ::1:51034] Not Found: /favicon.ico\r, referer: http://localhost:90/
[Tue Oct 31 11:13:26.558979 2023] [wsgi:error] [pid 5736:tid 1224] [client ::1:51051] teja partap singh \r, referer: http://localhost:90/records/henquiry
[Tue Oct 31 11:13:26.558979 2023] [wsgi:error] [pid 5736:tid 1224] [client ::1:51051] \r, referer: http://localhost:90/records/henquiry
[Tue Oct 31 11:13:26.558979 2023] [wsgi:error] [pid 5736:tid 1224] [client ::1:51051] \r, referer: http://localhost:90/records/henquiry
[Tue Oct 31 11:13:26.558979 2023] [wsgi:error] [pid 5736:tid 1224] [client ::1:51051] \r, referer: http://localhost:90/records/henquiry
[Tue Oct 31 11:13:26.558979 2023] [wsgi:error] [pid 5736:tid 1224] [client ::1:51051] \r, referer: http://localhost:90/records/henquiry
[Tue Oct 31 11:26:50.200282 2023] [wsgi:error] [pid 6492:tid 1196] [client 192.168.6.251:51363] Not Found: /favicon.ico\r, referer: http://192.168.6.251:90/
[Tue Oct 31 11:30:06.493256 2023] [wsgi:error] [pid 20320:tid 1268] [client 192.168.6.251:51516] Invalid HTTP_HOST header: '192.168.6.251:90'. You may need to add '192.168.6.251' to ALLOWED_HOSTS.\r
[Tue Oct 31 11:30:06.494233 2023] [wsgi:error] [pid 20320:tid 1268] [client 192.168.6.251:51516] Traceback (most recent call last):\r
[Tue Oct 31 11:30:06.494233 2023] [wsgi:error] [pid 20320:tid 1268] [client 192.168.6.251:51516]   File "D:\\Kuldeep(Python)\\Project\\env\\Lib\\site-packages\\django\\core\\handlers\\exception.py", line 55, in inner\r
[Tue Oct 31 11:30:06.494233 2023] [wsgi:error] [pid 20320:tid 1268] [client 192.168.6.251:51516]     response = get_response(request)\r
[Tue Oct 31 11:30:06.494233 2023] [wsgi:error] [pid 20320:tid 1268] [client 192.168.6.251:51516]                ^^^^^^^^^^^^^^^^^^^^^\r
[Tue Oct 31 11:30:06.494233 2023] [wsgi:error] [pid 20320:tid 1268] [client 192.168.6.251:51516]   File "D:\\Kuldeep(Python)\\Project\\env\\Lib\\site-packages\\django\\utils\\deprecation.py", line 133, in __call__\r
[Tue Oct 31 11:30:06.494233 2023] [wsgi:error] [pid 20320:tid 1268] [client 192.168.6.251:51516]     response = self.process_request(request)\r
[Tue Oct 31 11:30:06.494233 2023] [wsgi:error] [pid 20320:tid 1268] [client 192.168.6.251:51516]                ^^^^^^^^^^^^^^^^^^^^^^^^^^^^^\r
[Tue Oct 31 11:30:06.494233 2023] [wsgi:error] [pid 20320:tid 1268] [client 192.168.6.251:51516]   File "D:\\Kuldeep(Python)\\Project\\env\\Lib\\site-packages\\django\\middleware\\common.py", line 48, in process_request\r
[Tue Oct 31 11:30:06.494233 2023] [wsgi:error] [pid 20320:tid 1268] [client 192.168.6.251:51516]     host = request.get_host()\r
[Tue Oct 31 11:30:06.494233 2023] [wsgi:error] [pid 20320:tid 1268] [client 192.168.6.251:51516]            ^^^^^^^^^^^^^^^^^^\r
[Tue Oct 31 11:30:06.494233 2023] [wsgi:error] [pid 20320:tid 1268] [client 192.168.6.251:51516]   File "D:\\Kuldeep(Python)\\Project\\env\\Lib\\site-packages\\django\\http\\request.py", line 150, in get_host\r
[Tue Oct 31 11:30:06.494233 2023] [wsgi:error] [pid 20320:tid 1268] [client 192.168.6.251:51516]     raise DisallowedHost(msg)\r
[Tue Oct 31 11:30:06.494233 2023] [wsgi:error] [pid 20320:tid 1268] [client 192.168.6.251:51516] django.core.exceptions.DisallowedHost: Invalid HTTP_HOST header: '192.168.6.251:90'. You may need to add '192.168.6.251' to ALLOWED_HOSTS.\r
[Tue Oct 31 11:30:06.622232 2023] [wsgi:error] [pid 20320:tid 1268] [client 192.168.6.251:51516] Bad Request: /\r
[Tue Oct 31 11:42:33.698344 2023] [wsgi:error] [pid 19168:tid 1256] [client 192.168.6.251:52110] Not Found: /favicon.ico\r, referer: http://192.168.6.251:8051/
[Tue Oct 31 13:28:48.503358 2023] [wsgi:error] [pid 2360:tid 1216] [client 192.168.6.251:55414] Not Found: /favicon.ico\r, referer: http://192.168.6.251:90/
[Wed Nov 01 14:34:25.775938 2023] [wsgi:error] [pid 5848:tid 1204] [client ::1:53303] Not Found: /favicon.ico\r, referer: http://localhost:90/
[Wed Nov 01 14:35:25.601916 2023] [wsgi:error] [pid 5848:tid 1232] [client 192.168.6.251:53361] Not Found: /favicon.ico\r, referer: http://192.168.6.251:90/
[Thu Nov 02 13:07:24.409969 2023] [wsgi:error] [pid 5928:tid 1248] [client 192.168.6.251:63744] Invalid HTTP_HOST header: '192.168.6.251:90'. You may need to add '192.168.6.251' to ALLOWED_HOSTS.\r
[Thu Nov 02 13:07:24.421926 2023] [wsgi:error] [pid 5928:tid 1248] [client 192.168.6.251:63744] Traceback (most recent call last):\r
[Thu Nov 02 13:07:24.421926 2023] [wsgi:error] [pid 5928:tid 1248] [client 192.168.6.251:63744]   File "D:\\Kuldeep(Python)\\Project\\env\\Lib\\site-packages\\django\\core\\handlers\\exception.py", line 55, in inner\r
[Thu Nov 02 13:07:24.421926 2023] [wsgi:error] [pid 5928:tid 1248] [client 192.168.6.251:63744]     response = get_response(request)\r
[Thu Nov 02 13:07:24.421926 2023] [wsgi:error] [pid 5928:tid 1248] [client 192.168.6.251:63744]                ^^^^^^^^^^^^^^^^^^^^^\r
[Thu Nov 02 13:07:24.421926 2023] [wsgi:error] [pid 5928:tid 1248] [client 192.168.6.251:63744]   File "D:\\Kuldeep(Python)\\Project\\env\\Lib\\site-packages\\django\\utils\\deprecation.py", line 133, in __call__\r
[Thu Nov 02 13:07:24.421926 2023] [wsgi:error] [pid 5928:tid 1248] [client 192.168.6.251:63744]     response = self.process_request(request)\r
[Thu Nov 02 13:07:24.421926 2023] [wsgi:error] [pid 5928:tid 1248] [client 192.168.6.251:63744]                ^^^^^^^^^^^^^^^^^^^^^^^^^^^^^\r
[Thu Nov 02 13:07:24.421926 2023] [wsgi:error] [pid 5928:tid 1248] [client 192.168.6.251:63744]   File "D:\\Kuldeep(Python)\\Project\\env\\Lib\\site-packages\\django\\middleware\\common.py", line 48, in process_request\r
[Thu Nov 02 13:07:24.421926 2023] [wsgi:error] [pid 5928:tid 1248] [client 192.168.6.251:63744]     host = request.get_host()\r
[Thu Nov 02 13:07:24.421926 2023] [wsgi:error] [pid 5928:tid 1248] [client 192.168.6.251:63744]            ^^^^^^^^^^^^^^^^^^\r
[Thu Nov 02 13:07:24.421926 2023] [wsgi:error] [pid 5928:tid 1248] [client 192.168.6.251:63744]   File "D:\\Kuldeep(Python)\\Project\\env\\Lib\\site-packages\\django\\http\\request.py", line 150, in get_host\r
[Thu Nov 02 13:07:24.421926 2023] [wsgi:error] [pid 5928:tid 1248] [client 192.168.6.251:63744]     raise DisallowedHost(msg)\r
[Thu Nov 02 13:07:24.421926 2023] [wsgi:error] [pid 5928:tid 1248] [client 192.168.6.251:63744] django.core.exceptions.DisallowedHost: Invalid HTTP_HOST header: '192.168.6.251:90'. You may need to add '192.168.6.251' to ALLOWED_HOSTS.\r
[Thu Nov 02 13:07:24.845949 2023] [wsgi:error] [pid 5928:tid 1248] [client 192.168.6.251:63744] Bad Request: /\r
[Thu Nov 02 13:07:24.857952 2023] [wsgi:error] [pid 5928:tid 1240] [client 192.168.6.251:63750] Invalid HTTP_HOST header: '192.168.6.251:90'. You may need to add '192.168.6.251' to ALLOWED_HOSTS.\r
[Thu Nov 02 13:07:24.857952 2023] [wsgi:error] [pid 5928:tid 1240] [client 192.168.6.251:63750] Traceback (most recent call last):\r
[Thu Nov 02 13:07:24.857952 2023] [wsgi:error] [pid 5928:tid 1240] [client 192.168.6.251:63750]   File "D:\\Kuldeep(Python)\\Project\\env\\Lib\\site-packages\\django\\core\\handlers\\exception.py", line 55, in inner\r
[Thu Nov 02 13:07:24.857952 2023] [wsgi:error] [pid 5928:tid 1240] [client 192.168.6.251:63750]     response = get_response(request)\r
[Thu Nov 02 13:07:24.857952 2023] [wsgi:error] [pid 5928:tid 1240] [client 192.168.6.251:63750]                ^^^^^^^^^^^^^^^^^^^^^\r
[Thu Nov 02 13:07:24.857952 2023] [wsgi:error] [pid 5928:tid 1240] [client 192.168.6.251:63750]   File "D:\\Kuldeep(Python)\\Project\\env\\Lib\\site-packages\\django\\utils\\deprecation.py", line 133, in __call__\r
[Thu Nov 02 13:07:24.857952 2023] [wsgi:error] [pid 5928:tid 1240] [client 192.168.6.251:63750]     response = self.process_request(request)\r
[Thu Nov 02 13:07:24.857952 2023] [wsgi:error] [pid 5928:tid 1240] [client 192.168.6.251:63750]                ^^^^^^^^^^^^^^^^^^^^^^^^^^^^^\r
[Thu Nov 02 13:07:24.857952 2023] [wsgi:error] [pid 5928:tid 1240] [client 192.168.6.251:63750]   File "D:\\Kuldeep(Python)\\Project\\env\\Lib\\site-packages\\django\\middleware\\common.py", line 48, in process_request\r
[Thu Nov 02 13:07:24.857952 2023] [wsgi:error] [pid 5928:tid 1240] [client 192.168.6.251:63750]     host = request.get_host()\r
[Thu Nov 02 13:07:24.857952 2023] [wsgi:error] [pid 5928:tid 1240] [client 192.168.6.251:63750]            ^^^^^^^^^^^^^^^^^^\r
[Thu Nov 02 13:07:24.857952 2023] [wsgi:error] [pid 5928:tid 1240] [client 192.168.6.251:63750]   File "D:\\Kuldeep(Python)\\Project\\env\\Lib\\site-packages\\django\\http\\request.py", line 150, in get_host\r
[Thu Nov 02 13:07:24.857952 2023] [wsgi:error] [pid 5928:tid 1240] [client 192.168.6.251:63750]     raise DisallowedHost(msg)\r
[Thu Nov 02 13:07:24.857952 2023] [wsgi:error] [pid 5928:tid 1240] [client 192.168.6.251:63750] django.core.exceptions.DisallowedHost: Invalid HTTP_HOST header: '192.168.6.251:90'. You may need to add '192.168.6.251' to ALLOWED_HOSTS.\r
[Thu Nov 02 13:07:24.891970 2023] [wsgi:error] [pid 5928:tid 1240] [client 192.168.6.251:63750] Bad Request: /\r
[Thu Nov 02 13:07:25.198922 2023] [wsgi:error] [pid 5928:tid 1220] [client 192.168.6.251:63751] Invalid HTTP_HOST header: '192.168.6.251:90'. You may need to add '192.168.6.251' to ALLOWED_HOSTS.\r, referer: http://192.168.6.251:90/
[Thu Nov 02 13:07:25.198922 2023] [wsgi:error] [pid 5928:tid 1220] [client 192.168.6.251:63751] Traceback (most recent call last):\r, referer: http://192.168.6.251:90/
[Thu Nov 02 13:07:25.198922 2023] [wsgi:error] [pid 5928:tid 1220] [client 192.168.6.251:63751]   File "D:\\Kuldeep(Python)\\Project\\env\\Lib\\site-packages\\django\\core\\handlers\\exception.py", line 55, in inner\r, referer: http://192.168.6.251:90/
[Thu Nov 02 13:07:25.198922 2023] [wsgi:error] [pid 5928:tid 1220] [client 192.168.6.251:63751]     response = get_response(request)\r, referer: http://192.168.6.251:90/
[Thu Nov 02 13:07:25.198922 2023] [wsgi:error] [pid 5928:tid 1220] [client 192.168.6.251:63751]                ^^^^^^^^^^^^^^^^^^^^^\r, referer: http://192.168.6.251:90/
[Thu Nov 02 13:07:25.198922 2023] [wsgi:error] [pid 5928:tid 1220] [client 192.168.6.251:63751]   File "D:\\Kuldeep(Python)\\Project\\env\\Lib\\site-packages\\django\\utils\\deprecation.py", line 133, in __call__\r, referer: http://192.168.6.251:90/
[Thu Nov 02 13:07:25.198922 2023] [wsgi:error] [pid 5928:tid 1220] [client 192.168.6.251:63751]     response = self.process_request(request)\r, referer: http://192.168.6.251:90/
[Thu Nov 02 13:07:25.198922 2023] [wsgi:error] [pid 5928:tid 1220] [client 192.168.6.251:63751]                ^^^^^^^^^^^^^^^^^^^^^^^^^^^^^\r, referer: http://192.168.6.251:90/
[Thu Nov 02 13:07:25.198922 2023] [wsgi:error] [pid 5928:tid 1220] [client 192.168.6.251:63751]   File "D:\\Kuldeep(Python)\\Project\\env\\Lib\\site-packages\\django\\middleware\\common.py", line 48, in process_request\r, referer: http://192.168.6.251:90/
[Thu Nov 02 13:07:25.198922 2023] [wsgi:error] [pid 5928:tid 1220] [client 192.168.6.251:63751]     host = request.get_host()\r, referer: http://192.168.6.251:90/
[Thu Nov 02 13:07:25.198922 2023] [wsgi:error] [pid 5928:tid 1220] [client 192.168.6.251:63751]            ^^^^^^^^^^^^^^^^^^\r, referer: http://192.168.6.251:90/
[Thu Nov 02 13:07:25.198922 2023] [wsgi:error] [pid 5928:tid 1220] [client 192.168.6.251:63751]   File "D:\\Kuldeep(Python)\\Project\\env\\Lib\\site-packages\\django\\http\\request.py", line 150, in get_host\r, referer: http://192.168.6.251:90/
[Thu Nov 02 13:07:25.198922 2023] [wsgi:error] [pid 5928:tid 1220] [client 192.168.6.251:63751]     raise DisallowedHost(msg)\r, referer: http://192.168.6.251:90/
[Thu Nov 02 13:07:25.198922 2023] [wsgi:error] [pid 5928:tid 1220] [client 192.168.6.251:63751] django.core.exceptions.DisallowedHost: Invalid HTTP_HOST header: '192.168.6.251:90'. You may need to add '192.168.6.251' to ALLOWED_HOSTS.\r, referer: http://192.168.6.251:90/
[Thu Nov 02 13:07:25.234944 2023] [wsgi:error] [pid 5928:tid 1220] [client 192.168.6.251:63751] Bad Request: /favicon.ico\r, referer: http://192.168.6.251:90/
[Thu Nov 02 13:08:57.335971 2023] [wsgi:error] [pid 5928:tid 1220] [client 192.168.6.251:63933] Invalid HTTP_HOST header: '192.168.6.251:90'. You may need to add '192.168.6.251' to ALLOWED_HOSTS.\r
[Thu Nov 02 13:08:57.335971 2023] [wsgi:error] [pid 5928:tid 1220] [client 192.168.6.251:63933] Traceback (most recent call last):\r
[Thu Nov 02 13:08:57.335971 2023] [wsgi:error] [pid 5928:tid 1220] [client 192.168.6.251:63933]   File "D:\\Kuldeep(Python)\\Project\\env\\Lib\\site-packages\\django\\core\\handlers\\exception.py", line 55, in inner\r
[Thu Nov 02 13:08:57.335971 2023] [wsgi:error] [pid 5928:tid 1220] [client 192.168.6.251:63933]     response = get_response(request)\r
[Thu Nov 02 13:08:57.335971 2023] [wsgi:error] [pid 5928:tid 1220] [client 192.168.6.251:63933]                ^^^^^^^^^^^^^^^^^^^^^\r
[Thu Nov 02 13:08:57.335971 2023] [wsgi:error] [pid 5928:tid 1220] [client 192.168.6.251:63933]   File "D:\\Kuldeep(Python)\\Project\\env\\Lib\\site-packages\\django\\utils\\deprecation.py", line 133, in __call__\r
[Thu Nov 02 13:08:57.335971 2023] [wsgi:error] [pid 5928:tid 1220] [client 192.168.6.251:63933]     response = self.process_request(request)\r
[Thu Nov 02 13:08:57.335971 2023] [wsgi:error] [pid 5928:tid 1220] [client 192.168.6.251:63933]                ^^^^^^^^^^^^^^^^^^^^^^^^^^^^^\r
[Thu Nov 02 13:08:57.335971 2023] [wsgi:error] [pid 5928:tid 1220] [client 192.168.6.251:63933]   File "D:\\Kuldeep(Python)\\Project\\env\\Lib\\site-packages\\django\\middleware\\common.py", line 48, in process_request\r
[Thu Nov 02 13:08:57.335971 2023] [wsgi:error] [pid 5928:tid 1220] [client 192.168.6.251:63933]     host = request.get_host()\r
[Thu Nov 02 13:08:57.335971 2023] [wsgi:error] [pid 5928:tid 1220] [client 192.168.6.251:63933]            ^^^^^^^^^^^^^^^^^^\r
[Thu Nov 02 13:08:57.335971 2023] [wsgi:error] [pid 5928:tid 1220] [client 192.168.6.251:63933]   File "D:\\Kuldeep(Python)\\Project\\env\\Lib\\site-packages\\django\\http\\request.py", line 150, in get_host\r
[Thu Nov 02 13:08:57.335971 2023] [wsgi:error] [pid 5928:tid 1220] [client 192.168.6.251:63933]     raise DisallowedHost(msg)\r
[Thu Nov 02 13:08:57.335971 2023] [wsgi:error] [pid 5928:tid 1220] [client 192.168.6.251:63933] django.core.exceptions.DisallowedHost: Invalid HTTP_HOST header: '192.168.6.251:90'. You may need to add '192.168.6.251' to ALLOWED_HOSTS.\r
[Thu Nov 02 13:08:57.371939 2023] [wsgi:error] [pid 5928:tid 1220] [client 192.168.6.251:63933] Bad Request: /\r
[Thu Nov 02 13:08:57.504922 2023] [wsgi:error] [pid 5928:tid 1240] [client 192.168.6.251:63934] Invalid HTTP_HOST header: '192.168.6.251:90'. You may need to add '192.168.6.251' to ALLOWED_HOSTS.\r, referer: http://192.168.6.251:90/
[Thu Nov 02 13:08:57.504922 2023] [wsgi:error] [pid 5928:tid 1240] [client 192.168.6.251:63934] Traceback (most recent call last):\r, referer: http://192.168.6.251:90/
[Thu Nov 02 13:08:57.504922 2023] [wsgi:error] [pid 5928:tid 1240] [client 192.168.6.251:63934]   File "D:\\Kuldeep(Python)\\Project\\env\\Lib\\site-packages\\django\\core\\handlers\\exception.py", line 55, in inner\r, referer: http://192.168.6.251:90/
[Thu Nov 02 13:08:57.504922 2023] [wsgi:error] [pid 5928:tid 1240] [client 192.168.6.251:63934]     response = get_response(request)\r, referer: http://192.168.6.251:90/
[Thu Nov 02 13:08:57.504922 2023] [wsgi:error] [pid 5928:tid 1240] [client 192.168.6.251:63934]                ^^^^^^^^^^^^^^^^^^^^^\r, referer: http://192.168.6.251:90/
[Thu Nov 02 13:08:57.504922 2023] [wsgi:error] [pid 5928:tid 1240] [client 192.168.6.251:63934]   File "D:\\Kuldeep(Python)\\Project\\env\\Lib\\site-packages\\django\\utils\\deprecation.py", line 133, in __call__\r, referer: http://192.168.6.251:90/
[Thu Nov 02 13:08:57.504922 2023] [wsgi:error] [pid 5928:tid 1240] [client 192.168.6.251:63934]     response = self.process_request(request)\r, referer: http://192.168.6.251:90/
[Thu Nov 02 13:08:57.504922 2023] [wsgi:error] [pid 5928:tid 1240] [client 192.168.6.251:63934]                ^^^^^^^^^^^^^^^^^^^^^^^^^^^^^\r, referer: http://192.168.6.251:90/
[Thu Nov 02 13:08:57.504922 2023] [wsgi:error] [pid 5928:tid 1240] [client 192.168.6.251:63934]   File "D:\\Kuldeep(Python)\\Project\\env\\Lib\\site-packages\\django\\middleware\\common.py", line 48, in process_request\r, referer: http://192.168.6.251:90/
[Thu Nov 02 13:08:57.504922 2023] [wsgi:error] [pid 5928:tid 1240] [client 192.168.6.251:63934]     host = request.get_host()\r, referer: http://192.168.6.251:90/
[Thu Nov 02 13:08:57.504922 2023] [wsgi:error] [pid 5928:tid 1240] [client 192.168.6.251:63934]            ^^^^^^^^^^^^^^^^^^\r, referer: http://192.168.6.251:90/
[Thu Nov 02 13:08:57.504922 2023] [wsgi:error] [pid 5928:tid 1240] [client 192.168.6.251:63934]   File "D:\\Kuldeep(Python)\\Project\\env\\Lib\\site-packages\\django\\http\\request.py", line 150, in get_host\r, referer: http://192.168.6.251:90/
[Thu Nov 02 13:08:57.504922 2023] [wsgi:error] [pid 5928:tid 1240] [client 192.168.6.251:63934]     raise DisallowedHost(msg)\r, referer: http://192.168.6.251:90/
[Thu Nov 02 13:08:57.504922 2023] [wsgi:error] [pid 5928:tid 1240] [client 192.168.6.251:63934] django.core.exceptions.DisallowedHost: Invalid HTTP_HOST header: '192.168.6.251:90'. You may need to add '192.168.6.251' to ALLOWED_HOSTS.\r, referer: http://192.168.6.251:90/
[Thu Nov 02 13:08:57.539967 2023] [wsgi:error] [pid 5928:tid 1240] [client 192.168.6.251:63934] Bad Request: /favicon.ico\r, referer: http://192.168.6.251:90/
[Thu Nov 02 13:09:00.992927 2023] [wsgi:error] [pid 5928:tid 1240] [client 192.168.6.251:63940] Invalid HTTP_HOST header: '192.168.6.251:90'. You may need to add '192.168.6.251' to ALLOWED_HOSTS.\r
[Thu Nov 02 13:09:00.992927 2023] [wsgi:error] [pid 5928:tid 1240] [client 192.168.6.251:63940] Traceback (most recent call last):\r
[Thu Nov 02 13:09:00.992927 2023] [wsgi:error] [pid 5928:tid 1240] [client 192.168.6.251:63940]   File "D:\\Kuldeep(Python)\\Project\\env\\Lib\\site-packages\\django\\core\\handlers\\exception.py", line 55, in inner\r
[Thu Nov 02 13:09:00.992927 2023] [wsgi:error] [pid 5928:tid 1240] [client 192.168.6.251:63940]     response = get_response(request)\r
[Thu Nov 02 13:09:00.992927 2023] [wsgi:error] [pid 5928:tid 1240] [client 192.168.6.251:63940]                ^^^^^^^^^^^^^^^^^^^^^\r
[Thu Nov 02 13:09:00.992927 2023] [wsgi:error] [pid 5928:tid 1240] [client 192.168.6.251:63940]   File "D:\\Kuldeep(Python)\\Project\\env\\Lib\\site-packages\\django\\utils\\deprecation.py", line 133, in __call__\r
[Thu Nov 02 13:09:00.992927 2023] [wsgi:error] [pid 5928:tid 1240] [client 192.168.6.251:63940]     response = self.process_request(request)\r
[Thu Nov 02 13:09:00.992927 2023] [wsgi:error] [pid 5928:tid 1240] [client 192.168.6.251:63940]                ^^^^^^^^^^^^^^^^^^^^^^^^^^^^^\r
[Thu Nov 02 13:09:00.992927 2023] [wsgi:error] [pid 5928:tid 1240] [client 192.168.6.251:63940]   File "D:\\Kuldeep(Python)\\Project\\env\\Lib\\site-packages\\django\\middleware\\common.py", line 48, in process_request\r
[Thu Nov 02 13:09:00.992927 2023] [wsgi:error] [pid 5928:tid 1240] [client 192.168.6.251:63940]     host = request.get_host()\r
[Thu Nov 02 13:09:00.992927 2023] [wsgi:error] [pid 5928:tid 1240] [client 192.168.6.251:63940]            ^^^^^^^^^^^^^^^^^^\r
[Thu Nov 02 13:09:00.992927 2023] [wsgi:error] [pid 5928:tid 1240] [client 192.168.6.251:63940]   File "D:\\Kuldeep(Python)\\Project\\env\\Lib\\site-packages\\django\\http\\request.py", line 150, in get_host\r
[Thu Nov 02 13:09:00.992927 2023] [wsgi:error] [pid 5928:tid 1240] [client 192.168.6.251:63940]     raise DisallowedHost(msg)\r
[Thu Nov 02 13:09:00.992927 2023] [wsgi:error] [pid 5928:tid 1240] [client 192.168.6.251:63940] django.core.exceptions.DisallowedHost: Invalid HTTP_HOST header: '192.168.6.251:90'. You may need to add '192.168.6.251' to ALLOWED_HOSTS.\r
[Thu Nov 02 13:09:01.032969 2023] [wsgi:error] [pid 5928:tid 1240] [client 192.168.6.251:63940] Bad Request: /\r
[Thu Nov 02 13:09:01.180923 2023] [wsgi:error] [pid 5928:tid 1220] [client 192.168.6.251:63941] Invalid HTTP_HOST header: '192.168.6.251:90'. You may need to add '192.168.6.251' to ALLOWED_HOSTS.\r, referer: http://192.168.6.251:90/
[Thu Nov 02 13:09:01.180923 2023] [wsgi:error] [pid 5928:tid 1220] [client 192.168.6.251:63941] Traceback (most recent call last):\r, referer: http://192.168.6.251:90/
[Thu Nov 02 13:09:01.180923 2023] [wsgi:error] [pid 5928:tid 1220] [client 192.168.6.251:63941]   File "D:\\Kuldeep(Python)\\Project\\env\\Lib\\site-packages\\django\\core\\handlers\\exception.py", line 55, in inner\r, referer: http://192.168.6.251:90/
[Thu Nov 02 13:09:01.180923 2023] [wsgi:error] [pid 5928:tid 1220] [client 192.168.6.251:63941]     response = get_response(request)\r, referer: http://192.168.6.251:90/
[Thu Nov 02 13:09:01.180923 2023] [wsgi:error] [pid 5928:tid 1220] [client 192.168.6.251:63941]                ^^^^^^^^^^^^^^^^^^^^^\r, referer: http://192.168.6.251:90/
[Thu Nov 02 13:09:01.180923 2023] [wsgi:error] [pid 5928:tid 1220] [client 192.168.6.251:63941]   File "D:\\Kuldeep(Python)\\Project\\env\\Lib\\site-packages\\django\\utils\\deprecation.py", line 133, in __call__\r, referer: http://192.168.6.251:90/
[Thu Nov 02 13:09:01.180923 2023] [wsgi:error] [pid 5928:tid 1220] [client 192.168.6.251:63941]     response = self.process_request(request)\r, referer: http://192.168.6.251:90/
[Thu Nov 02 13:09:01.180923 2023] [wsgi:error] [pid 5928:tid 1220] [client 192.168.6.251:63941]                ^^^^^^^^^^^^^^^^^^^^^^^^^^^^^\r, referer: http://192.168.6.251:90/
[Thu Nov 02 13:09:01.180923 2023] [wsgi:error] [pid 5928:tid 1220] [client 192.168.6.251:63941]   File "D:\\Kuldeep(Python)\\Project\\env\\Lib\\site-packages\\django\\middleware\\common.py", line 48, in process_request\r, referer: http://192.168.6.251:90/
[Thu Nov 02 13:09:01.180923 2023] [wsgi:error] [pid 5928:tid 1220] [client 192.168.6.251:63941]     host = request.get_host()\r, referer: http://192.168.6.251:90/
[Thu Nov 02 13:09:01.180923 2023] [wsgi:error] [pid 5928:tid 1220] [client 192.168.6.251:63941]            ^^^^^^^^^^^^^^^^^^\r, referer: http://192.168.6.251:90/
[Thu Nov 02 13:09:01.180923 2023] [wsgi:error] [pid 5928:tid 1220] [client 192.168.6.251:63941]   File "D:\\Kuldeep(Python)\\Project\\env\\Lib\\site-packages\\django\\http\\request.py", line 150, in get_host\r, referer: http://192.168.6.251:90/
[Thu Nov 02 13:09:01.180923 2023] [wsgi:error] [pid 5928:tid 1220] [client 192.168.6.251:63941]     raise DisallowedHost(msg)\r, referer: http://192.168.6.251:90/
[Thu Nov 02 13:09:01.180923 2023] [wsgi:error] [pid 5928:tid 1220] [client 192.168.6.251:63941] django.core.exceptions.DisallowedHost: Invalid HTTP_HOST header: '192.168.6.251:90'. You may need to add '192.168.6.251' to ALLOWED_HOSTS.\r, referer: http://192.168.6.251:90/
[Thu Nov 02 13:09:01.228922 2023] [wsgi:error] [pid 5928:tid 1220] [client 192.168.6.251:63941] Bad Request: /favicon.ico\r, referer: http://192.168.6.251:90/
[Thu Nov 02 13:09:01.384976 2023] [wsgi:error] [pid 5928:tid 1220] [client 192.168.6.251:63947] Invalid HTTP_HOST header: '192.168.6.251:90'. You may need to add '192.168.6.251' to ALLOWED_HOSTS.\r
[Thu Nov 02 13:09:01.384976 2023] [wsgi:error] [pid 5928:tid 1220] [client 192.168.6.251:63947] Traceback (most recent call last):\r
[Thu Nov 02 13:09:01.384976 2023] [wsgi:error] [pid 5928:tid 1220] [client 192.168.6.251:63947]   File "D:\\Kuldeep(Python)\\Project\\env\\Lib\\site-packages\\django\\core\\handlers\\exception.py", line 55, in inner\r
[Thu Nov 02 13:09:01.384976 2023] [wsgi:error] [pid 5928:tid 1220] [client 192.168.6.251:63947]     response = get_response(request)\r
[Thu Nov 02 13:09:01.384976 2023] [wsgi:error] [pid 5928:tid 1220] [client 192.168.6.251:63947]                ^^^^^^^^^^^^^^^^^^^^^\r
[Thu Nov 02 13:09:01.384976 2023] [wsgi:error] [pid 5928:tid 1220] [client 192.168.6.251:63947]   File "D:\\Kuldeep(Python)\\Project\\env\\Lib\\site-packages\\django\\utils\\deprecation.py", line 133, in __call__\r
[Thu Nov 02 13:09:01.384976 2023] [wsgi:error] [pid 5928:tid 1220] [client 192.168.6.251:63947]     response = self.process_request(request)\r
[Thu Nov 02 13:09:01.384976 2023] [wsgi:error] [pid 5928:tid 1220] [client 192.168.6.251:63947]                ^^^^^^^^^^^^^^^^^^^^^^^^^^^^^\r
[Thu Nov 02 13:09:01.384976 2023] [wsgi:error] [pid 5928:tid 1220] [client 192.168.6.251:63947]   File "D:\\Kuldeep(Python)\\Project\\env\\Lib\\site-packages\\django\\middleware\\common.py", line 48, in process_request\r
[Thu Nov 02 13:09:01.384976 2023] [wsgi:error] [pid 5928:tid 1220] [client 192.168.6.251:63947]     host = request.get_host()\r
[Thu Nov 02 13:09:01.384976 2023] [wsgi:error] [pid 5928:tid 1220] [client 192.168.6.251:63947]            ^^^^^^^^^^^^^^^^^^\r
[Thu Nov 02 13:09:01.384976 2023] [wsgi:error] [pid 5928:tid 1220] [client 192.168.6.251:63947]   File "D:\\Kuldeep(Python)\\Project\\env\\Lib\\site-packages\\django\\http\\request.py", line 150, in get_host\r
[Thu Nov 02 13:09:01.384976 2023] [wsgi:error] [pid 5928:tid 1220] [client 192.168.6.251:63947]     raise DisallowedHost(msg)\r
[Thu Nov 02 13:09:01.384976 2023] [wsgi:error] [pid 5928:tid 1220] [client 192.168.6.251:63947] django.core.exceptions.DisallowedHost: Invalid HTTP_HOST header: '192.168.6.251:90'. You may need to add '192.168.6.251' to ALLOWED_HOSTS.\r
[Thu Nov 02 13:09:01.430923 2023] [wsgi:error] [pid 5928:tid 1220] [client 192.168.6.251:63947] Bad Request: /\r
[Thu Nov 02 13:09:01.574924 2023] [wsgi:error] [pid 5928:tid 1240] [client 192.168.6.251:63948] Invalid HTTP_HOST header: '192.168.6.251:90'. You may need to add '192.168.6.251' to ALLOWED_HOSTS.\r, referer: http://192.168.6.251:90/
[Thu Nov 02 13:09:01.574924 2023] [wsgi:error] [pid 5928:tid 1240] [client 192.168.6.251:63948] Traceback (most recent call last):\r, referer: http://192.168.6.251:90/
[Thu Nov 02 13:09:01.574924 2023] [wsgi:error] [pid 5928:tid 1240] [client 192.168.6.251:63948]   File "D:\\Kuldeep(Python)\\Project\\env\\Lib\\site-packages\\django\\core\\handlers\\exception.py", line 55, in inner\r, referer: http://192.168.6.251:90/
[Thu Nov 02 13:09:01.574924 2023] [wsgi:error] [pid 5928:tid 1240] [client 192.168.6.251:63948]     response = get_response(request)\r, referer: http://192.168.6.251:90/
[Thu Nov 02 13:09:01.574924 2023] [wsgi:error] [pid 5928:tid 1240] [client 192.168.6.251:63948]                ^^^^^^^^^^^^^^^^^^^^^\r, referer: http://192.168.6.251:90/
[Thu Nov 02 13:09:01.574924 2023] [wsgi:error] [pid 5928:tid 1240] [client 192.168.6.251:63948]   File "D:\\Kuldeep(Python)\\Project\\env\\Lib\\site-packages\\django\\utils\\deprecation.py", line 133, in __call__\r, referer: http://192.168.6.251:90/
[Thu Nov 02 13:09:01.574924 2023] [wsgi:error] [pid 5928:tid 1240] [client 192.168.6.251:63948]     response = self.process_request(request)\r, referer: http://192.168.6.251:90/
[Thu Nov 02 13:09:01.574924 2023] [wsgi:error] [pid 5928:tid 1240] [client 192.168.6.251:63948]                ^^^^^^^^^^^^^^^^^^^^^^^^^^^^^\r, referer: http://192.168.6.251:90/
[Thu Nov 02 13:09:01.574924 2023] [wsgi:error] [pid 5928:tid 1240] [client 192.168.6.251:63948]   File "D:\\Kuldeep(Python)\\Project\\env\\Lib\\site-packages\\django\\middleware\\common.py", line 48, in process_request\r, referer: http://192.168.6.251:90/
[Thu Nov 02 13:09:01.574924 2023] [wsgi:error] [pid 5928:tid 1240] [client 192.168.6.251:63948]     host = request.get_host()\r, referer: http://192.168.6.251:90/
[Thu Nov 02 13:09:01.574924 2023] [wsgi:error] [pid 5928:tid 1240] [client 192.168.6.251:63948]            ^^^^^^^^^^^^^^^^^^\r, referer: http://192.168.6.251:90/
[Thu Nov 02 13:09:01.574924 2023] [wsgi:error] [pid 5928:tid 1240] [client 192.168.6.251:63948]   File "D:\\Kuldeep(Python)\\Project\\env\\Lib\\site-packages\\django\\http\\request.py", line 150, in get_host\r, referer: http://192.168.6.251:90/
[Thu Nov 02 13:09:01.574924 2023] [wsgi:error] [pid 5928:tid 1240] [client 192.168.6.251:63948]     raise DisallowedHost(msg)\r, referer: http://192.168.6.251:90/
[Thu Nov 02 13:09:01.574924 2023] [wsgi:error] [pid 5928:tid 1240] [client 192.168.6.251:63948] django.core.exceptions.DisallowedHost: Invalid HTTP_HOST header: '192.168.6.251:90'. You may need to add '192.168.6.251' to ALLOWED_HOSTS.\r, referer: http://192.168.6.251:90/
[Thu Nov 02 13:09:01.609923 2023] [wsgi:error] [pid 5928:tid 1240] [client 192.168.6.251:63948] Bad Request: /favicon.ico\r, referer: http://192.168.6.251:90/
[Thu Nov 02 13:09:01.649923 2023] [wsgi:error] [pid 5928:tid 1240] [client 192.168.6.251:63949] Invalid HTTP_HOST header: '192.168.6.251:90'. You may need to add '192.168.6.251' to ALLOWED_HOSTS.\r
[Thu Nov 02 13:09:01.649923 2023] [wsgi:error] [pid 5928:tid 1240] [client 192.168.6.251:63949] Traceback (most recent call last):\r
[Thu Nov 02 13:09:01.649923 2023] [wsgi:error] [pid 5928:tid 1240] [client 192.168.6.251:63949]   File "D:\\Kuldeep(Python)\\Project\\env\\Lib\\site-packages\\django\\core\\handlers\\exception.py", line 55, in inner\r
[Thu Nov 02 13:09:01.649923 2023] [wsgi:error] [pid 5928:tid 1240] [client 192.168.6.251:63949]     response = get_response(request)\r
[Thu Nov 02 13:09:01.649923 2023] [wsgi:error] [pid 5928:tid 1240] [client 192.168.6.251:63949]                ^^^^^^^^^^^^^^^^^^^^^\r
[Thu Nov 02 13:09:01.649923 2023] [wsgi:error] [pid 5928:tid 1240] [client 192.168.6.251:63949]   File "D:\\Kuldeep(Python)\\Project\\env\\Lib\\site-packages\\django\\utils\\deprecation.py", line 133, in __call__\r
[Thu Nov 02 13:09:01.649923 2023] [wsgi:error] [pid 5928:tid 1240] [client 192.168.6.251:63949]     response = self.process_request(request)\r
[Thu Nov 02 13:09:01.649923 2023] [wsgi:error] [pid 5928:tid 1240] [client 192.168.6.251:63949]                ^^^^^^^^^^^^^^^^^^^^^^^^^^^^^\r
[Thu Nov 02 13:09:01.649923 2023] [wsgi:error] [pid 5928:tid 1240] [client 192.168.6.251:63949]   File "D:\\Kuldeep(Python)\\Project\\env\\Lib\\site-packages\\django\\middleware\\common.py", line 48, in process_request\r
[Thu Nov 02 13:09:01.649923 2023] [wsgi:error] [pid 5928:tid 1240] [client 192.168.6.251:63949]     host = request.get_host()\r
[Thu Nov 02 13:09:01.649923 2023] [wsgi:error] [pid 5928:tid 1240] [client 192.168.6.251:63949]            ^^^^^^^^^^^^^^^^^^\r
[Thu Nov 02 13:09:01.649923 2023] [wsgi:error] [pid 5928:tid 1240] [client 192.168.6.251:63949]   File "D:\\Kuldeep(Python)\\Project\\env\\Lib\\site-packages\\django\\http\\request.py", line 150, in get_host\r
[Thu Nov 02 13:09:01.649923 2023] [wsgi:error] [pid 5928:tid 1240] [client 192.168.6.251:63949]     raise DisallowedHost(msg)\r
[Thu Nov 02 13:09:01.649923 2023] [wsgi:error] [pid 5928:tid 1240] [client 192.168.6.251:63949] django.core.exceptions.DisallowedHost: Invalid HTTP_HOST header: '192.168.6.251:90'. You may need to add '192.168.6.251' to ALLOWED_HOSTS.\r
[Thu Nov 02 13:09:01.689922 2023] [wsgi:error] [pid 5928:tid 1240] [client 192.168.6.251:63949] Bad Request: /\r
[Thu Nov 02 13:09:01.819976 2023] [wsgi:error] [pid 5928:tid 1220] [client 192.168.6.251:63950] Invalid HTTP_HOST header: '192.168.6.251:90'. You may need to add '192.168.6.251' to ALLOWED_HOSTS.\r, referer: http://192.168.6.251:90/
[Thu Nov 02 13:09:01.819976 2023] [wsgi:error] [pid 5928:tid 1220] [client 192.168.6.251:63950] Traceback (most recent call last):\r, referer: http://192.168.6.251:90/
[Thu Nov 02 13:09:01.819976 2023] [wsgi:error] [pid 5928:tid 1220] [client 192.168.6.251:63950]   File "D:\\Kuldeep(Python)\\Project\\env\\Lib\\site-packages\\django\\core\\handlers\\exception.py", line 55, in inner\r, referer: http://192.168.6.251:90/
[Thu Nov 02 13:09:01.819976 2023] [wsgi:error] [pid 5928:tid 1220] [client 192.168.6.251:63950]     response = get_response(request)\r, referer: http://192.168.6.251:90/
[Thu Nov 02 13:09:01.819976 2023] [wsgi:error] [pid 5928:tid 1220] [client 192.168.6.251:63950]                ^^^^^^^^^^^^^^^^^^^^^\r, referer: http://192.168.6.251:90/
[Thu Nov 02 13:09:01.819976 2023] [wsgi:error] [pid 5928:tid 1220] [client 192.168.6.251:63950]   File "D:\\Kuldeep(Python)\\Project\\env\\Lib\\site-packages\\django\\utils\\deprecation.py", line 133, in __call__\r, referer: http://192.168.6.251:90/
[Thu Nov 02 13:09:01.819976 2023] [wsgi:error] [pid 5928:tid 1220] [client 192.168.6.251:63950]     response = self.process_request(request)\r, referer: http://192.168.6.251:90/
[Thu Nov 02 13:09:01.819976 2023] [wsgi:error] [pid 5928:tid 1220] [client 192.168.6.251:63950]                ^^^^^^^^^^^^^^^^^^^^^^^^^^^^^\r, referer: http://192.168.6.251:90/
[Thu Nov 02 13:09:01.819976 2023] [wsgi:error] [pid 5928:tid 1220] [client 192.168.6.251:63950]   File "D:\\Kuldeep(Python)\\Project\\env\\Lib\\site-packages\\django\\middleware\\common.py", line 48, in process_request\r, referer: http://192.168.6.251:90/
[Thu Nov 02 13:09:01.819976 2023] [wsgi:error] [pid 5928:tid 1220] [client 192.168.6.251:63950]     host = request.get_host()\r, referer: http://192.168.6.251:90/
[Thu Nov 02 13:09:01.819976 2023] [wsgi:error] [pid 5928:tid 1220] [client 192.168.6.251:63950]            ^^^^^^^^^^^^^^^^^^\r, referer: http://192.168.6.251:90/
[Thu Nov 02 13:09:01.819976 2023] [wsgi:error] [pid 5928:tid 1220] [client 192.168.6.251:63950]   File "D:\\Kuldeep(Python)\\Project\\env\\Lib\\site-packages\\django\\http\\request.py", line 150, in get_host\r, referer: http://192.168.6.251:90/
[Thu Nov 02 13:09:01.819976 2023] [wsgi:error] [pid 5928:tid 1220] [client 192.168.6.251:63950]     raise DisallowedHost(msg)\r, referer: http://192.168.6.251:90/
[Thu Nov 02 13:09:01.819976 2023] [wsgi:error] [pid 5928:tid 1220] [client 192.168.6.251:63950] django.core.exceptions.DisallowedHost: Invalid HTTP_HOST header: '192.168.6.251:90'. You may need to add '192.168.6.251' to ALLOWED_HOSTS.\r, referer: http://192.168.6.251:90/
[Thu Nov 02 13:09:01.859923 2023] [wsgi:error] [pid 5928:tid 1220] [client 192.168.6.251:63950] Bad Request: /favicon.ico\r, referer: http://192.168.6.251:90/
[Thu Nov 02 13:09:02.006923 2023] [wsgi:error] [pid 5928:tid 1220] [client 192.168.6.251:63951] Invalid HTTP_HOST header: '192.168.6.251:90'. You may need to add '192.168.6.251' to ALLOWED_HOSTS.\r
[Thu Nov 02 13:09:02.006923 2023] [wsgi:error] [pid 5928:tid 1220] [client 192.168.6.251:63951] Traceback (most recent call last):\r
[Thu Nov 02 13:09:02.006923 2023] [wsgi:error] [pid 5928:tid 1220] [client 192.168.6.251:63951]   File "D:\\Kuldeep(Python)\\Project\\env\\Lib\\site-packages\\django\\core\\handlers\\exception.py", line 55, in inner\r
[Thu Nov 02 13:09:02.006923 2023] [wsgi:error] [pid 5928:tid 1220] [client 192.168.6.251:63951]     response = get_response(request)\r
[Thu Nov 02 13:09:02.006923 2023] [wsgi:error] [pid 5928:tid 1220] [client 192.168.6.251:63951]                ^^^^^^^^^^^^^^^^^^^^^\r
[Thu Nov 02 13:09:02.006923 2023] [wsgi:error] [pid 5928:tid 1220] [client 192.168.6.251:63951]   File "D:\\Kuldeep(Python)\\Project\\env\\Lib\\site-packages\\django\\utils\\deprecation.py", line 133, in __call__\r
[Thu Nov 02 13:09:02.006923 2023] [wsgi:error] [pid 5928:tid 1220] [client 192.168.6.251:63951]     response = self.process_request(request)\r
[Thu Nov 02 13:09:02.006923 2023] [wsgi:error] [pid 5928:tid 1220] [client 192.168.6.251:63951]                ^^^^^^^^^^^^^^^^^^^^^^^^^^^^^\r
[Thu Nov 02 13:09:02.006923 2023] [wsgi:error] [pid 5928:tid 1220] [client 192.168.6.251:63951]   File "D:\\Kuldeep(Python)\\Project\\env\\Lib\\site-packages\\django\\middleware\\common.py", line 48, in process_request\r
[Thu Nov 02 13:09:02.006923 2023] [wsgi:error] [pid 5928:tid 1220] [client 192.168.6.251:63951]     host = request.get_host()\r
[Thu Nov 02 13:09:02.006923 2023] [wsgi:error] [pid 5928:tid 1220] [client 192.168.6.251:63951]            ^^^^^^^^^^^^^^^^^^\r
[Thu Nov 02 13:09:02.006923 2023] [wsgi:error] [pid 5928:tid 1220] [client 192.168.6.251:63951]   File "D:\\Kuldeep(Python)\\Project\\env\\Lib\\site-packages\\django\\http\\request.py", line 150, in get_host\r
[Thu Nov 02 13:09:02.006923 2023] [wsgi:error] [pid 5928:tid 1220] [client 192.168.6.251:63951]     raise DisallowedHost(msg)\r
[Thu Nov 02 13:09:02.006923 2023] [wsgi:error] [pid 5928:tid 1220] [client 192.168.6.251:63951] django.core.exceptions.DisallowedHost: Invalid HTTP_HOST header: '192.168.6.251:90'. You may need to add '192.168.6.251' to ALLOWED_HOSTS.\r
[Thu Nov 02 13:09:02.041997 2023] [wsgi:error] [pid 5928:tid 1220] [client 192.168.6.251:63951] Bad Request: /\r
[Thu Nov 02 13:09:02.187954 2023] [wsgi:error] [pid 5928:tid 1240] [client 192.168.6.251:63952] Invalid HTTP_HOST header: '192.168.6.251:90'. You may need to add '192.168.6.251' to ALLOWED_HOSTS.\r, referer: http://192.168.6.251:90/
[Thu Nov 02 13:09:02.187954 2023] [wsgi:error] [pid 5928:tid 1240] [client 192.168.6.251:63952] Traceback (most recent call last):\r, referer: http://192.168.6.251:90/
[Thu Nov 02 13:09:02.187954 2023] [wsgi:error] [pid 5928:tid 1240] [client 192.168.6.251:63952]   File "D:\\Kuldeep(Python)\\Project\\env\\Lib\\site-packages\\django\\core\\handlers\\exception.py", line 55, in inner\r, referer: http://192.168.6.251:90/
[Thu Nov 02 13:09:02.187954 2023] [wsgi:error] [pid 5928:tid 1240] [client 192.168.6.251:63952]     response = get_response(request)\r, referer: http://192.168.6.251:90/
[Thu Nov 02 13:09:02.187954 2023] [wsgi:error] [pid 5928:tid 1240] [client 192.168.6.251:63952]                ^^^^^^^^^^^^^^^^^^^^^\r, referer: http://192.168.6.251:90/
[Thu Nov 02 13:09:02.187954 2023] [wsgi:error] [pid 5928:tid 1240] [client 192.168.6.251:63952]   File "D:\\Kuldeep(Python)\\Project\\env\\Lib\\site-packages\\django\\utils\\deprecation.py", line 133, in __call__\r, referer: http://192.168.6.251:90/
[Thu Nov 02 13:09:02.187954 2023] [wsgi:error] [pid 5928:tid 1240] [client 192.168.6.251:63952]     response = self.process_request(request)\r, referer: http://192.168.6.251:90/
[Thu Nov 02 13:09:02.187954 2023] [wsgi:error] [pid 5928:tid 1240] [client 192.168.6.251:63952]                ^^^^^^^^^^^^^^^^^^^^^^^^^^^^^\r, referer: http://192.168.6.251:90/
[Thu Nov 02 13:09:02.187954 2023] [wsgi:error] [pid 5928:tid 1240] [client 192.168.6.251:63952]   File "D:\\Kuldeep(Python)\\Project\\env\\Lib\\site-packages\\django\\middleware\\common.py", line 48, in process_request\r, referer: http://192.168.6.251:90/
[Thu Nov 02 13:09:02.187954 2023] [wsgi:error] [pid 5928:tid 1240] [client 192.168.6.251:63952]     host = request.get_host()\r, referer: http://192.168.6.251:90/
[Thu Nov 02 13:09:02.187954 2023] [wsgi:error] [pid 5928:tid 1240] [client 192.168.6.251:63952]            ^^^^^^^^^^^^^^^^^^\r, referer: http://192.168.6.251:90/
[Thu Nov 02 13:09:02.187954 2023] [wsgi:error] [pid 5928:tid 1240] [client 192.168.6.251:63952]   File "D:\\Kuldeep(Python)\\Project\\env\\Lib\\site-packages\\django\\http\\request.py", line 150, in get_host\r, referer: http://192.168.6.251:90/
[Thu Nov 02 13:09:02.187954 2023] [wsgi:error] [pid 5928:tid 1240] [client 192.168.6.251:63952]     raise DisallowedHost(msg)\r, referer: http://192.168.6.251:90/
[Thu Nov 02 13:09:02.187954 2023] [wsgi:error] [pid 5928:tid 1240] [client 192.168.6.251:63952] django.core.exceptions.DisallowedHost: Invalid HTTP_HOST header: '192.168.6.251:90'. You may need to add '192.168.6.251' to ALLOWED_HOSTS.\r, referer: http://192.168.6.251:90/
[Thu Nov 02 13:09:02.221950 2023] [wsgi:error] [pid 5928:tid 1240] [client 192.168.6.251:63952] Bad Request: /favicon.ico\r, referer: http://192.168.6.251:90/
[Thu Nov 02 13:09:48.678925 2023] [wsgi:error] [pid 5928:tid 1240] [client 192.168.6.251:64069] Invalid HTTP_HOST header: '192.168.6.251:90'. You may need to add '192.168.6.251' to ALLOWED_HOSTS.\r
[Thu Nov 02 13:09:48.678925 2023] [wsgi:error] [pid 5928:tid 1240] [client 192.168.6.251:64069] Traceback (most recent call last):\r
[Thu Nov 02 13:09:48.678925 2023] [wsgi:error] [pid 5928:tid 1240] [client 192.168.6.251:64069]   File "D:\\Kuldeep(Python)\\Project\\env\\Lib\\site-packages\\django\\core\\handlers\\exception.py", line 55, in inner\r
[Thu Nov 02 13:09:48.678925 2023] [wsgi:error] [pid 5928:tid 1240] [client 192.168.6.251:64069]     response = get_response(request)\r
[Thu Nov 02 13:09:48.678925 2023] [wsgi:error] [pid 5928:tid 1240] [client 192.168.6.251:64069]                ^^^^^^^^^^^^^^^^^^^^^\r
[Thu Nov 02 13:09:48.678925 2023] [wsgi:error] [pid 5928:tid 1240] [client 192.168.6.251:64069]   File "D:\\Kuldeep(Python)\\Project\\env\\Lib\\site-packages\\django\\utils\\deprecation.py", line 133, in __call__\r
[Thu Nov 02 13:09:48.678925 2023] [wsgi:error] [pid 5928:tid 1240] [client 192.168.6.251:64069]     response = self.process_request(request)\r
[Thu Nov 02 13:09:48.678925 2023] [wsgi:error] [pid 5928:tid 1240] [client 192.168.6.251:64069]                ^^^^^^^^^^^^^^^^^^^^^^^^^^^^^\r
[Thu Nov 02 13:09:48.678925 2023] [wsgi:error] [pid 5928:tid 1240] [client 192.168.6.251:64069]   File "D:\\Kuldeep(Python)\\Project\\env\\Lib\\site-packages\\django\\middleware\\common.py", line 48, in process_request\r
[Thu Nov 02 13:09:48.678925 2023] [wsgi:error] [pid 5928:tid 1240] [client 192.168.6.251:64069]     host = request.get_host()\r
[Thu Nov 02 13:09:48.678925 2023] [wsgi:error] [pid 5928:tid 1240] [client 192.168.6.251:64069]            ^^^^^^^^^^^^^^^^^^\r
[Thu Nov 02 13:09:48.678925 2023] [wsgi:error] [pid 5928:tid 1240] [client 192.168.6.251:64069]   File "D:\\Kuldeep(Python)\\Project\\env\\Lib\\site-packages\\django\\http\\request.py", line 150, in get_host\r
[Thu Nov 02 13:09:48.678925 2023] [wsgi:error] [pid 5928:tid 1240] [client 192.168.6.251:64069]     raise DisallowedHost(msg)\r
[Thu Nov 02 13:09:48.678925 2023] [wsgi:error] [pid 5928:tid 1240] [client 192.168.6.251:64069] django.core.exceptions.DisallowedHost: Invalid HTTP_HOST header: '192.168.6.251:90'. You may need to add '192.168.6.251' to ALLOWED_HOSTS.\r
[Thu Nov 02 13:09:48.712946 2023] [wsgi:error] [pid 5928:tid 1240] [client 192.168.6.251:64069] Bad Request: /\r
[Thu Nov 02 13:09:48.853955 2023] [wsgi:error] [pid 5928:tid 1220] [client 192.168.6.251:64070] Invalid HTTP_HOST header: '192.168.6.251:90'. You may need to add '192.168.6.251' to ALLOWED_HOSTS.\r, referer: http://192.168.6.251:90/
[Thu Nov 02 13:09:48.853955 2023] [wsgi:error] [pid 5928:tid 1220] [client 192.168.6.251:64070] Traceback (most recent call last):\r, referer: http://192.168.6.251:90/
[Thu Nov 02 13:09:48.853955 2023] [wsgi:error] [pid 5928:tid 1220] [client 192.168.6.251:64070]   File "D:\\Kuldeep(Python)\\Project\\env\\Lib\\site-packages\\django\\core\\handlers\\exception.py", line 55, in inner\r, referer: http://192.168.6.251:90/
[Thu Nov 02 13:09:48.853955 2023] [wsgi:error] [pid 5928:tid 1220] [client 192.168.6.251:64070]     response = get_response(request)\r, referer: http://192.168.6.251:90/
[Thu Nov 02 13:09:48.853955 2023] [wsgi:error] [pid 5928:tid 1220] [client 192.168.6.251:64070]                ^^^^^^^^^^^^^^^^^^^^^\r, referer: http://192.168.6.251:90/
[Thu Nov 02 13:09:48.853955 2023] [wsgi:error] [pid 5928:tid 1220] [client 192.168.6.251:64070]   File "D:\\Kuldeep(Python)\\Project\\env\\Lib\\site-packages\\django\\utils\\deprecation.py", line 133, in __call__\r, referer: http://192.168.6.251:90/
[Thu Nov 02 13:09:48.853955 2023] [wsgi:error] [pid 5928:tid 1220] [client 192.168.6.251:64070]     response = self.process_request(request)\r, referer: http://192.168.6.251:90/
[Thu Nov 02 13:09:48.853955 2023] [wsgi:error] [pid 5928:tid 1220] [client 192.168.6.251:64070]                ^^^^^^^^^^^^^^^^^^^^^^^^^^^^^\r, referer: http://192.168.6.251:90/
[Thu Nov 02 13:09:48.853955 2023] [wsgi:error] [pid 5928:tid 1220] [client 192.168.6.251:64070]   File "D:\\Kuldeep(Python)\\Project\\env\\Lib\\site-packages\\django\\middleware\\common.py", line 48, in process_request\r, referer: http://192.168.6.251:90/
[Thu Nov 02 13:09:48.853955 2023] [wsgi:error] [pid 5928:tid 1220] [client 192.168.6.251:64070]     host = request.get_host()\r, referer: http://192.168.6.251:90/
[Thu Nov 02 13:09:48.853955 2023] [wsgi:error] [pid 5928:tid 1220] [client 192.168.6.251:64070]            ^^^^^^^^^^^^^^^^^^\r, referer: http://192.168.6.251:90/
[Thu Nov 02 13:09:48.853955 2023] [wsgi:error] [pid 5928:tid 1220] [client 192.168.6.251:64070]   File "D:\\Kuldeep(Python)\\Project\\env\\Lib\\site-packages\\django\\http\\request.py", line 150, in get_host\r, referer: http://192.168.6.251:90/
[Thu Nov 02 13:09:48.853955 2023] [wsgi:error] [pid 5928:tid 1220] [client 192.168.6.251:64070]     raise DisallowedHost(msg)\r, referer: http://192.168.6.251:90/
[Thu Nov 02 13:09:48.853955 2023] [wsgi:error] [pid 5928:tid 1220] [client 192.168.6.251:64070] django.core.exceptions.DisallowedHost: Invalid HTTP_HOST header: '192.168.6.251:90'. You may need to add '192.168.6.251' to ALLOWED_HOSTS.\r, referer: http://192.168.6.251:90/
[Thu Nov 02 13:09:48.888952 2023] [wsgi:error] [pid 5928:tid 1220] [client 192.168.6.251:64070] Bad Request: /favicon.ico\r, referer: http://192.168.6.251:90/
[Fri Nov 03 13:21:39.824472 2023] [wsgi:error] [pid 5352:tid 1244] [client ::1:60642] Not Found: /favicon.ico\r, referer: http://localhost:90/
[Mon Nov 06 12:54:42.033083 2023] [wsgi:error] [pid 6076:tid 1208] [client ::1:50647] Not Found: /favicon.ico\r, referer: http://localhost:90/
[Mon Nov 06 13:20:24.380558 2023] [wsgi:error] [pid 6076:tid 1204] [client 192.168.6.251:53195] Not Found: /favicon.ico\r, referer: http://192.168.6.251:90/
[Mon Nov 06 14:26:35.859558 2023] [wsgi:error] [pid 6076:tid 1228] [client ::1:59856] Not Found: /favicon.ico\r, referer: http://localhost:90/
[Mon Nov 06 15:19:01.352663 2023] [wsgi:error] [pid 6076:tid 1224] [client 192.168.6.251:65065] Not Found: /favicon.ico\r, referer: http://192.168.6.251:90/
[Mon Nov 06 15:30:41.436661 2023] [wsgi:error] [pid 6076:tid 1196] [client ::1:50193] Not Found: /favicon.ico\r, referer: http://localhost:90/
[Mon Nov 06 16:05:42.904833 2023] [wsgi:error] [pid 6076:tid 1196] [client ::1:55181] Not Found: /favicon.ico\r, referer: http://localhost:90/
[Mon Nov 06 16:37:36.707211 2023] [wsgi:error] [pid 4904:tid 1228] [client ::1:57090] Not Found: /favicon.ico\r, referer: http://localhost:90/
[Mon Nov 06 17:40:28.012061 2023] [wsgi:error] [pid 4904:tid 1228] [client 192.168.6.251:62168] Not Found: /favicon.ico\r, referer: http://192.168.6.251:90/
[Mon Nov 06 17:40:37.068061 2023] [wsgi:error] [pid 4904:tid 1228] [client ::1:62189] Not Found: /favicon.ico\r, referer: http://localhost:90/
[Thu Nov 09 11:13:37.672764 2023] [wsgi:error] [pid 5084:tid 1236] [client 192.168.6.251:52449] Not Found: /favicon.ico\r, referer: http://192.168.6.251:90/records/free_demo
[Thu Nov 09 13:05:12.318722 2023] [wsgi:error] [pid 5084:tid 1232] [client ::1:50179] Not Found: /favicon.ico\r, referer: http://localhost:90/
[Thu Nov 09 16:07:32.974099 2023] [wsgi:error] [pid 5084:tid 1228] [client 192.168.6.251:51482] Not Found: /favicon.ico\r, referer: http://192.168.6.251:90/
[Thu Nov 09 16:07:38.803118 2023] [wsgi:error] [pid 5084:tid 1228] [client 192.168.6.251:51520] cannot access local variable 'name' where it is not associated with a value\r, referer: http://192.168.6.251:90/
[Fri Nov 10 12:43:49.699112 2023] [wsgi:error] [pid 5868:tid 1200] [client ::1:52520] Not Found: /favicon.ico\r, referer: http://localhost:90/
[Tue Nov 14 12:13:41.925420 2023] [wsgi:error] [pid 5940:tid 1192] [client 192.168.6.251:62231] Not Found: /favicon.ico\r, referer: http://192.168.6.251:90/
[Wed Nov 15 14:06:30.906777 2023] [wsgi:error] [pid 6052:tid 1196] [client ::1:65481] Not Found: /favicon.ico\r, referer: http://localhost:90/
[Mon Nov 20 12:12:46.833718 2023] [wsgi:error] [pid 5976:tid 1236] [client ::1:59732] Not Found: /favicon.ico\r, referer: http://localhost:90/
[Mon Nov 20 14:25:13.315673 2023] [wsgi:error] [pid 5976:tid 1192] [client ::1:53738] Not Found: /favicon.ico\r, referer: http://localhost:90/
[Mon Nov 20 15:01:01.054674 2023] [wsgi:error] [pid 5976:tid 1192] [client 192.168.6.251:58232] Not Found: /favicon.ico\r, referer: http://192.168.6.251:90/
[Mon Nov 20 17:13:08.845785 2023] [wsgi:error] [pid 5976:tid 1200] [client 192.168.6.251:65119] Not Found: /favicon.ico\r, referer: http://192.168.6.251:90/
[Mon Nov 20 17:41:10.955733 2023] [wsgi:error] [pid 5976:tid 1192] [client 192.168.6.251:51574] Not Found: /favicon.ico\r, referer: http://192.168.6.251:90/
[Tue Nov 21 09:27:28.334871 2023] [wsgi:error] [pid 6036:tid 1248] [client ::1:60809] Not Found: /favicon.ico\r, referer: http://localhost:90/
[Thu Nov 23 16:47:47.294885 2023] [wsgi:error] [pid 5996:tid 1220] [client ::1:61000] Not Found: /favicon.ico\r, referer: http://localhost:90/
[Fri Nov 24 12:43:26.888349 2023] [wsgi:error] [pid 5892:tid 1232] [client ::1:58081] Not Found: /favicon.ico\r, referer: http://localhost:90/
[Wed Dec 20 12:53:32.432778 2023] [wsgi:error] [pid 5864:tid 1232] [client ::1:65374] Not Found: /favicon.ico\r, referer: http://localhost:90/
[Thu Dec 21 09:10:03.811540 2023] [authz_core:error] [pid 5848:tid 1232] [client ::1:65157] AH01630: client denied by server configuration: D:/Kuldeep(Python)/Project/piinfo/staticfiles, referer: http://localhost:90/
[Thu Dec 21 09:10:03.866491 2023] [authz_core:error] [pid 5848:tid 1232] [client ::1:65157] AH01630: client denied by server configuration: D:/Kuldeep(Python)/Project/piinfo/staticfiles, referer: http://localhost:90/
[Thu Dec 21 09:10:03.948490 2023] [authz_core:error] [pid 5848:tid 1232] [client ::1:65157] AH01630: client denied by server configuration: D:/Kuldeep(Python)/Project/piinfo/staticfiles, referer: http://localhost:90/
[Thu Dec 21 09:10:03.950527 2023] [authz_core:error] [pid 5848:tid 1224] [client ::1:65158] AH01630: client denied by server configuration: D:/Kuldeep(Python)/Project/piinfo/staticfiles, referer: http://localhost:90/
[Thu Dec 21 09:10:03.958491 2023] [authz_core:error] [pid 5848:tid 1224] [client ::1:65158] AH01630: client denied by server configuration: D:/Kuldeep(Python)/Project/piinfo/staticfiles, referer: http://localhost:90/
[Thu Dec 21 09:10:03.965537 2023] [authz_core:error] [pid 5848:tid 1232] [client ::1:65157] AH01630: client denied by server configuration: D:/Kuldeep(Python)/Project/piinfo/staticfiles, referer: http://localhost:90/
[Thu Dec 21 09:10:04.099489 2023] [authz_core:error] [pid 5848:tid 1232] [client ::1:65157] AH01630: client denied by server configuration: D:/Kuldeep(Python)/Project/piinfo/staticfiles, referer: http://localhost:90/
[Thu Dec 21 09:10:04.946493 2023] [authz_core:error] [pid 5848:tid 1232] [client ::1:65157] AH01630: client denied by server configuration: D:/Kuldeep(Python)/Project/piinfo/staticfiles, referer: http://localhost:90/
[Thu Dec 21 09:10:04.948495 2023] [authz_core:error] [pid 5848:tid 1224] [client ::1:65158] AH01630: client denied by server configuration: D:/Kuldeep(Python)/Project/piinfo/staticfiles, referer: http://localhost:90/
[Thu Dec 21 09:10:04.956489 2023] [authz_core:error] [pid 5848:tid 1232] [client ::1:65157] AH01630: client denied by server configuration: D:/Kuldeep(Python)/Project/piinfo/staticfiles, referer: http://localhost:90/
[Thu Dec 21 09:10:04.988491 2023] [authz_core:error] [pid 5848:tid 1224] [client ::1:65158] AH01630: client denied by server configuration: D:/Kuldeep(Python)/Project/piinfo/staticfiles, referer: http://localhost:90/
[Thu Dec 21 09:10:04.995549 2023] [authz_core:error] [pid 5848:tid 1216] [client ::1:65215] AH01630: client denied by server configuration: D:/Kuldeep(Python)/Project/piinfo/staticfiles, referer: http://localhost:90/
[Thu Dec 21 09:10:05.011532 2023] [authz_core:error] [pid 5848:tid 1216] [client ::1:65215] AH01630: client denied by server configuration: D:/Kuldeep(Python)/Project/piinfo/staticfiles, referer: http://localhost:90/
[Thu Dec 21 09:10:05.014536 2023] [authz_core:error] [pid 5848:tid 1224] [client ::1:65158] AH01630: client denied by server configuration: D:/Kuldeep(Python)/Project/piinfo/staticfiles, referer: http://localhost:90/
[Thu Dec 21 09:10:05.021489 2023] [authz_core:error] [pid 5848:tid 1232] [client ::1:65157] AH01630: client denied by server configuration: D:/Kuldeep(Python)/Project/piinfo/staticfiles, referer: http://localhost:90/
[Thu Dec 21 09:10:05.048510 2023] [authz_core:error] [pid 5848:tid 1232] [client ::1:65157] AH01630: client denied by server configuration: D:/Kuldeep(Python)/Project/piinfo/staticfiles, referer: http://localhost:90/
[Thu Dec 21 09:10:05.054492 2023] [authz_core:error] [pid 5848:tid 1224] [client ::1:65158] AH01630: client denied by server configuration: D:/Kuldeep(Python)/Project/piinfo/staticfiles, referer: http://localhost:90/
[Thu Dec 21 09:10:05.057523 2023] [authz_core:error] [pid 5848:tid 1216] [client ::1:65215] AH01630: client denied by server configuration: D:/Kuldeep(Python)/Project/piinfo/staticfiles, referer: http://localhost:90/
[Thu Dec 21 09:10:05.074558 2023] [authz_core:error] [pid 5848:tid 1216] [client ::1:65215] AH01630: client denied by server configuration: D:/Kuldeep(Python)/Project/piinfo/staticfiles, referer: http://localhost:90/
[Thu Dec 21 09:10:06.474491 2023] [wsgi:error] [pid 5848:tid 1216] [client ::1:65215] Not Found: /favicon.ico\r, referer: http://localhost:90/
[Fri Dec 29 09:51:20.296232 2023] [authz_core:error] [pid 5912:tid 1228] [client ::1:49176] AH01630: client denied by server configuration: D:/Kuldeep(Python)/Project/piinfo/staticfiles, referer: http://localhost:90/
[Fri Dec 29 09:51:20.296232 2023] [authz_core:error] [pid 5912:tid 1220] [client ::1:49177] AH01630: client denied by server configuration: D:/Kuldeep(Python)/Project/piinfo/staticfiles, referer: http://localhost:90/
[Fri Dec 29 09:51:20.310233 2023] [authz_core:error] [pid 5912:tid 1236] [client ::1:49168] AH01630: client denied by server configuration: D:/Kuldeep(Python)/Project/piinfo/staticfiles, referer: http://localhost:90/
[Fri Dec 29 09:51:20.314233 2023] [authz_core:error] [pid 5912:tid 1236] [client ::1:49168] AH01630: client denied by server configuration: D:/Kuldeep(Python)/Project/piinfo/staticfiles, referer: http://localhost:90/
[Fri Dec 29 09:51:20.315233 2023] [authz_core:error] [pid 5912:tid 1220] [client ::1:49177] AH01630: client denied by server configuration: D:/Kuldeep(Python)/Project/piinfo/staticfiles, referer: http://localhost:90/
[Fri Dec 29 09:51:20.315233 2023] [authz_core:error] [pid 5912:tid 1228] [client ::1:49176] AH01630: client denied by server configuration: D:/Kuldeep(Python)/Project/piinfo/staticfiles, referer: http://localhost:90/
[Fri Dec 29 09:51:20.334242 2023] [authz_core:error] [pid 5912:tid 1236] [client ::1:49168] AH01630: client denied by server configuration: D:/Kuldeep(Python)/Project/piinfo/staticfiles, referer: http://localhost:90/
[Fri Dec 29 09:51:20.335234 2023] [authz_core:error] [pid 5912:tid 1228] [client ::1:49176] AH01630: client denied by server configuration: D:/Kuldeep(Python)/Project/piinfo/staticfiles, referer: http://localhost:90/
[Fri Dec 29 09:51:20.352233 2023] [authz_core:error] [pid 5912:tid 1220] [client ::1:49177] AH01630: client denied by server configuration: D:/Kuldeep(Python)/Project/piinfo/staticfiles, referer: http://localhost:90/
[Fri Dec 29 09:51:20.354301 2023] [authz_core:error] [pid 5912:tid 1228] [client ::1:49176] AH01630: client denied by server configuration: D:/Kuldeep(Python)/Project/piinfo/staticfiles, referer: http://localhost:90/
[Fri Dec 29 09:51:20.354301 2023] [authz_core:error] [pid 5912:tid 1220] [client ::1:49177] AH01630: client denied by server configuration: D:/Kuldeep(Python)/Project/piinfo/staticfiles, referer: http://localhost:90/
[Fri Dec 29 09:51:20.376233 2023] [authz_core:error] [pid 5912:tid 1228] [client ::1:49176] AH01630: client denied by server configuration: D:/Kuldeep(Python)/Project/piinfo/staticfiles, referer: http://localhost:90/
[Fri Dec 29 09:51:20.377232 2023] [authz_core:error] [pid 5912:tid 1236] [client ::1:49168] AH01630: client denied by server configuration: D:/Kuldeep(Python)/Project/piinfo/staticfiles, referer: http://localhost:90/
[Fri Dec 29 09:51:20.377232 2023] [authz_core:error] [pid 5912:tid 1220] [client ::1:49177] AH01630: client denied by server configuration: D:/Kuldeep(Python)/Project/piinfo/staticfiles, referer: http://localhost:90/
[Fri Dec 29 09:51:20.380235 2023] [authz_core:error] [pid 5912:tid 1236] [client ::1:49168] AH01630: client denied by server configuration: D:/Kuldeep(Python)/Project/piinfo/staticfiles, referer: http://localhost:90/
[Fri Dec 29 09:51:20.380235 2023] [authz_core:error] [pid 5912:tid 1220] [client ::1:49177] AH01630: client denied by server configuration: D:/Kuldeep(Python)/Project/piinfo/staticfiles, referer: http://localhost:90/
[Fri Dec 29 09:51:20.383283 2023] [authz_core:error] [pid 5912:tid 1236] [client ::1:49168] AH01630: client denied by server configuration: D:/Kuldeep(Python)/Project/piinfo/staticfiles, referer: http://localhost:90/
[Fri Dec 29 09:51:20.386233 2023] [authz_core:error] [pid 5912:tid 1236] [client ::1:49168] AH01630: client denied by server configuration: D:/Kuldeep(Python)/Project/piinfo/staticfiles, referer: http://localhost:90/
[Fri Dec 29 09:51:20.388235 2023] [authz_core:error] [pid 5912:tid 1236] [client ::1:49168] AH01630: client denied by server configuration: D:/Kuldeep(Python)/Project/piinfo/staticfiles, referer: http://localhost:90/
[Fri Dec 29 09:51:20.391235 2023] [authz_core:error] [pid 5912:tid 1236] [client ::1:49168] AH01630: client denied by server configuration: D:/Kuldeep(Python)/Project/piinfo/staticfiles, referer: http://localhost:90/
[Fri Dec 29 09:51:20.394233 2023] [authz_core:error] [pid 5912:tid 1236] [client ::1:49168] AH01630: client denied by server configuration: D:/Kuldeep(Python)/Project/piinfo/staticfiles, referer: http://localhost:90/
[Fri Dec 29 09:51:20.396282 2023] [authz_core:error] [pid 5912:tid 1236] [client ::1:49168] AH01630: client denied by server configuration: D:/Kuldeep(Python)/Project/piinfo/staticfiles, referer: http://localhost:90/
[Fri Dec 29 09:51:20.399232 2023] [authz_core:error] [pid 5912:tid 1236] [client ::1:49168] AH01630: client denied by server configuration: D:/Kuldeep(Python)/Project/piinfo/staticfiles, referer: http://localhost:90/
[Fri Dec 29 09:51:20.418246 2023] [authz_core:error] [pid 5912:tid 1236] [client ::1:49168] AH01630: client denied by server configuration: D:/Kuldeep(Python)/Project/piinfo/staticfiles, referer: http://localhost:90/
[Fri Dec 29 09:51:20.665264 2023] [authz_core:error] [pid 5912:tid 1236] [client ::1:49168] AH01630: client denied by server configuration: D:/Kuldeep(Python)/Project/piinfo/staticfiles, referer: http://localhost:90/
[Fri Dec 29 09:51:20.666234 2023] [authz_core:error] [pid 5912:tid 1220] [client ::1:49177] AH01630: client denied by server configuration: D:/Kuldeep(Python)/Project/piinfo/staticfiles, referer: http://localhost:90/
[Fri Dec 29 09:51:20.666234 2023] [authz_core:error] [pid 5912:tid 1228] [client ::1:49176] AH01630: client denied by server configuration: D:/Kuldeep(Python)/Project/piinfo/staticfiles, referer: http://localhost:90/
[Fri Dec 29 09:51:20.686265 2023] [authz_core:error] [pid 5912:tid 1220] [client ::1:49177] AH01630: client denied by server configuration: D:/Kuldeep(Python)/Project/piinfo/staticfiles, referer: http://localhost:90/
[Fri Dec 29 09:51:20.686265 2023] [authz_core:error] [pid 5912:tid 1228] [client ::1:49176] AH01630: client denied by server configuration: D:/Kuldeep(Python)/Project/piinfo/staticfiles, referer: http://localhost:90/
[Fri Dec 29 09:51:20.688274 2023] [authz_core:error] [pid 5912:tid 1220] [client ::1:49177] AH01630: client denied by server configuration: D:/Kuldeep(Python)/Project/piinfo/staticfiles, referer: http://localhost:90/
[Fri Dec 29 09:51:20.690234 2023] [authz_core:error] [pid 5912:tid 1228] [client ::1:49176] AH01630: client denied by server configuration: D:/Kuldeep(Python)/Project/piinfo/staticfiles, referer: http://localhost:90/
[Fri Dec 29 09:51:20.693269 2023] [authz_core:error] [pid 5912:tid 1228] [client ::1:49176] AH01630: client denied by server configuration: D:/Kuldeep(Python)/Project/piinfo/staticfiles, referer: http://localhost:90/
[Fri Dec 29 09:51:20.693269 2023] [authz_core:error] [pid 5912:tid 1220] [client ::1:49177] AH01630: client denied by server configuration: D:/Kuldeep(Python)/Project/piinfo/staticfiles, referer: http://localhost:90/
[Fri Dec 29 09:51:20.694232 2023] [authz_core:error] [pid 5912:tid 1236] [client ::1:49168] AH01630: client denied by server configuration: D:/Kuldeep(Python)/Project/piinfo/staticfiles, referer: http://localhost:90/
[Fri Dec 29 09:51:20.697234 2023] [authz_core:error] [pid 5912:tid 1236] [client ::1:49168] AH01630: client denied by server configuration: D:/Kuldeep(Python)/Project/piinfo/staticfiles, referer: http://localhost:90/
[Fri Dec 29 09:51:20.697234 2023] [authz_core:error] [pid 5912:tid 1220] [client ::1:49177] AH01630: client denied by server configuration: D:/Kuldeep(Python)/Project/piinfo/staticfiles, referer: http://localhost:90/
[Fri Dec 29 09:51:20.699261 2023] [authz_core:error] [pid 5912:tid 1228] [client ::1:49176] AH01630: client denied by server configuration: D:/Kuldeep(Python)/Project/piinfo/staticfiles, referer: http://localhost:90/
[Fri Dec 29 09:51:20.714285 2023] [authz_core:error] [pid 5912:tid 1228] [client ::1:49176] AH01630: client denied by server configuration: D:/Kuldeep(Python)/Project/piinfo/staticfiles, referer: http://localhost:90/
[Fri Dec 29 09:51:20.725232 2023] [authz_core:error] [pid 5912:tid 1220] [client ::1:49177] AH01630: client denied by server configuration: D:/Kuldeep(Python)/Project/piinfo/staticfiles, referer: http://localhost:90/
[Fri Dec 29 09:51:20.725232 2023] [authz_core:error] [pid 5912:tid 1236] [client ::1:49168] AH01630: client denied by server configuration: D:/Kuldeep(Python)/Project/piinfo/staticfiles, referer: http://localhost:90/
[Fri Dec 29 09:51:20.728242 2023] [authz_core:error] [pid 5912:tid 1220] [client ::1:49177] AH01630: client denied by server configuration: D:/Kuldeep(Python)/Project/piinfo/staticfiles, referer: http://localhost:90/
[Fri Dec 29 09:51:20.729279 2023] [authz_core:error] [pid 5912:tid 1236] [client ::1:49168] AH01630: client denied by server configuration: D:/Kuldeep(Python)/Project/piinfo/staticfiles, referer: http://localhost:90/
[Mon Jan 22 14:21:08.063628 2024] [authz_core:error] [pid 5816:tid 1232] [client ::1:62378] AH01630: client denied by server configuration: D:/Kuldeep(Python)/Project/piinfo/staticfiles, referer: http://localhost:90/
[Mon Jan 22 14:21:08.068631 2024] [authz_core:error] [pid 5816:tid 1224] [client ::1:62379] AH01630: client denied by server configuration: D:/Kuldeep(Python)/Project/piinfo/staticfiles, referer: http://localhost:90/
[Mon Jan 22 14:21:08.086624 2024] [authz_core:error] [pid 5816:tid 1216] [client ::1:62388] AH01630: client denied by server configuration: D:/Kuldeep(Python)/Project/piinfo/staticfiles, referer: http://localhost:90/
[Mon Jan 22 14:21:08.098686 2024] [authz_core:error] [pid 5816:tid 1232] [client ::1:62378] AH01630: client denied by server configuration: D:/Kuldeep(Python)/Project/piinfo/staticfiles, referer: http://localhost:90/
[Mon Jan 22 14:21:08.098686 2024] [authz_core:error] [pid 5816:tid 1216] [client ::1:62388] AH01630: client denied by server configuration: D:/Kuldeep(Python)/Project/piinfo/staticfiles, referer: http://localhost:90/
[Mon Jan 22 14:21:08.098686 2024] [authz_core:error] [pid 5816:tid 1224] [client ::1:62379] AH01630: client denied by server configuration: D:/Kuldeep(Python)/Project/piinfo/staticfiles, referer: http://localhost:90/
[Mon Jan 22 14:21:08.100626 2024] [authz_core:error] [pid 5816:tid 1196] [client ::1:62391] AH01630: client denied by server configuration: D:/Kuldeep(Python)/Project/piinfo/staticfiles, referer: http://localhost:90/
[Mon Jan 22 14:21:08.100626 2024] [authz_core:error] [pid 5816:tid 1204] [client ::1:62390] AH01630: client denied by server configuration: D:/Kuldeep(Python)/Project/piinfo/staticfiles, referer: http://localhost:90/
[Mon Jan 22 14:21:08.115623 2024] [authz_core:error] [pid 5816:tid 1208] [client ::1:62389] AH01630: client denied by server configuration: D:/Kuldeep(Python)/Project/piinfo/staticfiles, referer: http://localhost:90/
[Mon Jan 22 14:21:08.132621 2024] [authz_core:error] [pid 5816:tid 1232] [client ::1:62378] AH01630: client denied by server configuration: D:/Kuldeep(Python)/Project/piinfo/staticfiles, referer: http://localhost:90/
[Mon Jan 22 14:21:08.132621 2024] [authz_core:error] [pid 5816:tid 1224] [client ::1:62379] AH01630: client denied by server configuration: D:/Kuldeep(Python)/Project/piinfo/staticfiles, referer: http://localhost:90/
[Mon Jan 22 14:21:08.132621 2024] [authz_core:error] [pid 5816:tid 1216] [client ::1:62388] AH01630: client denied by server configuration: D:/Kuldeep(Python)/Project/piinfo/staticfiles, referer: http://localhost:90/
[Mon Jan 22 14:21:08.159615 2024] [authz_core:error] [pid 5816:tid 1208] [client ::1:62389] AH01630: client denied by server configuration: D:/Kuldeep(Python)/Project/piinfo/staticfiles, referer: http://localhost:90/
[Mon Jan 22 14:21:08.161583 2024] [authz_core:error] [pid 5816:tid 1204] [client ::1:62390] AH01630: client denied by server configuration: D:/Kuldeep(Python)/Project/piinfo/staticfiles, referer: http://localhost:90/
[Mon Jan 22 14:21:08.199610 2024] [authz_core:error] [pid 5816:tid 1204] [client ::1:62390] AH01630: client denied by server configuration: D:/Kuldeep(Python)/Project/piinfo/staticfiles, referer: http://localhost:90/
[Mon Jan 22 14:21:08.200629 2024] [authz_core:error] [pid 5816:tid 1208] [client ::1:62389] AH01630: client denied by server configuration: D:/Kuldeep(Python)/Project/piinfo/staticfiles, referer: http://localhost:90/
[Mon Jan 22 14:21:08.256599 2024] [authz_core:error] [pid 5816:tid 1204] [client ::1:62390] AH01630: client denied by server configuration: D:/Kuldeep(Python)/Project/piinfo/staticfiles, referer: http://localhost:90/
[Mon Jan 22 14:21:08.263584 2024] [authz_core:error] [pid 5816:tid 1204] [client ::1:62390] AH01630: client denied by server configuration: D:/Kuldeep(Python)/Project/piinfo/staticfiles, referer: http://localhost:90/
[Mon Jan 22 14:21:08.269629 2024] [authz_core:error] [pid 5816:tid 1204] [client ::1:62390] AH01630: client denied by server configuration: D:/Kuldeep(Python)/Project/piinfo/staticfiles, referer: http://localhost:90/
[Mon Jan 22 14:21:08.274594 2024] [authz_core:error] [pid 5816:tid 1204] [client ::1:62390] AH01630: client denied by server configuration: D:/Kuldeep(Python)/Project/piinfo/staticfiles, referer: http://localhost:90/
[Mon Jan 22 14:21:08.280616 2024] [authz_core:error] [pid 5816:tid 1204] [client ::1:62390] AH01630: client denied by server configuration: D:/Kuldeep(Python)/Project/piinfo/staticfiles, referer: http://localhost:90/
[Mon Jan 22 14:21:08.333620 2024] [authz_core:error] [pid 5816:tid 1216] [client ::1:62388] AH01630: client denied by server configuration: D:/Kuldeep(Python)/Project/piinfo/staticfiles, referer: http://localhost:90/
[Mon Jan 22 14:21:08.335578 2024] [authz_core:error] [pid 5816:tid 1224] [client ::1:62379] AH01630: client denied by server configuration: D:/Kuldeep(Python)/Project/piinfo/staticfiles, referer: http://localhost:90/
[Mon Jan 22 14:21:08.336598 2024] [authz_core:error] [pid 5816:tid 1232] [client ::1:62378] AH01630: client denied by server configuration: D:/Kuldeep(Python)/Project/piinfo/staticfiles, referer: http://localhost:90/
[Mon Jan 22 14:21:08.336598 2024] [authz_core:error] [pid 5816:tid 1196] [client ::1:62391] AH01630: client denied by server configuration: D:/Kuldeep(Python)/Project/piinfo/staticfiles, referer: http://localhost:90/
[Mon Jan 22 14:21:08.347576 2024] [authz_core:error] [pid 5816:tid 1216] [client ::1:62388] AH01630: client denied by server configuration: D:/Kuldeep(Python)/Project/piinfo/staticfiles, referer: http://localhost:90/
[Mon Jan 22 14:21:08.349576 2024] [authz_core:error] [pid 5816:tid 1204] [client ::1:62390] AH01630: client denied by server configuration: D:/Kuldeep(Python)/Project/piinfo/staticfiles, referer: http://localhost:90/
[Mon Jan 22 14:21:08.354578 2024] [authz_core:error] [pid 5816:tid 1208] [client ::1:62389] AH01630: client denied by server configuration: D:/Kuldeep(Python)/Project/piinfo/staticfiles, referer: http://localhost:90/
[Mon Jan 22 14:21:08.354578 2024] [authz_core:error] [pid 5816:tid 1196] [client ::1:62391] AH01630: client denied by server configuration: D:/Kuldeep(Python)/Project/piinfo/staticfiles, referer: http://localhost:90/
[Mon Jan 22 14:21:08.354578 2024] [authz_core:error] [pid 5816:tid 1232] [client ::1:62378] AH01630: client denied by server configuration: D:/Kuldeep(Python)/Project/piinfo/staticfiles, referer: http://localhost:90/
[Mon Jan 22 14:21:08.357577 2024] [authz_core:error] [pid 5816:tid 1224] [client ::1:62379] AH01630: client denied by server configuration: D:/Kuldeep(Python)/Project/piinfo/staticfiles, referer: http://localhost:90/
[Mon Jan 22 14:21:08.359577 2024] [authz_core:error] [pid 5816:tid 1204] [client ::1:62390] AH01630: client denied by server configuration: D:/Kuldeep(Python)/Project/piinfo/staticfiles, referer: http://localhost:90/
[Mon Jan 22 14:21:08.360577 2024] [authz_core:error] [pid 5816:tid 1208] [client ::1:62389] AH01630: client denied by server configuration: D:/Kuldeep(Python)/Project/piinfo/staticfiles, referer: http://localhost:90/
[Mon Jan 22 14:21:08.361577 2024] [authz_core:error] [pid 5816:tid 1196] [client ::1:62391] AH01630: client denied by server configuration: D:/Kuldeep(Python)/Project/piinfo/staticfiles, referer: http://localhost:90/
[Mon Jan 22 14:21:08.367576 2024] [authz_core:error] [pid 5816:tid 1232] [client ::1:62378] AH01630: client denied by server configuration: D:/Kuldeep(Python)/Project/piinfo/staticfiles, referer: http://localhost:90/
[Mon Jan 22 14:21:08.367576 2024] [authz_core:error] [pid 5816:tid 1216] [client ::1:62388] AH01630: client denied by server configuration: D:/Kuldeep(Python)/Project/piinfo/staticfiles, referer: http://localhost:90/
[Mon Jan 22 14:21:08.369576 2024] [authz_core:error] [pid 5816:tid 1224] [client ::1:62379] AH01630: client denied by server configuration: D:/Kuldeep(Python)/Project/piinfo/staticfiles, referer: http://localhost:90/
[Mon Jan 22 14:21:08.418577 2024] [authz_core:error] [pid 5816:tid 1196] [client ::1:62391] AH01630: client denied by server configuration: D:/Kuldeep(Python)/Project/piinfo/staticfiles, referer: http://localhost:90/
[Mon Jan 22 14:21:08.446579 2024] [authz_core:error] [pid 5816:tid 1196] [client ::1:62391] AH01630: client denied by server configuration: D:/Kuldeep(Python)/Project/piinfo/staticfiles, referer: http://localhost:90/
[Mon Jan 22 14:21:10.586577 2024] [authz_core:error] [pid 5816:tid 1196] [client ::1:62391] AH01630: client denied by server configuration: D:/Kuldeep(Python)/Project/piinfo/staticfiles, referer: http://localhost:90/
[Mon Jan 22 16:28:28.593695 2024] [wsgi:error] [pid 5816:tid 1216] [client ::1:58440] Arjan Dhillon \r, referer: http://localhost:90/records/henquiry
[Mon Jan 22 16:28:28.593695 2024] [wsgi:error] [pid 5816:tid 1216] [client ::1:58440] \r, referer: http://localhost:90/records/henquiry
[Mon Jan 22 16:28:28.593695 2024] [wsgi:error] [pid 5816:tid 1216] [client ::1:58440] \r, referer: http://localhost:90/records/henquiry
[Mon Jan 22 16:28:28.593695 2024] [wsgi:error] [pid 5816:tid 1216] [client ::1:58440] \r, referer: http://localhost:90/records/henquiry
[Mon Jan 22 16:28:28.593695 2024] [wsgi:error] [pid 5816:tid 1216] [client ::1:58440] \r, referer: http://localhost:90/records/henquiry
[Mon Jan 22 16:28:29.483741 2024] [wsgi:error] [pid 5816:tid 1216] [client ::1:58440] Internal Server Error: /records/henquiry\r, referer: http://localhost:90/records/henquiry
[Mon Jan 22 16:28:29.483741 2024] [wsgi:error] [pid 5816:tid 1216] [client ::1:58440] Traceback (most recent call last):\r, referer: http://localhost:90/records/henquiry
[Mon Jan 22 16:28:29.483741 2024] [wsgi:error] [pid 5816:tid 1216] [client ::1:58440]   File "D:\\Kuldeep(Python)\\Project\\env\\Lib\\site-packages\\django\\core\\handlers\\exception.py", line 55, in inner\r, referer: http://localhost:90/records/henquiry
[Mon Jan 22 16:28:29.483741 2024] [wsgi:error] [pid 5816:tid 1216] [client ::1:58440]     response = get_response(request)\r, referer: http://localhost:90/records/henquiry
[Mon Jan 22 16:28:29.483741 2024] [wsgi:error] [pid 5816:tid 1216] [client ::1:58440]                ^^^^^^^^^^^^^^^^^^^^^\r, referer: http://localhost:90/records/henquiry
[Mon Jan 22 16:28:29.483741 2024] [wsgi:error] [pid 5816:tid 1216] [client ::1:58440]   File "D:\\Kuldeep(Python)\\Project\\env\\Lib\\site-packages\\django\\core\\handlers\\base.py", line 197, in _get_response\r, referer: http://localhost:90/records/henquiry
[Mon Jan 22 16:28:29.483741 2024] [wsgi:error] [pid 5816:tid 1216] [client ::1:58440]     response = wrapped_callback(request, *callback_args, **callback_kwargs)\r, referer: http://localhost:90/records/henquiry
[Mon Jan 22 16:28:29.483741 2024] [wsgi:error] [pid 5816:tid 1216] [client ::1:58440]                ^^^^^^^^^^^^^^^^^^^^^^^^^^^^^^^^^^^^^^^^^^^^^^^^^^^^^^^^^^^^\r, referer: http://localhost:90/records/henquiry
[Mon Jan 22 16:28:29.483741 2024] [wsgi:error] [pid 5816:tid 1216] [client ::1:58440]   File "D:\\Kuldeep(Python)\\Project\\piinfo\\records\\views.py", line 22, in henquiry\r, referer: http://localhost:90/records/henquiry
[Mon Jan 22 16:28:29.483741 2024] [wsgi:error] [pid 5816:tid 1216] [client ::1:58440]     data = HEnquiry(name = name, phone = phone, email=email, intrested_in = intrest,\r, referer: http://localhost:90/records/henquiry
[Mon Jan 22 16:28:29.483741 2024] [wsgi:error] [pid 5816:tid 1216] [client ::1:58440]            ^^^^^^^^^^^^^^^^^^^^^^^^^^^^^^^^^^^^^^^^^^^^^^^^^^^^^^^^^^^^^^^^^^^^^^^^^\r, referer: http://localhost:90/records/henquiry
[Mon Jan 22 16:28:29.483741 2024] [wsgi:error] [pid 5816:tid 1216] [client ::1:58440]   File "D:\\Kuldeep(Python)\\Project\\env\\Lib\\site-packages\\django\\db\\models\\base.py", line 567, in __init__\r, referer: http://localhost:90/records/henquiry
[Mon Jan 22 16:28:29.483741 2024] [wsgi:error] [pid 5816:tid 1216] [client ::1:58440]     raise TypeError(\r, referer: http://localhost:90/records/henquiry
[Mon Jan 22 16:28:29.483741 2024] [wsgi:error] [pid 5816:tid 1216] [client ::1:58440] TypeError: HEnquiry() got unexpected keyword arguments: 'intrested_in'\r, referer: http://localhost:90/records/henquiry
[Mon Jan 22 16:28:29.835695 2024] [wsgi:error] [pid 5816:tid 1216] [client ::1:58442] Not Found: /favicon.ico\r, referer: http://localhost:90/records/henquiry
[Mon Jan 22 16:29:24.776695 2024] [wsgi:error] [pid 5816:tid 1216] [client ::1:58468] Arjan Dhillon \r, referer: http://localhost:90/records/henquiry
[Mon Jan 22 16:29:24.776695 2024] [wsgi:error] [pid 5816:tid 1216] [client ::1:58468] \r, referer: http://localhost:90/records/henquiry
[Mon Jan 22 16:29:24.776695 2024] [wsgi:error] [pid 5816:tid 1216] [client ::1:58468] \r, referer: http://localhost:90/records/henquiry
[Mon Jan 22 16:29:24.776695 2024] [wsgi:error] [pid 5816:tid 1216] [client ::1:58468] \r, referer: http://localhost:90/records/henquiry
[Mon Jan 22 16:29:24.776695 2024] [wsgi:error] [pid 5816:tid 1216] [client ::1:58468] \r, referer: http://localhost:90/records/henquiry
[Mon Jan 22 16:29:24.836721 2024] [wsgi:error] [pid 5816:tid 1216] [client ::1:58468] Internal Server Error: /records/henquiry\r, referer: http://localhost:90/records/henquiry
[Mon Jan 22 16:29:24.836721 2024] [wsgi:error] [pid 5816:tid 1216] [client ::1:58468] Traceback (most recent call last):\r, referer: http://localhost:90/records/henquiry
[Mon Jan 22 16:29:24.836721 2024] [wsgi:error] [pid 5816:tid 1216] [client ::1:58468]   File "D:\\Kuldeep(Python)\\Project\\env\\Lib\\site-packages\\django\\core\\handlers\\exception.py", line 55, in inner\r, referer: http://localhost:90/records/henquiry
[Mon Jan 22 16:29:24.836721 2024] [wsgi:error] [pid 5816:tid 1216] [client ::1:58468]     response = get_response(request)\r, referer: http://localhost:90/records/henquiry
[Mon Jan 22 16:29:24.836721 2024] [wsgi:error] [pid 5816:tid 1216] [client ::1:58468]                ^^^^^^^^^^^^^^^^^^^^^\r, referer: http://localhost:90/records/henquiry
[Mon Jan 22 16:29:24.836721 2024] [wsgi:error] [pid 5816:tid 1216] [client ::1:58468]   File "D:\\Kuldeep(Python)\\Project\\env\\Lib\\site-packages\\django\\core\\handlers\\base.py", line 197, in _get_response\r, referer: http://localhost:90/records/henquiry
[Mon Jan 22 16:29:24.836721 2024] [wsgi:error] [pid 5816:tid 1216] [client ::1:58468]     response = wrapped_callback(request, *callback_args, **callback_kwargs)\r, referer: http://localhost:90/records/henquiry
[Mon Jan 22 16:29:24.836721 2024] [wsgi:error] [pid 5816:tid 1216] [client ::1:58468]                ^^^^^^^^^^^^^^^^^^^^^^^^^^^^^^^^^^^^^^^^^^^^^^^^^^^^^^^^^^^^\r, referer: http://localhost:90/records/henquiry
[Mon Jan 22 16:29:24.836721 2024] [wsgi:error] [pid 5816:tid 1216] [client ::1:58468]   File "D:\\Kuldeep(Python)\\Project\\piinfo\\records\\views.py", line 22, in henquiry\r, referer: http://localhost:90/records/henquiry
[Mon Jan 22 16:29:24.836721 2024] [wsgi:error] [pid 5816:tid 1216] [client ::1:58468]     data = HEnquiry(name = name, phone = phone, email=email, interested_in = intrest,\r, referer: http://localhost:90/records/henquiry
[Mon Jan 22 16:29:24.836721 2024] [wsgi:error] [pid 5816:tid 1216] [client ::1:58468]            ^^^^^^^^^^^^^^^^^^^^^^^^^^^^^^^^^^^^^^^^^^^^^^^^^^^^^^^^^^^^^^^^^^^^^^^^^^\r, referer: http://localhost:90/records/henquiry
[Mon Jan 22 16:29:24.836721 2024] [wsgi:error] [pid 5816:tid 1216] [client ::1:58468]   File "D:\\Kuldeep(Python)\\Project\\env\\Lib\\site-packages\\django\\db\\models\\base.py", line 567, in __init__\r, referer: http://localhost:90/records/henquiry
[Mon Jan 22 16:29:24.836721 2024] [wsgi:error] [pid 5816:tid 1216] [client ::1:58468]     raise TypeError(\r, referer: http://localhost:90/records/henquiry
[Mon Jan 22 16:29:24.836721 2024] [wsgi:error] [pid 5816:tid 1216] [client ::1:58468] TypeError: HEnquiry() got unexpected keyword arguments: 'intrested_in'\r, referer: http://localhost:90/records/henquiry
[Mon Jan 22 16:29:44.394381 2024] [wsgi:error] [pid 5816:tid 1216] [client ::1:58475] Arjan Dhillon \r, referer: http://localhost:90/records/henquiry
[Mon Jan 22 16:29:44.394381 2024] [wsgi:error] [pid 5816:tid 1216] [client ::1:58475] \r, referer: http://localhost:90/records/henquiry
[Mon Jan 22 16:29:44.394381 2024] [wsgi:error] [pid 5816:tid 1216] [client ::1:58475] \r, referer: http://localhost:90/records/henquiry
[Mon Jan 22 16:29:44.394381 2024] [wsgi:error] [pid 5816:tid 1216] [client ::1:58475] \r, referer: http://localhost:90/records/henquiry
[Mon Jan 22 16:29:44.394381 2024] [wsgi:error] [pid 5816:tid 1216] [client ::1:58475] \r, referer: http://localhost:90/records/henquiry
[Mon Jan 22 16:29:44.454383 2024] [wsgi:error] [pid 5816:tid 1216] [client ::1:58475] Internal Server Error: /records/henquiry\r, referer: http://localhost:90/records/henquiry
[Mon Jan 22 16:29:44.454383 2024] [wsgi:error] [pid 5816:tid 1216] [client ::1:58475] Traceback (most recent call last):\r, referer: http://localhost:90/records/henquiry
[Mon Jan 22 16:29:44.454383 2024] [wsgi:error] [pid 5816:tid 1216] [client ::1:58475]   File "D:\\Kuldeep(Python)\\Project\\env\\Lib\\site-packages\\django\\core\\handlers\\exception.py", line 55, in inner\r, referer: http://localhost:90/records/henquiry
[Mon Jan 22 16:29:44.454383 2024] [wsgi:error] [pid 5816:tid 1216] [client ::1:58475]     response = get_response(request)\r, referer: http://localhost:90/records/henquiry
[Mon Jan 22 16:29:44.454383 2024] [wsgi:error] [pid 5816:tid 1216] [client ::1:58475]                ^^^^^^^^^^^^^^^^^^^^^\r, referer: http://localhost:90/records/henquiry
[Mon Jan 22 16:29:44.454383 2024] [wsgi:error] [pid 5816:tid 1216] [client ::1:58475]   File "D:\\Kuldeep(Python)\\Project\\env\\Lib\\site-packages\\django\\core\\handlers\\base.py", line 197, in _get_response\r, referer: http://localhost:90/records/henquiry
[Mon Jan 22 16:29:44.454383 2024] [wsgi:error] [pid 5816:tid 1216] [client ::1:58475]     response = wrapped_callback(request, *callback_args, **callback_kwargs)\r, referer: http://localhost:90/records/henquiry
[Mon Jan 22 16:29:44.454383 2024] [wsgi:error] [pid 5816:tid 1216] [client ::1:58475]                ^^^^^^^^^^^^^^^^^^^^^^^^^^^^^^^^^^^^^^^^^^^^^^^^^^^^^^^^^^^^\r, referer: http://localhost:90/records/henquiry
[Mon Jan 22 16:29:44.454383 2024] [wsgi:error] [pid 5816:tid 1216] [client ::1:58475]   File "D:\\Kuldeep(Python)\\Project\\piinfo\\records\\views.py", line 22, in henquiry\r, referer: http://localhost:90/records/henquiry
[Mon Jan 22 16:29:44.454383 2024] [wsgi:error] [pid 5816:tid 1216] [client ::1:58475]     data = HEnquiry(name = name, phone = phone, email=email, interested_in = intrest,\r, referer: http://localhost:90/records/henquiry
[Mon Jan 22 16:29:44.454383 2024] [wsgi:error] [pid 5816:tid 1216] [client ::1:58475]            ^^^^^^^^^^^^^^^^^^^^^^^^^^^^^^^^^^^^^^^^^^^^^^^^^^^^^^^^^^^^^^^^^^^^^^^^^^\r, referer: http://localhost:90/records/henquiry
[Mon Jan 22 16:29:44.454383 2024] [wsgi:error] [pid 5816:tid 1216] [client ::1:58475]   File "D:\\Kuldeep(Python)\\Project\\env\\Lib\\site-packages\\django\\db\\models\\base.py", line 567, in __init__\r, referer: http://localhost:90/records/henquiry
[Mon Jan 22 16:29:44.454383 2024] [wsgi:error] [pid 5816:tid 1216] [client ::1:58475]     raise TypeError(\r, referer: http://localhost:90/records/henquiry
[Mon Jan 22 16:29:44.454383 2024] [wsgi:error] [pid 5816:tid 1216] [client ::1:58475] TypeError: HEnquiry() got unexpected keyword arguments: 'intrested_in'\r, referer: http://localhost:90/records/henquiry
[Mon Jan 22 16:31:25.820381 2024] [wsgi:error] [pid 5816:tid 1216] [client ::1:58504] Arjan Dhillon \r, referer: http://localhost:90/records/henquiry
[Mon Jan 22 16:31:25.820381 2024] [wsgi:error] [pid 5816:tid 1216] [client ::1:58504] \r, referer: http://localhost:90/records/henquiry
[Mon Jan 22 16:31:25.820381 2024] [wsgi:error] [pid 5816:tid 1216] [client ::1:58504] \r, referer: http://localhost:90/records/henquiry
[Mon Jan 22 16:31:25.820381 2024] [wsgi:error] [pid 5816:tid 1216] [client ::1:58504] \r, referer: http://localhost:90/records/henquiry
[Mon Jan 22 16:31:25.820381 2024] [wsgi:error] [pid 5816:tid 1216] [client ::1:58504] \r, referer: http://localhost:90/records/henquiry
[Mon Jan 22 16:31:25.873335 2024] [wsgi:error] [pid 5816:tid 1216] [client ::1:58504] Internal Server Error: /records/henquiry\r, referer: http://localhost:90/records/henquiry
[Mon Jan 22 16:31:25.881335 2024] [wsgi:error] [pid 5816:tid 1216] [client ::1:58504] Traceback (most recent call last):\r, referer: http://localhost:90/records/henquiry
[Mon Jan 22 16:31:25.881335 2024] [wsgi:error] [pid 5816:tid 1216] [client ::1:58504]   File "D:\\Kuldeep(Python)\\Project\\env\\Lib\\site-packages\\django\\core\\handlers\\exception.py", line 55, in inner\r, referer: http://localhost:90/records/henquiry
[Mon Jan 22 16:31:25.881335 2024] [wsgi:error] [pid 5816:tid 1216] [client ::1:58504]     response = get_response(request)\r, referer: http://localhost:90/records/henquiry
[Mon Jan 22 16:31:25.881335 2024] [wsgi:error] [pid 5816:tid 1216] [client ::1:58504]                ^^^^^^^^^^^^^^^^^^^^^\r, referer: http://localhost:90/records/henquiry
[Mon Jan 22 16:31:25.881335 2024] [wsgi:error] [pid 5816:tid 1216] [client ::1:58504]   File "D:\\Kuldeep(Python)\\Project\\env\\Lib\\site-packages\\django\\core\\handlers\\base.py", line 197, in _get_response\r, referer: http://localhost:90/records/henquiry
[Mon Jan 22 16:31:25.881335 2024] [wsgi:error] [pid 5816:tid 1216] [client ::1:58504]     response = wrapped_callback(request, *callback_args, **callback_kwargs)\r, referer: http://localhost:90/records/henquiry
[Mon Jan 22 16:31:25.881335 2024] [wsgi:error] [pid 5816:tid 1216] [client ::1:58504]                ^^^^^^^^^^^^^^^^^^^^^^^^^^^^^^^^^^^^^^^^^^^^^^^^^^^^^^^^^^^^\r, referer: http://localhost:90/records/henquiry
[Mon Jan 22 16:31:25.881335 2024] [wsgi:error] [pid 5816:tid 1216] [client ::1:58504]   File "D:\\Kuldeep(Python)\\Project\\piinfo\\records\\views.py", line 22, in henquiry\r, referer: http://localhost:90/records/henquiry
[Mon Jan 22 16:31:25.881335 2024] [wsgi:error] [pid 5816:tid 1216] [client ::1:58504]     data = HEnquiry(name = name, phone = phone, email=email, interested_in = intrest,\r, referer: http://localhost:90/records/henquiry
[Mon Jan 22 16:31:25.881335 2024] [wsgi:error] [pid 5816:tid 1216] [client ::1:58504]            ^^^^^^^^^^^^^^^^^^^^^^^^^^^^^^^^^^^^^^^^^^^^^^^^^^^^^^^^^^^^^^^^^^^^^^^^^^\r, referer: http://localhost:90/records/henquiry
[Mon Jan 22 16:31:25.881335 2024] [wsgi:error] [pid 5816:tid 1216] [client ::1:58504]   File "D:\\Kuldeep(Python)\\Project\\env\\Lib\\site-packages\\django\\db\\models\\base.py", line 567, in __init__\r, referer: http://localhost:90/records/henquiry
[Mon Jan 22 16:31:25.881335 2024] [wsgi:error] [pid 5816:tid 1216] [client ::1:58504]     raise TypeError(\r, referer: http://localhost:90/records/henquiry
[Mon Jan 22 16:31:25.881335 2024] [wsgi:error] [pid 5816:tid 1216] [client ::1:58504] TypeError: HEnquiry() got unexpected keyword arguments: 'intrested_in'\r, referer: http://localhost:90/records/henquiry
[Mon Jan 22 16:31:38.461335 2024] [wsgi:error] [pid 5816:tid 1216] [client ::1:58524] Arjan Dhillon \r, referer: http://localhost:90/records/henquiry
[Mon Jan 22 16:31:38.461335 2024] [wsgi:error] [pid 5816:tid 1216] [client ::1:58524] \r, referer: http://localhost:90/records/henquiry
[Mon Jan 22 16:31:38.461335 2024] [wsgi:error] [pid 5816:tid 1216] [client ::1:58524] \r, referer: http://localhost:90/records/henquiry
[Mon Jan 22 16:31:38.461335 2024] [wsgi:error] [pid 5816:tid 1216] [client ::1:58524] \r, referer: http://localhost:90/records/henquiry
[Mon Jan 22 16:31:38.461335 2024] [wsgi:error] [pid 5816:tid 1216] [client ::1:58524] \r, referer: http://localhost:90/records/henquiry
[Mon Jan 22 16:31:38.503367 2024] [wsgi:error] [pid 5816:tid 1216] [client ::1:58524] Internal Server Error: /records/henquiry\r, referer: http://localhost:90/records/henquiry
[Mon Jan 22 16:31:38.503367 2024] [wsgi:error] [pid 5816:tid 1216] [client ::1:58524] Traceback (most recent call last):\r, referer: http://localhost:90/records/henquiry
[Mon Jan 22 16:31:38.503367 2024] [wsgi:error] [pid 5816:tid 1216] [client ::1:58524]   File "D:\\Kuldeep(Python)\\Project\\env\\Lib\\site-packages\\django\\core\\handlers\\exception.py", line 55, in inner\r, referer: http://localhost:90/records/henquiry
[Mon Jan 22 16:31:38.503367 2024] [wsgi:error] [pid 5816:tid 1216] [client ::1:58524]     response = get_response(request)\r, referer: http://localhost:90/records/henquiry
[Mon Jan 22 16:31:38.503367 2024] [wsgi:error] [pid 5816:tid 1216] [client ::1:58524]                ^^^^^^^^^^^^^^^^^^^^^\r, referer: http://localhost:90/records/henquiry
[Mon Jan 22 16:31:38.503367 2024] [wsgi:error] [pid 5816:tid 1216] [client ::1:58524]   File "D:\\Kuldeep(Python)\\Project\\env\\Lib\\site-packages\\django\\core\\handlers\\base.py", line 197, in _get_response\r, referer: http://localhost:90/records/henquiry
[Mon Jan 22 16:31:38.503367 2024] [wsgi:error] [pid 5816:tid 1216] [client ::1:58524]     response = wrapped_callback(request, *callback_args, **callback_kwargs)\r, referer: http://localhost:90/records/henquiry
[Mon Jan 22 16:31:38.503367 2024] [wsgi:error] [pid 5816:tid 1216] [client ::1:58524]                ^^^^^^^^^^^^^^^^^^^^^^^^^^^^^^^^^^^^^^^^^^^^^^^^^^^^^^^^^^^^\r, referer: http://localhost:90/records/henquiry
[Mon Jan 22 16:31:38.503367 2024] [wsgi:error] [pid 5816:tid 1216] [client ::1:58524]   File "D:\\Kuldeep(Python)\\Project\\piinfo\\records\\views.py", line 22, in henquiry\r, referer: http://localhost:90/records/henquiry
[Mon Jan 22 16:31:38.503367 2024] [wsgi:error] [pid 5816:tid 1216] [client ::1:58524]     data = HEnquiry(name = name, phone = phone, email=email, interested_in = intrest,\r, referer: http://localhost:90/records/henquiry
[Mon Jan 22 16:31:38.503367 2024] [wsgi:error] [pid 5816:tid 1216] [client ::1:58524]            ^^^^^^^^^^^^^^^^^^^^^^^^^^^^^^^^^^^^^^^^^^^^^^^^^^^^^^^^^^^^^^^^^^^^^^^^^^\r, referer: http://localhost:90/records/henquiry
[Mon Jan 22 16:31:38.503367 2024] [wsgi:error] [pid 5816:tid 1216] [client ::1:58524]   File "D:\\Kuldeep(Python)\\Project\\env\\Lib\\site-packages\\django\\db\\models\\base.py", line 567, in __init__\r, referer: http://localhost:90/records/henquiry
[Mon Jan 22 16:31:38.503367 2024] [wsgi:error] [pid 5816:tid 1216] [client ::1:58524]     raise TypeError(\r, referer: http://localhost:90/records/henquiry
[Mon Jan 22 16:31:38.503367 2024] [wsgi:error] [pid 5816:tid 1216] [client ::1:58524] TypeError: HEnquiry() got unexpected keyword arguments: 'intrested_in'\r, referer: http://localhost:90/records/henquiry
[Mon Jan 22 16:32:01.192335 2024] [wsgi:error] [pid 5816:tid 1216] [client ::1:58554] Arjan Dhillon \r, referer: http://localhost:90/records/henquiry
[Mon Jan 22 16:32:01.192335 2024] [wsgi:error] [pid 5816:tid 1216] [client ::1:58554] \r, referer: http://localhost:90/records/henquiry
[Mon Jan 22 16:32:01.192335 2024] [wsgi:error] [pid 5816:tid 1216] [client ::1:58554] \r, referer: http://localhost:90/records/henquiry
[Mon Jan 22 16:32:01.192335 2024] [wsgi:error] [pid 5816:tid 1216] [client ::1:58554] \r, referer: http://localhost:90/records/henquiry
[Mon Jan 22 16:32:01.192335 2024] [wsgi:error] [pid 5816:tid 1216] [client ::1:58554] \r, referer: http://localhost:90/records/henquiry
[Mon Jan 22 16:32:01.254335 2024] [wsgi:error] [pid 5816:tid 1216] [client ::1:58554] Internal Server Error: /records/henquiry\r, referer: http://localhost:90/records/henquiry
[Mon Jan 22 16:32:01.254335 2024] [wsgi:error] [pid 5816:tid 1216] [client ::1:58554] Traceback (most recent call last):\r, referer: http://localhost:90/records/henquiry
[Mon Jan 22 16:32:01.254335 2024] [wsgi:error] [pid 5816:tid 1216] [client ::1:58554]   File "D:\\Kuldeep(Python)\\Project\\env\\Lib\\site-packages\\django\\core\\handlers\\exception.py", line 55, in inner\r, referer: http://localhost:90/records/henquiry
[Mon Jan 22 16:32:01.254335 2024] [wsgi:error] [pid 5816:tid 1216] [client ::1:58554]     response = get_response(request)\r, referer: http://localhost:90/records/henquiry
[Mon Jan 22 16:32:01.254335 2024] [wsgi:error] [pid 5816:tid 1216] [client ::1:58554]                ^^^^^^^^^^^^^^^^^^^^^\r, referer: http://localhost:90/records/henquiry
[Mon Jan 22 16:32:01.254335 2024] [wsgi:error] [pid 5816:tid 1216] [client ::1:58554]   File "D:\\Kuldeep(Python)\\Project\\env\\Lib\\site-packages\\django\\core\\handlers\\base.py", line 197, in _get_response\r, referer: http://localhost:90/records/henquiry
[Mon Jan 22 16:32:01.254335 2024] [wsgi:error] [pid 5816:tid 1216] [client ::1:58554]     response = wrapped_callback(request, *callback_args, **callback_kwargs)\r, referer: http://localhost:90/records/henquiry
[Mon Jan 22 16:32:01.254335 2024] [wsgi:error] [pid 5816:tid 1216] [client ::1:58554]                ^^^^^^^^^^^^^^^^^^^^^^^^^^^^^^^^^^^^^^^^^^^^^^^^^^^^^^^^^^^^\r, referer: http://localhost:90/records/henquiry
[Mon Jan 22 16:32:01.254335 2024] [wsgi:error] [pid 5816:tid 1216] [client ::1:58554]   File "D:\\Kuldeep(Python)\\Project\\piinfo\\records\\views.py", line 22, in henquiry\r, referer: http://localhost:90/records/henquiry
[Mon Jan 22 16:32:01.254335 2024] [wsgi:error] [pid 5816:tid 1216] [client ::1:58554]     data = HEnquiry(name = name, phone = phone, email=email, intrest = intrest,\r, referer: http://localhost:90/records/henquiry
[Mon Jan 22 16:32:01.254335 2024] [wsgi:error] [pid 5816:tid 1216] [client ::1:58554]            ^^^^^^^^^^^^^^^^^^^^^^^^^^^^^^^^^^^^^^^^^^^^^^^^^^^^^^^^^^^^^^^^^^^^\r, referer: http://localhost:90/records/henquiry
[Mon Jan 22 16:32:01.254335 2024] [wsgi:error] [pid 5816:tid 1216] [client ::1:58554]   File "D:\\Kuldeep(Python)\\Project\\env\\Lib\\site-packages\\django\\db\\models\\base.py", line 567, in __init__\r, referer: http://localhost:90/records/henquiry
[Mon Jan 22 16:32:01.254335 2024] [wsgi:error] [pid 5816:tid 1216] [client ::1:58554]     raise TypeError(\r, referer: http://localhost:90/records/henquiry
[Mon Jan 22 16:32:01.254335 2024] [wsgi:error] [pid 5816:tid 1216] [client ::1:58554] TypeError: HEnquiry() got unexpected keyword arguments: 'intrested_in'\r, referer: http://localhost:90/records/henquiry
[Thu Feb 08 10:52:00.948776 2024] [wsgi:error] [pid 18512:tid 1220] [client 192.168.6.251:53087] mod_wsgi (pid=18512): Failed to exec Python script file 'E:/Kuldeep(Python)/Project/piinfo/piinfo/wsgi.py'.
[Thu Feb 08 10:52:00.948776 2024] [wsgi:error] [pid 18512:tid 1220] [client 192.168.6.251:53087] mod_wsgi (pid=18512): Exception occurred processing WSGI script 'E:/Kuldeep(Python)/Project/piinfo/piinfo/wsgi.py'.
[Thu Feb 08 10:52:01.085744 2024] [wsgi:error] [pid 18512:tid 1220] [client 192.168.6.251:53087] Traceback (most recent call last):\r
[Thu Feb 08 10:52:01.086728 2024] [wsgi:error] [pid 18512:tid 1220] [client 192.168.6.251:53087]   File "E:/Kuldeep(Python)/Project/piinfo/piinfo/wsgi.py", line 31, in <module>\r
[Thu Feb 08 10:52:01.086728 2024] [wsgi:error] [pid 18512:tid 1220] [client 192.168.6.251:53087]     application = get_wsgi_application()\r
[Thu Feb 08 10:52:01.086728 2024] [wsgi:error] [pid 18512:tid 1220] [client 192.168.6.251:53087]                   ^^^^^^^^^^^^^^^^^^^^^^\r
[Thu Feb 08 10:52:01.086728 2024] [wsgi:error] [pid 18512:tid 1220] [client 192.168.6.251:53087]   File "C:\\Program Files\\Python312\\Lib\\site-packages\\django\\core\\wsgi.py", line 12, in get_wsgi_application\r
[Thu Feb 08 10:52:01.086728 2024] [wsgi:error] [pid 18512:tid 1220] [client 192.168.6.251:53087]     django.setup(set_prefix=False)\r
[Thu Feb 08 10:52:01.086728 2024] [wsgi:error] [pid 18512:tid 1220] [client 192.168.6.251:53087]   File "C:\\Program Files\\Python312\\Lib\\site-packages\\django\\__init__.py", line 24, in setup\r
[Thu Feb 08 10:52:01.086728 2024] [wsgi:error] [pid 18512:tid 1220] [client 192.168.6.251:53087]     apps.populate(settings.INSTALLED_APPS)\r
[Thu Feb 08 10:52:01.086728 2024] [wsgi:error] [pid 18512:tid 1220] [client 192.168.6.251:53087]   File "C:\\Program Files\\Python312\\Lib\\site-packages\\django\\apps\\registry.py", line 91, in populate\r
[Thu Feb 08 10:52:01.086728 2024] [wsgi:error] [pid 18512:tid 1220] [client 192.168.6.251:53087]     app_config = AppConfig.create(entry)\r
[Thu Feb 08 10:52:01.086728 2024] [wsgi:error] [pid 18512:tid 1220] [client 192.168.6.251:53087]                  ^^^^^^^^^^^^^^^^^^^^^^^\r
[Thu Feb 08 10:52:01.086728 2024] [wsgi:error] [pid 18512:tid 1220] [client 192.168.6.251:53087]   File "C:\\Program Files\\Python312\\Lib\\site-packages\\django\\apps\\config.py", line 193, in create\r
[Thu Feb 08 10:52:01.086728 2024] [wsgi:error] [pid 18512:tid 1220] [client 192.168.6.251:53087]     import_module(entry)\r
[Thu Feb 08 10:52:01.086728 2024] [wsgi:error] [pid 18512:tid 1220] [client 192.168.6.251:53087]   File "C:\\Program Files\\Python312\\Lib\\importlib\\__init__.py", line 90, in import_module\r
[Thu Feb 08 10:52:01.086728 2024] [wsgi:error] [pid 18512:tid 1220] [client 192.168.6.251:53087]     return _bootstrap._gcd_import(name[level:], package, level)\r
[Thu Feb 08 10:52:01.086728 2024] [wsgi:error] [pid 18512:tid 1220] [client 192.168.6.251:53087]            ^^^^^^^^^^^^^^^^^^^^^^^^^^^^^^^^^^^^^^^^^^^^^^^^^^^^\r
[Thu Feb 08 10:52:01.086728 2024] [wsgi:error] [pid 18512:tid 1220] [client 192.168.6.251:53087]   File "<frozen importlib._bootstrap>", line 1381, in _gcd_import\r
[Thu Feb 08 10:52:01.086728 2024] [wsgi:error] [pid 18512:tid 1220] [client 192.168.6.251:53087]   File "<frozen importlib._bootstrap>", line 1354, in _find_and_load\r
[Thu Feb 08 10:52:01.086728 2024] [wsgi:error] [pid 18512:tid 1220] [client 192.168.6.251:53087]   File "<frozen importlib._bootstrap>", line 1318, in _find_and_load_unlocked\r
[Thu Feb 08 10:52:01.086728 2024] [wsgi:error] [pid 18512:tid 1220] [client 192.168.6.251:53087] ModuleNotFoundError: No module named 'jazzmin'\r
[Thu Feb 08 10:52:01.128766 2024] [wsgi:error] [pid 18512:tid 1208] [client 192.168.6.251:53088] mod_wsgi (pid=18512): Failed to exec Python script file 'E:/Kuldeep(Python)/Project/piinfo/piinfo/wsgi.py'., referer: http://192.168.6.251:90/
[Thu Feb 08 10:52:01.129728 2024] [wsgi:error] [pid 18512:tid 1208] [client 192.168.6.251:53088] mod_wsgi (pid=18512): Exception occurred processing WSGI script 'E:/Kuldeep(Python)/Project/piinfo/piinfo/wsgi.py'., referer: http://192.168.6.251:90/
[Thu Feb 08 10:52:01.129728 2024] [wsgi:error] [pid 18512:tid 1208] [client 192.168.6.251:53088] Traceback (most recent call last):\r, referer: http://192.168.6.251:90/
[Thu Feb 08 10:52:01.130726 2024] [wsgi:error] [pid 18512:tid 1208] [client 192.168.6.251:53088]   File "E:/Kuldeep(Python)/Project/piinfo/piinfo/wsgi.py", line 31, in <module>\r, referer: http://192.168.6.251:90/
[Thu Feb 08 10:52:01.130726 2024] [wsgi:error] [pid 18512:tid 1208] [client 192.168.6.251:53088]     application = get_wsgi_application()\r, referer: http://192.168.6.251:90/
[Thu Feb 08 10:52:01.130726 2024] [wsgi:error] [pid 18512:tid 1208] [client 192.168.6.251:53088]                   ^^^^^^^^^^^^^^^^^^^^^^\r, referer: http://192.168.6.251:90/
[Thu Feb 08 10:52:01.130726 2024] [wsgi:error] [pid 18512:tid 1208] [client 192.168.6.251:53088]   File "C:\\Program Files\\Python312\\Lib\\site-packages\\django\\core\\wsgi.py", line 12, in get_wsgi_application\r, referer: http://192.168.6.251:90/
[Thu Feb 08 10:52:01.130726 2024] [wsgi:error] [pid 18512:tid 1208] [client 192.168.6.251:53088]     django.setup(set_prefix=False)\r, referer: http://192.168.6.251:90/
[Thu Feb 08 10:52:01.130726 2024] [wsgi:error] [pid 18512:tid 1208] [client 192.168.6.251:53088]   File "C:\\Program Files\\Python312\\Lib\\site-packages\\django\\__init__.py", line 24, in setup\r, referer: http://192.168.6.251:90/
[Thu Feb 08 10:52:01.130726 2024] [wsgi:error] [pid 18512:tid 1208] [client 192.168.6.251:53088]     apps.populate(settings.INSTALLED_APPS)\r, referer: http://192.168.6.251:90/
[Thu Feb 08 10:52:01.130726 2024] [wsgi:error] [pid 18512:tid 1208] [client 192.168.6.251:53088]   File "C:\\Program Files\\Python312\\Lib\\site-packages\\django\\apps\\registry.py", line 83, in populate\r, referer: http://192.168.6.251:90/
[Thu Feb 08 10:52:01.130726 2024] [wsgi:error] [pid 18512:tid 1208] [client 192.168.6.251:53088]     raise RuntimeError("populate() isn't reentrant")\r, referer: http://192.168.6.251:90/
[Thu Feb 08 10:52:01.130726 2024] [wsgi:error] [pid 18512:tid 1208] [client 192.168.6.251:53088] RuntimeError: populate() isn't reentrant\r, referer: http://192.168.6.251:90/
[Thu Feb 08 10:54:29.806630 2024] [wsgi:error] [pid 13048:tid 1248] [client 192.168.6.251:53142] mod_wsgi (pid=13048): Failed to exec Python script file 'E:/Kuldeep(Python)/Project/piinfo/piinfo/wsgi.py'.
[Thu Feb 08 10:54:29.806630 2024] [wsgi:error] [pid 13048:tid 1248] [client 192.168.6.251:53142] mod_wsgi (pid=13048): Exception occurred processing WSGI script 'E:/Kuldeep(Python)/Project/piinfo/piinfo/wsgi.py'.
[Thu Feb 08 10:54:29.809643 2024] [wsgi:error] [pid 13048:tid 1248] [client 192.168.6.251:53142] Traceback (most recent call last):\r
[Thu Feb 08 10:54:29.810630 2024] [wsgi:error] [pid 13048:tid 1248] [client 192.168.6.251:53142]   File "E:/Kuldeep(Python)/Project/piinfo/piinfo/wsgi.py", line 31, in <module>\r
[Thu Feb 08 10:54:29.810630 2024] [wsgi:error] [pid 13048:tid 1248] [client 192.168.6.251:53142]     application = get_wsgi_application()\r
[Thu Feb 08 10:54:29.810630 2024] [wsgi:error] [pid 13048:tid 1248] [client 192.168.6.251:53142]                   ^^^^^^^^^^^^^^^^^^^^^^\r
[Thu Feb 08 10:54:29.810630 2024] [wsgi:error] [pid 13048:tid 1248] [client 192.168.6.251:53142]   File "C:\\Program Files\\Python312\\Lib\\site-packages\\django\\core\\wsgi.py", line 12, in get_wsgi_application\r
[Thu Feb 08 10:54:29.810630 2024] [wsgi:error] [pid 13048:tid 1248] [client 192.168.6.251:53142]     django.setup(set_prefix=False)\r
[Thu Feb 08 10:54:29.810630 2024] [wsgi:error] [pid 13048:tid 1248] [client 192.168.6.251:53142]   File "C:\\Program Files\\Python312\\Lib\\site-packages\\django\\__init__.py", line 24, in setup\r
[Thu Feb 08 10:54:29.810630 2024] [wsgi:error] [pid 13048:tid 1248] [client 192.168.6.251:53142]     apps.populate(settings.INSTALLED_APPS)\r
[Thu Feb 08 10:54:29.810630 2024] [wsgi:error] [pid 13048:tid 1248] [client 192.168.6.251:53142]   File "C:\\Program Files\\Python312\\Lib\\site-packages\\django\\apps\\registry.py", line 91, in populate\r
[Thu Feb 08 10:54:29.810630 2024] [wsgi:error] [pid 13048:tid 1248] [client 192.168.6.251:53142]     app_config = AppConfig.create(entry)\r
[Thu Feb 08 10:54:29.810630 2024] [wsgi:error] [pid 13048:tid 1248] [client 192.168.6.251:53142]                  ^^^^^^^^^^^^^^^^^^^^^^^\r
[Thu Feb 08 10:54:29.810630 2024] [wsgi:error] [pid 13048:tid 1248] [client 192.168.6.251:53142]   File "C:\\Program Files\\Python312\\Lib\\site-packages\\django\\apps\\config.py", line 193, in create\r
[Thu Feb 08 10:54:29.810630 2024] [wsgi:error] [pid 13048:tid 1248] [client 192.168.6.251:53142]     import_module(entry)\r
[Thu Feb 08 10:54:29.810630 2024] [wsgi:error] [pid 13048:tid 1248] [client 192.168.6.251:53142]   File "C:\\Program Files\\Python312\\Lib\\importlib\\__init__.py", line 90, in import_module\r
[Thu Feb 08 10:54:29.810630 2024] [wsgi:error] [pid 13048:tid 1248] [client 192.168.6.251:53142]     return _bootstrap._gcd_import(name[level:], package, level)\r
[Thu Feb 08 10:54:29.810630 2024] [wsgi:error] [pid 13048:tid 1248] [client 192.168.6.251:53142]            ^^^^^^^^^^^^^^^^^^^^^^^^^^^^^^^^^^^^^^^^^^^^^^^^^^^^\r
[Thu Feb 08 10:54:29.810630 2024] [wsgi:error] [pid 13048:tid 1248] [client 192.168.6.251:53142]   File "<frozen importlib._bootstrap>", line 1381, in _gcd_import\r
[Thu Feb 08 10:54:29.810630 2024] [wsgi:error] [pid 13048:tid 1248] [client 192.168.6.251:53142]   File "<frozen importlib._bootstrap>", line 1354, in _find_and_load\r
[Thu Feb 08 10:54:29.810630 2024] [wsgi:error] [pid 13048:tid 1248] [client 192.168.6.251:53142]   File "<frozen importlib._bootstrap>", line 1318, in _find_and_load_unlocked\r
[Thu Feb 08 10:54:29.810630 2024] [wsgi:error] [pid 13048:tid 1248] [client 192.168.6.251:53142] ModuleNotFoundError: No module named 'tinymce'\r
[Thu Feb 08 10:54:29.833688 2024] [wsgi:error] [pid 13048:tid 1244] [client 192.168.6.251:53143] mod_wsgi (pid=13048): Failed to exec Python script file 'E:/Kuldeep(Python)/Project/piinfo/piinfo/wsgi.py'., referer: http://192.168.6.251:90/
[Thu Feb 08 10:54:29.834686 2024] [wsgi:error] [pid 13048:tid 1244] [client 192.168.6.251:53143] mod_wsgi (pid=13048): Exception occurred processing WSGI script 'E:/Kuldeep(Python)/Project/piinfo/piinfo/wsgi.py'., referer: http://192.168.6.251:90/
[Thu Feb 08 10:54:29.834686 2024] [wsgi:error] [pid 13048:tid 1244] [client 192.168.6.251:53143] Traceback (most recent call last):\r, referer: http://192.168.6.251:90/
[Thu Feb 08 10:54:29.834686 2024] [wsgi:error] [pid 13048:tid 1244] [client 192.168.6.251:53143]   File "E:/Kuldeep(Python)/Project/piinfo/piinfo/wsgi.py", line 31, in <module>\r, referer: http://192.168.6.251:90/
[Thu Feb 08 10:54:29.834686 2024] [wsgi:error] [pid 13048:tid 1244] [client 192.168.6.251:53143]     application = get_wsgi_application()\r, referer: http://192.168.6.251:90/
[Thu Feb 08 10:54:29.834686 2024] [wsgi:error] [pid 13048:tid 1244] [client 192.168.6.251:53143]                   ^^^^^^^^^^^^^^^^^^^^^^\r, referer: http://192.168.6.251:90/
[Thu Feb 08 10:54:29.834686 2024] [wsgi:error] [pid 13048:tid 1244] [client 192.168.6.251:53143]   File "C:\\Program Files\\Python312\\Lib\\site-packages\\django\\core\\wsgi.py", line 12, in get_wsgi_application\r, referer: http://192.168.6.251:90/
[Thu Feb 08 10:54:29.834686 2024] [wsgi:error] [pid 13048:tid 1244] [client 192.168.6.251:53143]     django.setup(set_prefix=False)\r, referer: http://192.168.6.251:90/
[Thu Feb 08 10:54:29.834686 2024] [wsgi:error] [pid 13048:tid 1244] [client 192.168.6.251:53143]   File "C:\\Program Files\\Python312\\Lib\\site-packages\\django\\__init__.py", line 24, in setup\r, referer: http://192.168.6.251:90/
[Thu Feb 08 10:54:29.834686 2024] [wsgi:error] [pid 13048:tid 1244] [client 192.168.6.251:53143]     apps.populate(settings.INSTALLED_APPS)\r, referer: http://192.168.6.251:90/
[Thu Feb 08 10:54:29.834686 2024] [wsgi:error] [pid 13048:tid 1244] [client 192.168.6.251:53143]   File "C:\\Program Files\\Python312\\Lib\\site-packages\\django\\apps\\registry.py", line 83, in populate\r, referer: http://192.168.6.251:90/
[Thu Feb 08 10:54:29.834686 2024] [wsgi:error] [pid 13048:tid 1244] [client 192.168.6.251:53143]     raise RuntimeError("populate() isn't reentrant")\r, referer: http://192.168.6.251:90/
[Thu Feb 08 10:54:29.834686 2024] [wsgi:error] [pid 13048:tid 1244] [client 192.168.6.251:53143] RuntimeError: populate() isn't reentrant\r, referer: http://192.168.6.251:90/
[Thu Feb 08 10:55:43.800038 2024] [wsgi:error] [pid 13048:tid 1244] [client 192.168.6.251:53160] mod_wsgi (pid=13048): Failed to exec Python script file 'E:/Kuldeep(Python)/Project/piinfo/piinfo/wsgi.py'.
[Thu Feb 08 10:55:43.800038 2024] [wsgi:error] [pid 13048:tid 1244] [client 192.168.6.251:53160] mod_wsgi (pid=13048): Exception occurred processing WSGI script 'E:/Kuldeep(Python)/Project/piinfo/piinfo/wsgi.py'.
[Thu Feb 08 10:55:43.801038 2024] [wsgi:error] [pid 13048:tid 1244] [client 192.168.6.251:53160] Traceback (most recent call last):\r
[Thu Feb 08 10:55:43.801038 2024] [wsgi:error] [pid 13048:tid 1244] [client 192.168.6.251:53160]   File "E:/Kuldeep(Python)/Project/piinfo/piinfo/wsgi.py", line 31, in <module>\r
[Thu Feb 08 10:55:43.801038 2024] [wsgi:error] [pid 13048:tid 1244] [client 192.168.6.251:53160]     application = get_wsgi_application()\r
[Thu Feb 08 10:55:43.801038 2024] [wsgi:error] [pid 13048:tid 1244] [client 192.168.6.251:53160]                   ^^^^^^^^^^^^^^^^^^^^^^\r
[Thu Feb 08 10:55:43.801038 2024] [wsgi:error] [pid 13048:tid 1244] [client 192.168.6.251:53160]   File "C:\\Program Files\\Python312\\Lib\\site-packages\\django\\core\\wsgi.py", line 12, in get_wsgi_application\r
[Thu Feb 08 10:55:43.801038 2024] [wsgi:error] [pid 13048:tid 1244] [client 192.168.6.251:53160]     django.setup(set_prefix=False)\r
[Thu Feb 08 10:55:43.801038 2024] [wsgi:error] [pid 13048:tid 1244] [client 192.168.6.251:53160]   File "C:\\Program Files\\Python312\\Lib\\site-packages\\django\\__init__.py", line 24, in setup\r
[Thu Feb 08 10:55:43.801038 2024] [wsgi:error] [pid 13048:tid 1244] [client 192.168.6.251:53160]     apps.populate(settings.INSTALLED_APPS)\r
[Thu Feb 08 10:55:43.801038 2024] [wsgi:error] [pid 13048:tid 1244] [client 192.168.6.251:53160]   File "C:\\Program Files\\Python312\\Lib\\site-packages\\django\\apps\\registry.py", line 83, in populate\r
[Thu Feb 08 10:55:43.801038 2024] [wsgi:error] [pid 13048:tid 1244] [client 192.168.6.251:53160]     raise RuntimeError("populate() isn't reentrant")\r
[Thu Feb 08 10:55:43.801038 2024] [wsgi:error] [pid 13048:tid 1244] [client 192.168.6.251:53160] RuntimeError: populate() isn't reentrant\r
[Thu Feb 08 10:55:43.822029 2024] [wsgi:error] [pid 13048:tid 1248] [client 192.168.6.251:53161] mod_wsgi (pid=13048): Failed to exec Python script file 'E:/Kuldeep(Python)/Project/piinfo/piinfo/wsgi.py'., referer: http://192.168.6.251:90/
[Thu Feb 08 10:55:43.822029 2024] [wsgi:error] [pid 13048:tid 1248] [client 192.168.6.251:53161] mod_wsgi (pid=13048): Exception occurred processing WSGI script 'E:/Kuldeep(Python)/Project/piinfo/piinfo/wsgi.py'., referer: http://192.168.6.251:90/
[Thu Feb 08 10:55:43.823086 2024] [wsgi:error] [pid 13048:tid 1248] [client 192.168.6.251:53161] Traceback (most recent call last):\r, referer: http://192.168.6.251:90/
[Thu Feb 08 10:55:43.823086 2024] [wsgi:error] [pid 13048:tid 1248] [client 192.168.6.251:53161]   File "E:/Kuldeep(Python)/Project/piinfo/piinfo/wsgi.py", line 31, in <module>\r, referer: http://192.168.6.251:90/
[Thu Feb 08 10:55:43.823086 2024] [wsgi:error] [pid 13048:tid 1248] [client 192.168.6.251:53161]     application = get_wsgi_application()\r, referer: http://192.168.6.251:90/
[Thu Feb 08 10:55:43.823086 2024] [wsgi:error] [pid 13048:tid 1248] [client 192.168.6.251:53161]                   ^^^^^^^^^^^^^^^^^^^^^^\r, referer: http://192.168.6.251:90/
[Thu Feb 08 10:55:43.823086 2024] [wsgi:error] [pid 13048:tid 1248] [client 192.168.6.251:53161]   File "C:\\Program Files\\Python312\\Lib\\site-packages\\django\\core\\wsgi.py", line 12, in get_wsgi_application\r, referer: http://192.168.6.251:90/
[Thu Feb 08 10:55:43.823086 2024] [wsgi:error] [pid 13048:tid 1248] [client 192.168.6.251:53161]     django.setup(set_prefix=False)\r, referer: http://192.168.6.251:90/
[Thu Feb 08 10:55:43.823086 2024] [wsgi:error] [pid 13048:tid 1248] [client 192.168.6.251:53161]   File "C:\\Program Files\\Python312\\Lib\\site-packages\\django\\__init__.py", line 24, in setup\r, referer: http://192.168.6.251:90/
[Thu Feb 08 10:55:43.823086 2024] [wsgi:error] [pid 13048:tid 1248] [client 192.168.6.251:53161]     apps.populate(settings.INSTALLED_APPS)\r, referer: http://192.168.6.251:90/
[Thu Feb 08 10:55:43.823086 2024] [wsgi:error] [pid 13048:tid 1248] [client 192.168.6.251:53161]   File "C:\\Program Files\\Python312\\Lib\\site-packages\\django\\apps\\registry.py", line 83, in populate\r, referer: http://192.168.6.251:90/
[Thu Feb 08 10:55:43.823086 2024] [wsgi:error] [pid 13048:tid 1248] [client 192.168.6.251:53161]     raise RuntimeError("populate() isn't reentrant")\r, referer: http://192.168.6.251:90/
[Thu Feb 08 10:55:43.823086 2024] [wsgi:error] [pid 13048:tid 1248] [client 192.168.6.251:53161] RuntimeError: populate() isn't reentrant\r, referer: http://192.168.6.251:90/
[Thu Feb 08 10:55:57.168978 2024] [wsgi:error] [pid 5324:tid 1248] [client 192.168.6.251:53163] mod_wsgi (pid=5324): Failed to exec Python script file 'E:/Kuldeep(Python)/Project/piinfo/piinfo/wsgi.py'.
[Thu Feb 08 10:55:57.169931 2024] [wsgi:error] [pid 5324:tid 1248] [client 192.168.6.251:53163] mod_wsgi (pid=5324): Exception occurred processing WSGI script 'E:/Kuldeep(Python)/Project/piinfo/piinfo/wsgi.py'.
[Thu Feb 08 10:55:57.310931 2024] [wsgi:error] [pid 5324:tid 1248] [client 192.168.6.251:53163] Traceback (most recent call last):\r
[Thu Feb 08 10:55:57.311921 2024] [wsgi:error] [pid 5324:tid 1248] [client 192.168.6.251:53163]   File "E:/Kuldeep(Python)/Project/piinfo/piinfo/wsgi.py", line 31, in <module>\r
[Thu Feb 08 10:55:57.311921 2024] [wsgi:error] [pid 5324:tid 1248] [client 192.168.6.251:53163]     application = get_wsgi_application()\r
[Thu Feb 08 10:55:57.311921 2024] [wsgi:error] [pid 5324:tid 1248] [client 192.168.6.251:53163]                   ^^^^^^^^^^^^^^^^^^^^^^\r
[Thu Feb 08 10:55:57.311921 2024] [wsgi:error] [pid 5324:tid 1248] [client 192.168.6.251:53163]   File "C:\\Program Files\\Python312\\Lib\\site-packages\\django\\core\\wsgi.py", line 13, in get_wsgi_application\r
[Thu Feb 08 10:55:57.311921 2024] [wsgi:error] [pid 5324:tid 1248] [client 192.168.6.251:53163]     return WSGIHandler()\r
[Thu Feb 08 10:55:57.311921 2024] [wsgi:error] [pid 5324:tid 1248] [client 192.168.6.251:53163]            ^^^^^^^^^^^^^\r
[Thu Feb 08 10:55:57.311921 2024] [wsgi:error] [pid 5324:tid 1248] [client 192.168.6.251:53163]   File "C:\\Program Files\\Python312\\Lib\\site-packages\\django\\core\\handlers\\wsgi.py", line 118, in __init__\r
[Thu Feb 08 10:55:57.311921 2024] [wsgi:error] [pid 5324:tid 1248] [client 192.168.6.251:53163]     self.load_middleware()\r
[Thu Feb 08 10:55:57.311921 2024] [wsgi:error] [pid 5324:tid 1248] [client 192.168.6.251:53163]   File "C:\\Program Files\\Python312\\Lib\\site-packages\\django\\core\\handlers\\base.py", line 40, in load_middleware\r
[Thu Feb 08 10:55:57.311921 2024] [wsgi:error] [pid 5324:tid 1248] [client 192.168.6.251:53163]     middleware = import_string(middleware_path)\r
[Thu Feb 08 10:55:57.311921 2024] [wsgi:error] [pid 5324:tid 1248] [client 192.168.6.251:53163]                  ^^^^^^^^^^^^^^^^^^^^^^^^^^^^^^\r
[Thu Feb 08 10:55:57.311921 2024] [wsgi:error] [pid 5324:tid 1248] [client 192.168.6.251:53163]   File "C:\\Program Files\\Python312\\Lib\\site-packages\\django\\utils\\module_loading.py", line 30, in import_string\r
[Thu Feb 08 10:55:57.311921 2024] [wsgi:error] [pid 5324:tid 1248] [client 192.168.6.251:53163]     return cached_import(module_path, class_name)\r
[Thu Feb 08 10:55:57.311921 2024] [wsgi:error] [pid 5324:tid 1248] [client 192.168.6.251:53163]            ^^^^^^^^^^^^^^^^^^^^^^^^^^^^^^^^^^^^^^\r
[Thu Feb 08 10:55:57.311921 2024] [wsgi:error] [pid 5324:tid 1248] [client 192.168.6.251:53163]   File "C:\\Program Files\\Python312\\Lib\\site-packages\\django\\utils\\module_loading.py", line 15, in cached_import\r
[Thu Feb 08 10:55:57.311921 2024] [wsgi:error] [pid 5324:tid 1248] [client 192.168.6.251:53163]     module = import_module(module_path)\r
[Thu Feb 08 10:55:57.311921 2024] [wsgi:error] [pid 5324:tid 1248] [client 192.168.6.251:53163]              ^^^^^^^^^^^^^^^^^^^^^^^^^^\r
[Thu Feb 08 10:55:57.311921 2024] [wsgi:error] [pid 5324:tid 1248] [client 192.168.6.251:53163]   File "C:\\Program Files\\Python312\\Lib\\importlib\\__init__.py", line 90, in import_module\r
[Thu Feb 08 10:55:57.311921 2024] [wsgi:error] [pid 5324:tid 1248] [client 192.168.6.251:53163]     return _bootstrap._gcd_import(name[level:], package, level)\r
[Thu Feb 08 10:55:57.311921 2024] [wsgi:error] [pid 5324:tid 1248] [client 192.168.6.251:53163]            ^^^^^^^^^^^^^^^^^^^^^^^^^^^^^^^^^^^^^^^^^^^^^^^^^^^^\r
[Thu Feb 08 10:55:57.311921 2024] [wsgi:error] [pid 5324:tid 1248] [client 192.168.6.251:53163]   File "<frozen importlib._bootstrap>", line 1381, in _gcd_import\r
[Thu Feb 08 10:55:57.313006 2024] [wsgi:error] [pid 5324:tid 1248] [client 192.168.6.251:53163]   File "<frozen importlib._bootstrap>", line 1354, in _find_and_load\r
[Thu Feb 08 10:55:57.313006 2024] [wsgi:error] [pid 5324:tid 1248] [client 192.168.6.251:53163]   File "<frozen importlib._bootstrap>", line 1304, in _find_and_load_unlocked\r
[Thu Feb 08 10:55:57.313006 2024] [wsgi:error] [pid 5324:tid 1248] [client 192.168.6.251:53163]   File "<frozen importlib._bootstrap>", line 488, in _call_with_frames_removed\r
[Thu Feb 08 10:55:57.313006 2024] [wsgi:error] [pid 5324:tid 1248] [client 192.168.6.251:53163]   File "<frozen importlib._bootstrap>", line 1381, in _gcd_import\r
[Thu Feb 08 10:55:57.313006 2024] [wsgi:error] [pid 5324:tid 1248] [client 192.168.6.251:53163]   File "<frozen importlib._bootstrap>", line 1354, in _find_and_load\r
[Thu Feb 08 10:55:57.313006 2024] [wsgi:error] [pid 5324:tid 1248] [client 192.168.6.251:53163]   File "<frozen importlib._bootstrap>", line 1318, in _find_and_load_unlocked\r
[Thu Feb 08 10:55:57.313006 2024] [wsgi:error] [pid 5324:tid 1248] [client 192.168.6.251:53163] ModuleNotFoundError: No module named 'whitenoise'\r
[Thu Feb 08 10:55:57.338950 2024] [wsgi:error] [pid 5324:tid 1244] [client 192.168.6.251:53164] mod_wsgi (pid=5324): Failed to exec Python script file 'E:/Kuldeep(Python)/Project/piinfo/piinfo/wsgi.py'., referer: http://192.168.6.251:90/
[Thu Feb 08 10:55:57.338950 2024] [wsgi:error] [pid 5324:tid 1244] [client 192.168.6.251:53164] mod_wsgi (pid=5324): Exception occurred processing WSGI script 'E:/Kuldeep(Python)/Project/piinfo/piinfo/wsgi.py'., referer: http://192.168.6.251:90/
[Thu Feb 08 10:55:57.339968 2024] [wsgi:error] [pid 5324:tid 1244] [client 192.168.6.251:53164] Traceback (most recent call last):\r, referer: http://192.168.6.251:90/
[Thu Feb 08 10:55:57.340976 2024] [wsgi:error] [pid 5324:tid 1244] [client 192.168.6.251:53164]   File "E:/Kuldeep(Python)/Project/piinfo/piinfo/wsgi.py", line 31, in <module>\r, referer: http://192.168.6.251:90/
[Thu Feb 08 10:55:57.340976 2024] [wsgi:error] [pid 5324:tid 1244] [client 192.168.6.251:53164]     application = get_wsgi_application()\r, referer: http://192.168.6.251:90/
[Thu Feb 08 10:55:57.340976 2024] [wsgi:error] [pid 5324:tid 1244] [client 192.168.6.251:53164]                   ^^^^^^^^^^^^^^^^^^^^^^\r, referer: http://192.168.6.251:90/
[Thu Feb 08 10:55:57.340976 2024] [wsgi:error] [pid 5324:tid 1244] [client 192.168.6.251:53164]   File "C:\\Program Files\\Python312\\Lib\\site-packages\\django\\core\\wsgi.py", line 13, in get_wsgi_application\r, referer: http://192.168.6.251:90/
[Thu Feb 08 10:55:57.340976 2024] [wsgi:error] [pid 5324:tid 1244] [client 192.168.6.251:53164]     return WSGIHandler()\r, referer: http://192.168.6.251:90/
[Thu Feb 08 10:55:57.340976 2024] [wsgi:error] [pid 5324:tid 1244] [client 192.168.6.251:53164]            ^^^^^^^^^^^^^\r, referer: http://192.168.6.251:90/
[Thu Feb 08 10:55:57.340976 2024] [wsgi:error] [pid 5324:tid 1244] [client 192.168.6.251:53164]   File "C:\\Program Files\\Python312\\Lib\\site-packages\\django\\core\\handlers\\wsgi.py", line 118, in __init__\r, referer: http://192.168.6.251:90/
[Thu Feb 08 10:55:57.340976 2024] [wsgi:error] [pid 5324:tid 1244] [client 192.168.6.251:53164]     self.load_middleware()\r, referer: http://192.168.6.251:90/
[Thu Feb 08 10:55:57.340976 2024] [wsgi:error] [pid 5324:tid 1244] [client 192.168.6.251:53164]   File "C:\\Program Files\\Python312\\Lib\\site-packages\\django\\core\\handlers\\base.py", line 40, in load_middleware\r, referer: http://192.168.6.251:90/
[Thu Feb 08 10:55:57.340976 2024] [wsgi:error] [pid 5324:tid 1244] [client 192.168.6.251:53164]     middleware = import_string(middleware_path)\r, referer: http://192.168.6.251:90/
[Thu Feb 08 10:55:57.340976 2024] [wsgi:error] [pid 5324:tid 1244] [client 192.168.6.251:53164]                  ^^^^^^^^^^^^^^^^^^^^^^^^^^^^^^\r, referer: http://192.168.6.251:90/
[Thu Feb 08 10:55:57.340976 2024] [wsgi:error] [pid 5324:tid 1244] [client 192.168.6.251:53164]   File "C:\\Program Files\\Python312\\Lib\\site-packages\\django\\utils\\module_loading.py", line 30, in import_string\r, referer: http://192.168.6.251:90/
[Thu Feb 08 10:55:57.340976 2024] [wsgi:error] [pid 5324:tid 1244] [client 192.168.6.251:53164]     return cached_import(module_path, class_name)\r, referer: http://192.168.6.251:90/
[Thu Feb 08 10:55:57.340976 2024] [wsgi:error] [pid 5324:tid 1244] [client 192.168.6.251:53164]            ^^^^^^^^^^^^^^^^^^^^^^^^^^^^^^^^^^^^^^\r, referer: http://192.168.6.251:90/
[Thu Feb 08 10:55:57.340976 2024] [wsgi:error] [pid 5324:tid 1244] [client 192.168.6.251:53164]   File "C:\\Program Files\\Python312\\Lib\\site-packages\\django\\utils\\module_loading.py", line 15, in cached_import\r, referer: http://192.168.6.251:90/
[Thu Feb 08 10:55:57.340976 2024] [wsgi:error] [pid 5324:tid 1244] [client 192.168.6.251:53164]     module = import_module(module_path)\r, referer: http://192.168.6.251:90/
[Thu Feb 08 10:55:57.340976 2024] [wsgi:error] [pid 5324:tid 1244] [client 192.168.6.251:53164]              ^^^^^^^^^^^^^^^^^^^^^^^^^^\r, referer: http://192.168.6.251:90/
[Thu Feb 08 10:55:57.340976 2024] [wsgi:error] [pid 5324:tid 1244] [client 192.168.6.251:53164]   File "C:\\Program Files\\Python312\\Lib\\importlib\\__init__.py", line 90, in import_module\r, referer: http://192.168.6.251:90/
[Thu Feb 08 10:55:57.340976 2024] [wsgi:error] [pid 5324:tid 1244] [client 192.168.6.251:53164]     return _bootstrap._gcd_import(name[level:], package, level)\r, referer: http://192.168.6.251:90/
[Thu Feb 08 10:55:57.340976 2024] [wsgi:error] [pid 5324:tid 1244] [client 192.168.6.251:53164]            ^^^^^^^^^^^^^^^^^^^^^^^^^^^^^^^^^^^^^^^^^^^^^^^^^^^^\r, referer: http://192.168.6.251:90/
[Thu Feb 08 10:55:57.340976 2024] [wsgi:error] [pid 5324:tid 1244] [client 192.168.6.251:53164]   File "<frozen importlib._bootstrap>", line 1381, in _gcd_import\r, referer: http://192.168.6.251:90/
[Thu Feb 08 10:55:57.340976 2024] [wsgi:error] [pid 5324:tid 1244] [client 192.168.6.251:53164]   File "<frozen importlib._bootstrap>", line 1354, in _find_and_load\r, referer: http://192.168.6.251:90/
[Thu Feb 08 10:55:57.340976 2024] [wsgi:error] [pid 5324:tid 1244] [client 192.168.6.251:53164]   File "<frozen importlib._bootstrap>", line 1304, in _find_and_load_unlocked\r, referer: http://192.168.6.251:90/
[Thu Feb 08 10:55:57.340976 2024] [wsgi:error] [pid 5324:tid 1244] [client 192.168.6.251:53164]   File "<frozen importlib._bootstrap>", line 488, in _call_with_frames_removed\r, referer: http://192.168.6.251:90/
[Thu Feb 08 10:55:57.340976 2024] [wsgi:error] [pid 5324:tid 1244] [client 192.168.6.251:53164]   File "<frozen importlib._bootstrap>", line 1381, in _gcd_import\r, referer: http://192.168.6.251:90/
[Thu Feb 08 10:55:57.341976 2024] [wsgi:error] [pid 5324:tid 1244] [client 192.168.6.251:53164]   File "<frozen importlib._bootstrap>", line 1354, in _find_and_load\r, referer: http://192.168.6.251:90/
[Thu Feb 08 10:55:57.341976 2024] [wsgi:error] [pid 5324:tid 1244] [client 192.168.6.251:53164]   File "<frozen importlib._bootstrap>", line 1318, in _find_and_load_unlocked\r, referer: http://192.168.6.251:90/
[Thu Feb 08 10:55:57.341976 2024] [wsgi:error] [pid 5324:tid 1244] [client 192.168.6.251:53164] ModuleNotFoundError: No module named 'whitenoise'\r, referer: http://192.168.6.251:90/
[Thu Feb 08 11:03:46.618403 2024] [authz_core:error] [pid 8552:tid 1248] [client 192.168.6.251:53293] AH01630: client denied by server configuration: E:/Kuldeep(Python)/Project/piinfo/css, referer: http://192.168.6.251:90/
[Thu Feb 08 11:03:46.618403 2024] [authz_core:error] [pid 8552:tid 1244] [client 192.168.6.251:53294] AH01630: client denied by server configuration: E:/Kuldeep(Python)/Project/piinfo/css, referer: http://192.168.6.251:90/
[Thu Feb 08 11:03:46.619404 2024] [authz_core:error] [pid 8552:tid 1236] [client 192.168.6.251:53295] AH01630: client denied by server configuration: E:/Kuldeep(Python)/Project/piinfo/vendor, referer: http://192.168.6.251:90/
[Thu Feb 08 11:03:46.622437 2024] [authz_core:error] [pid 8552:tid 1228] [client 192.168.6.251:53296] AH01630: client denied by server configuration: E:/Kuldeep(Python)/Project/piinfo/vendor, referer: http://192.168.6.251:90/
[Thu Feb 08 11:03:46.622437 2024] [authz_core:error] [pid 8552:tid 1220] [client 192.168.6.251:53297] AH01630: client denied by server configuration: E:/Kuldeep(Python)/Project/piinfo/vendor, referer: http://192.168.6.251:90/
[Thu Feb 08 11:03:46.622437 2024] [authz_core:error] [pid 8552:tid 1212] [client 192.168.6.251:53298] AH01630: client denied by server configuration: E:/Kuldeep(Python)/Project/piinfo/css, referer: http://192.168.6.251:90/
[Thu Feb 08 11:03:46.626403 2024] [authz_core:error] [pid 8552:tid 1248] [client 192.168.6.251:53293] AH01630: client denied by server configuration: E:/Kuldeep(Python)/Project/piinfo/css, referer: http://192.168.6.251:90/
[Thu Feb 08 11:03:46.626403 2024] [authz_core:error] [pid 8552:tid 1244] [client 192.168.6.251:53294] AH01630: client denied by server configuration: E:/Kuldeep(Python)/Project/piinfo/css, referer: http://192.168.6.251:90/
[Thu Feb 08 11:03:46.627446 2024] [authz_core:error] [pid 8552:tid 1236] [client 192.168.6.251:53295] AH01630: client denied by server configuration: E:/Kuldeep(Python)/Project/piinfo/css, referer: http://192.168.6.251:90/
[Thu Feb 08 11:03:46.629411 2024] [authz_core:error] [pid 8552:tid 1228] [client 192.168.6.251:53296] AH01630: client denied by server configuration: E:/Kuldeep(Python)/Project/piinfo/css, referer: http://192.168.6.251:90/
[Thu Feb 08 11:03:46.629411 2024] [authz_core:error] [pid 8552:tid 1220] [client 192.168.6.251:53297] AH01630: client denied by server configuration: E:/Kuldeep(Python)/Project/piinfo/css, referer: http://192.168.6.251:90/
[Thu Feb 08 11:03:46.630461 2024] [authz_core:error] [pid 8552:tid 1212] [client 192.168.6.251:53298] AH01630: client denied by server configuration: E:/Kuldeep(Python)/Project/piinfo/js, referer: http://192.168.6.251:90/
[Thu Feb 08 11:03:46.673408 2024] [authz_core:error] [pid 8552:tid 1212] [client 192.168.6.251:53298] AH01630: client denied by server configuration: E:/Kuldeep(Python)/Project/piinfo/img, referer: http://192.168.6.251:90/
[Thu Feb 08 11:03:46.682400 2024] [authz_core:error] [pid 8552:tid 1220] [client 192.168.6.251:53297] AH01630: client denied by server configuration: E:/Kuldeep(Python)/Project/piinfo/img, referer: http://192.168.6.251:90/
[Thu Feb 08 11:03:46.706405 2024] [authz_core:error] [pid 8552:tid 1220] [client 192.168.6.251:53297] AH01630: client denied by server configuration: E:/Kuldeep(Python)/Project/piinfo/img, referer: http://192.168.6.251:90/
[Thu Feb 08 11:03:46.707403 2024] [authz_core:error] [pid 8552:tid 1212] [client 192.168.6.251:53298] AH01630: client denied by server configuration: E:/Kuldeep(Python)/Project/piinfo/img, referer: http://192.168.6.251:90/
[Thu Feb 08 11:03:46.707403 2024] [authz_core:error] [pid 8552:tid 1228] [client 192.168.6.251:53296] AH01630: client denied by server configuration: E:/Kuldeep(Python)/Project/piinfo/vendor, referer: http://192.168.6.251:90/
[Thu Feb 08 11:03:46.708406 2024] [authz_core:error] [pid 8552:tid 1236] [client 192.168.6.251:53295] AH01630: client denied by server configuration: E:/Kuldeep(Python)/Project/piinfo/vendor, referer: http://192.168.6.251:90/
[Thu Feb 08 11:03:46.708406 2024] [authz_core:error] [pid 8552:tid 1244] [client 192.168.6.251:53294] AH01630: client denied by server configuration: E:/Kuldeep(Python)/Project/piinfo/vendor, referer: http://192.168.6.251:90/
[Thu Feb 08 11:03:46.708406 2024] [authz_core:error] [pid 8552:tid 1248] [client 192.168.6.251:53293] AH01630: client denied by server configuration: E:/Kuldeep(Python)/Project/piinfo/vendor, referer: http://192.168.6.251:90/
[Thu Feb 08 11:03:46.736404 2024] [authz_core:error] [pid 8552:tid 1248] [client 192.168.6.251:53293] AH01630: client denied by server configuration: E:/Kuldeep(Python)/Project/piinfo/js, referer: http://192.168.6.251:90/
[Thu Feb 08 11:03:46.736404 2024] [authz_core:error] [pid 8552:tid 1244] [client 192.168.6.251:53294] AH01630: client denied by server configuration: E:/Kuldeep(Python)/Project/piinfo/img, referer: http://192.168.6.251:90/
[Thu Feb 08 11:03:46.737402 2024] [authz_core:error] [pid 8552:tid 1236] [client 192.168.6.251:53295] AH01630: client denied by server configuration: E:/Kuldeep(Python)/Project/piinfo/img, referer: http://192.168.6.251:90/
[Thu Feb 08 11:03:46.737402 2024] [authz_core:error] [pid 8552:tid 1228] [client 192.168.6.251:53296] AH01630: client denied by server configuration: E:/Kuldeep(Python)/Project/piinfo/img, referer: http://192.168.6.251:90/
[Thu Feb 08 11:03:46.737402 2024] [authz_core:error] [pid 8552:tid 1212] [client 192.168.6.251:53298] AH01630: client denied by server configuration: E:/Kuldeep(Python)/Project/piinfo/img, referer: http://192.168.6.251:90/
[Thu Feb 08 11:03:46.737402 2024] [authz_core:error] [pid 8552:tid 1220] [client 192.168.6.251:53297] AH01630: client denied by server configuration: E:/Kuldeep(Python)/Project/piinfo/img, referer: http://192.168.6.251:90/
[Thu Feb 08 11:03:46.745401 2024] [authz_core:error] [pid 8552:tid 1220] [client 192.168.6.251:53297] AH01630: client denied by server configuration: E:/Kuldeep(Python)/Project/piinfo/img, referer: http://192.168.6.251:90/
[Thu Feb 08 11:03:46.750405 2024] [authz_core:error] [pid 8552:tid 1212] [client 192.168.6.251:53298] AH01630: client denied by server configuration: E:/Kuldeep(Python)/Project/piinfo/img, referer: http://192.168.6.251:90/
[Thu Feb 08 11:03:46.752430 2024] [authz_core:error] [pid 8552:tid 1228] [client 192.168.6.251:53296] AH01630: client denied by server configuration: E:/Kuldeep(Python)/Project/piinfo/img, referer: http://192.168.6.251:90/
[Thu Feb 08 11:03:46.753402 2024] [authz_core:error] [pid 8552:tid 1236] [client 192.168.6.251:53295] AH01630: client denied by server configuration: E:/Kuldeep(Python)/Project/piinfo/img, referer: http://192.168.6.251:90/
[Thu Feb 08 11:03:46.753402 2024] [authz_core:error] [pid 8552:tid 1244] [client 192.168.6.251:53294] AH01630: client denied by server configuration: E:/Kuldeep(Python)/Project/piinfo/img, referer: http://192.168.6.251:90/
[Thu Feb 08 11:03:46.753402 2024] [authz_core:error] [pid 8552:tid 1248] [client 192.168.6.251:53293] AH01630: client denied by server configuration: E:/Kuldeep(Python)/Project/piinfo/img, referer: http://192.168.6.251:90/
[Thu Feb 08 11:03:46.775438 2024] [authz_core:error] [pid 8552:tid 1212] [client 192.168.6.251:53298] AH01630: client denied by server configuration: E:/Kuldeep(Python)/Project/piinfo/img, referer: http://192.168.6.251:90/
[Thu Feb 08 11:03:46.776470 2024] [authz_core:error] [pid 8552:tid 1228] [client 192.168.6.251:53296] AH01630: client denied by server configuration: E:/Kuldeep(Python)/Project/piinfo/img, referer: http://192.168.6.251:90/
[Thu Feb 08 11:03:46.783403 2024] [authz_core:error] [pid 8552:tid 1248] [client 192.168.6.251:53293] AH01630: client denied by server configuration: E:/Kuldeep(Python)/Project/piinfo/img, referer: http://192.168.6.251:90/
[Thu Feb 08 11:03:46.783403 2024] [authz_core:error] [pid 8552:tid 1244] [client 192.168.6.251:53294] AH01630: client denied by server configuration: E:/Kuldeep(Python)/Project/piinfo/img, referer: http://192.168.6.251:90/
[Thu Feb 08 11:03:46.784483 2024] [authz_core:error] [pid 8552:tid 1220] [client 192.168.6.251:53297] AH01630: client denied by server configuration: E:/Kuldeep(Python)/Project/piinfo/img, referer: http://192.168.6.251:90/
[Thu Feb 08 11:03:46.784483 2024] [authz_core:error] [pid 8552:tid 1236] [client 192.168.6.251:53295] AH01630: client denied by server configuration: E:/Kuldeep(Python)/Project/piinfo/img, referer: http://192.168.6.251:90/
[Thu Feb 08 11:03:46.789457 2024] [authz_core:error] [pid 8552:tid 1244] [client 192.168.6.251:53294] AH01630: client denied by server configuration: E:/Kuldeep(Python)/Project/piinfo/img, referer: http://192.168.6.251:90/
[Thu Feb 08 11:03:50.094379 2024] [authz_core:error] [pid 8552:tid 1244] [client 192.168.6.251:53294] AH01630: client denied by server configuration: E:/Kuldeep(Python)/Project/piinfo/css, referer: http://192.168.6.251:90/
[Thu Feb 08 11:03:50.095379 2024] [authz_core:error] [pid 8552:tid 1236] [client 192.168.6.251:53295] AH01630: client denied by server configuration: E:/Kuldeep(Python)/Project/piinfo/js, referer: http://192.168.6.251:90/
[Thu Feb 08 11:03:50.096378 2024] [authz_core:error] [pid 8552:tid 1220] [client 192.168.6.251:53297] AH01630: client denied by server configuration: E:/Kuldeep(Python)/Project/piinfo/css, referer: http://192.168.6.251:90/
[Thu Feb 08 11:03:50.096378 2024] [authz_core:error] [pid 8552:tid 1248] [client 192.168.6.251:53293] AH01630: client denied by server configuration: E:/Kuldeep(Python)/Project/piinfo/vendor, referer: http://192.168.6.251:90/
[Thu Feb 08 11:03:50.096378 2024] [authz_core:error] [pid 8552:tid 1228] [client 192.168.6.251:53296] AH01630: client denied by server configuration: E:/Kuldeep(Python)/Project/piinfo/vendor, referer: http://192.168.6.251:90/
[Thu Feb 08 11:03:50.097377 2024] [authz_core:error] [pid 8552:tid 1212] [client 192.168.6.251:53298] AH01630: client denied by server configuration: E:/Kuldeep(Python)/Project/piinfo/vendor, referer: http://192.168.6.251:90/
[Thu Feb 08 11:03:50.103453 2024] [authz_core:error] [pid 8552:tid 1244] [client 192.168.6.251:53294] AH01630: client denied by server configuration: E:/Kuldeep(Python)/Project/piinfo/css, referer: http://192.168.6.251:90/
[Thu Feb 08 11:03:50.105395 2024] [authz_core:error] [pid 8552:tid 1236] [client 192.168.6.251:53295] AH01630: client denied by server configuration: E:/Kuldeep(Python)/Project/piinfo/css, referer: http://192.168.6.251:90/
[Thu Feb 08 11:03:50.105395 2024] [authz_core:error] [pid 8552:tid 1220] [client 192.168.6.251:53297] AH01630: client denied by server configuration: E:/Kuldeep(Python)/Project/piinfo/css, referer: http://192.168.6.251:90/
[Thu Feb 08 11:03:50.105395 2024] [authz_core:error] [pid 8552:tid 1248] [client 192.168.6.251:53293] AH01630: client denied by server configuration: E:/Kuldeep(Python)/Project/piinfo/css, referer: http://192.168.6.251:90/
[Thu Feb 08 11:03:50.106397 2024] [authz_core:error] [pid 8552:tid 1228] [client 192.168.6.251:53296] AH01630: client denied by server configuration: E:/Kuldeep(Python)/Project/piinfo/css, referer: http://192.168.6.251:90/
[Thu Feb 08 11:03:50.106397 2024] [authz_core:error] [pid 8552:tid 1212] [client 192.168.6.251:53298] AH01630: client denied by server configuration: E:/Kuldeep(Python)/Project/piinfo/css, referer: http://192.168.6.251:90/
[Thu Feb 08 11:03:50.112433 2024] [authz_core:error] [pid 8552:tid 1248] [client 192.168.6.251:53293] AH01630: client denied by server configuration: E:/Kuldeep(Python)/Project/piinfo/img, referer: http://192.168.6.251:90/
[Thu Feb 08 11:03:50.114380 2024] [authz_core:error] [pid 8552:tid 1212] [client 192.168.6.251:53298] AH01630: client denied by server configuration: E:/Kuldeep(Python)/Project/piinfo/img, referer: http://192.168.6.251:90/
[Thu Feb 08 11:03:50.140389 2024] [authz_core:error] [pid 8552:tid 1212] [client 192.168.6.251:53298] AH01630: client denied by server configuration: E:/Kuldeep(Python)/Project/piinfo/img, referer: http://192.168.6.251:90/
[Thu Feb 08 11:03:50.141433 2024] [authz_core:error] [pid 8552:tid 1248] [client 192.168.6.251:53293] AH01630: client denied by server configuration: E:/Kuldeep(Python)/Project/piinfo/img, referer: http://192.168.6.251:90/
[Thu Feb 08 11:03:50.141433 2024] [authz_core:error] [pid 8552:tid 1228] [client 192.168.6.251:53296] AH01630: client denied by server configuration: E:/Kuldeep(Python)/Project/piinfo/vendor, referer: http://192.168.6.251:90/
[Thu Feb 08 11:03:50.142398 2024] [authz_core:error] [pid 8552:tid 1220] [client 192.168.6.251:53297] AH01630: client denied by server configuration: E:/Kuldeep(Python)/Project/piinfo/vendor, referer: http://192.168.6.251:90/
[Thu Feb 08 11:03:50.142398 2024] [authz_core:error] [pid 8552:tid 1236] [client 192.168.6.251:53295] AH01630: client denied by server configuration: E:/Kuldeep(Python)/Project/piinfo/vendor, referer: http://192.168.6.251:90/
[Thu Feb 08 11:03:50.142398 2024] [authz_core:error] [pid 8552:tid 1244] [client 192.168.6.251:53294] AH01630: client denied by server configuration: E:/Kuldeep(Python)/Project/piinfo/vendor, referer: http://192.168.6.251:90/
[Thu Feb 08 11:03:50.176379 2024] [authz_core:error] [pid 8552:tid 1244] [client 192.168.6.251:53294] AH01630: client denied by server configuration: E:/Kuldeep(Python)/Project/piinfo/js, referer: http://192.168.6.251:90/
[Thu Feb 08 11:03:50.177386 2024] [authz_core:error] [pid 8552:tid 1236] [client 192.168.6.251:53295] AH01630: client denied by server configuration: E:/Kuldeep(Python)/Project/piinfo/img, referer: http://192.168.6.251:90/
[Thu Feb 08 11:03:50.179379 2024] [authz_core:error] [pid 8552:tid 1220] [client 192.168.6.251:53297] AH01630: client denied by server configuration: E:/Kuldeep(Python)/Project/piinfo/img, referer: http://192.168.6.251:90/
[Thu Feb 08 11:03:50.179379 2024] [authz_core:error] [pid 8552:tid 1228] [client 192.168.6.251:53296] AH01630: client denied by server configuration: E:/Kuldeep(Python)/Project/piinfo/img, referer: http://192.168.6.251:90/
[Thu Feb 08 11:03:50.180379 2024] [authz_core:error] [pid 8552:tid 1248] [client 192.168.6.251:53293] AH01630: client denied by server configuration: E:/Kuldeep(Python)/Project/piinfo/img, referer: http://192.168.6.251:90/
[Thu Feb 08 11:03:50.180379 2024] [authz_core:error] [pid 8552:tid 1212] [client 192.168.6.251:53298] AH01630: client denied by server configuration: E:/Kuldeep(Python)/Project/piinfo/img, referer: http://192.168.6.251:90/
[Thu Feb 08 11:03:50.218399 2024] [authz_core:error] [pid 8552:tid 1248] [client 192.168.6.251:53293] AH01630: client denied by server configuration: E:/Kuldeep(Python)/Project/piinfo/img, referer: http://192.168.6.251:90/
[Thu Feb 08 11:03:50.218399 2024] [authz_core:error] [pid 8552:tid 1212] [client 192.168.6.251:53298] AH01630: client denied by server configuration: E:/Kuldeep(Python)/Project/piinfo/img, referer: http://192.168.6.251:90/
[Thu Feb 08 11:03:50.222386 2024] [authz_core:error] [pid 8552:tid 1228] [client 192.168.6.251:53296] AH01630: client denied by server configuration: E:/Kuldeep(Python)/Project/piinfo/img, referer: http://192.168.6.251:90/
[Thu Feb 08 11:03:50.222386 2024] [authz_core:error] [pid 8552:tid 1220] [client 192.168.6.251:53297] AH01630: client denied by server configuration: E:/Kuldeep(Python)/Project/piinfo/img, referer: http://192.168.6.251:90/
[Thu Feb 08 11:03:50.222386 2024] [authz_core:error] [pid 8552:tid 1236] [client 192.168.6.251:53295] AH01630: client denied by server configuration: E:/Kuldeep(Python)/Project/piinfo/img, referer: http://192.168.6.251:90/
[Thu Feb 08 11:03:50.222386 2024] [authz_core:error] [pid 8552:tid 1244] [client 192.168.6.251:53294] AH01630: client denied by server configuration: E:/Kuldeep(Python)/Project/piinfo/img, referer: http://192.168.6.251:90/
[Thu Feb 08 11:03:50.230377 2024] [authz_core:error] [pid 8552:tid 1236] [client 192.168.6.251:53295] AH01630: client denied by server configuration: E:/Kuldeep(Python)/Project/piinfo/img, referer: http://192.168.6.251:90/
[Thu Feb 08 11:03:50.230377 2024] [authz_core:error] [pid 8552:tid 1244] [client 192.168.6.251:53294] AH01630: client denied by server configuration: E:/Kuldeep(Python)/Project/piinfo/img, referer: http://192.168.6.251:90/
[Thu Feb 08 11:03:50.234384 2024] [authz_core:error] [pid 8552:tid 1220] [client 192.168.6.251:53297] AH01630: client denied by server configuration: E:/Kuldeep(Python)/Project/piinfo/img, referer: http://192.168.6.251:90/
[Thu Feb 08 11:03:50.235383 2024] [authz_core:error] [pid 8552:tid 1228] [client 192.168.6.251:53296] AH01630: client denied by server configuration: E:/Kuldeep(Python)/Project/piinfo/img, referer: http://192.168.6.251:90/
[Thu Feb 08 11:03:50.236377 2024] [authz_core:error] [pid 8552:tid 1212] [client 192.168.6.251:53298] AH01630: client denied by server configuration: E:/Kuldeep(Python)/Project/piinfo/img, referer: http://192.168.6.251:90/
[Thu Feb 08 11:03:50.236377 2024] [authz_core:error] [pid 8552:tid 1248] [client 192.168.6.251:53293] AH01630: client denied by server configuration: E:/Kuldeep(Python)/Project/piinfo/img, referer: http://192.168.6.251:90/
[Thu Feb 08 11:03:50.239384 2024] [authz_core:error] [pid 8552:tid 1220] [client 192.168.6.251:53297] AH01630: client denied by server configuration: E:/Kuldeep(Python)/Project/piinfo/img, referer: http://192.168.6.251:90/
[Thu Feb 08 11:04:07.710264 2024] [authz_core:error] [pid 19648:tid 1248] [client 192.168.6.251:53304] AH01630: client denied by server configuration: E:/Kuldeep(Python)/Project/piinfo/staticfilescss, referer: http://192.168.6.251:90/
[Thu Feb 08 11:04:07.711260 2024] [authz_core:error] [pid 19648:tid 1244] [client 192.168.6.251:53305] AH01630: client denied by server configuration: E:/Kuldeep(Python)/Project/piinfo/staticfilescss, referer: http://192.168.6.251:90/
[Thu Feb 08 11:04:07.714262 2024] [authz_core:error] [pid 19648:tid 1240] [client 192.168.6.251:53306] AH01630: client denied by server configuration: E:/Kuldeep(Python)/Project/piinfo/staticfilesvendor, referer: http://192.168.6.251:90/
[Thu Feb 08 11:04:07.714262 2024] [authz_core:error] [pid 19648:tid 1224] [client 192.168.6.251:53307] AH01630: client denied by server configuration: E:/Kuldeep(Python)/Project/piinfo/staticfilesvendor, referer: http://192.168.6.251:90/
[Thu Feb 08 11:04:07.715261 2024] [authz_core:error] [pid 19648:tid 1212] [client 192.168.6.251:53309] AH01630: client denied by server configuration: E:/Kuldeep(Python)/Project/piinfo/staticfilescss, referer: http://192.168.6.251:90/
[Thu Feb 08 11:04:07.715261 2024] [authz_core:error] [pid 19648:tid 1220] [client 192.168.6.251:53308] AH01630: client denied by server configuration: E:/Kuldeep(Python)/Project/piinfo/staticfilesvendor, referer: http://192.168.6.251:90/
[Thu Feb 08 11:04:07.717261 2024] [authz_core:error] [pid 19648:tid 1248] [client 192.168.6.251:53304] AH01630: client denied by server configuration: E:/Kuldeep(Python)/Project/piinfo/staticfilescss, referer: http://192.168.6.251:90/
[Thu Feb 08 11:04:07.717261 2024] [authz_core:error] [pid 19648:tid 1244] [client 192.168.6.251:53305] AH01630: client denied by server configuration: E:/Kuldeep(Python)/Project/piinfo/staticfilescss, referer: http://192.168.6.251:90/
[Thu Feb 08 11:04:07.720273 2024] [authz_core:error] [pid 19648:tid 1224] [client 192.168.6.251:53307] AH01630: client denied by server configuration: E:/Kuldeep(Python)/Project/piinfo/staticfilescss, referer: http://192.168.6.251:90/
[Thu Feb 08 11:04:07.722258 2024] [authz_core:error] [pid 19648:tid 1240] [client 192.168.6.251:53306] AH01630: client denied by server configuration: E:/Kuldeep(Python)/Project/piinfo/staticfilescss, referer: http://192.168.6.251:90/
[Thu Feb 08 11:04:07.722258 2024] [authz_core:error] [pid 19648:tid 1212] [client 192.168.6.251:53309] AH01630: client denied by server configuration: E:/Kuldeep(Python)/Project/piinfo/staticfilescss, referer: http://192.168.6.251:90/
[Thu Feb 08 11:04:07.724276 2024] [authz_core:error] [pid 19648:tid 1220] [client 192.168.6.251:53308] AH01630: client denied by server configuration: E:/Kuldeep(Python)/Project/piinfo/staticfilesjs, referer: http://192.168.6.251:90/
[Thu Feb 08 11:04:07.728261 2024] [authz_core:error] [pid 19648:tid 1224] [client 192.168.6.251:53307] AH01630: client denied by server configuration: E:/Kuldeep(Python)/Project/piinfo/staticfilesimg, referer: http://192.168.6.251:90/
[Thu Feb 08 11:04:07.730278 2024] [authz_core:error] [pid 19648:tid 1212] [client 192.168.6.251:53309] AH01630: client denied by server configuration: E:/Kuldeep(Python)/Project/piinfo/staticfilesimg, referer: http://192.168.6.251:90/
[Thu Feb 08 11:04:07.754257 2024] [authz_core:error] [pid 19648:tid 1220] [client 192.168.6.251:53308] AH01630: client denied by server configuration: E:/Kuldeep(Python)/Project/piinfo/staticfilesimg, referer: http://192.168.6.251:90/
[Thu Feb 08 11:04:07.755256 2024] [authz_core:error] [pid 19648:tid 1212] [client 192.168.6.251:53309] AH01630: client denied by server configuration: E:/Kuldeep(Python)/Project/piinfo/staticfilesimg, referer: http://192.168.6.251:90/
[Thu Feb 08 11:04:07.755256 2024] [authz_core:error] [pid 19648:tid 1224] [client 192.168.6.251:53307] AH01630: client denied by server configuration: E:/Kuldeep(Python)/Project/piinfo/staticfilesvendor, referer: http://192.168.6.251:90/
[Thu Feb 08 11:04:07.755256 2024] [authz_core:error] [pid 19648:tid 1240] [client 192.168.6.251:53306] AH01630: client denied by server configuration: E:/Kuldeep(Python)/Project/piinfo/staticfilesvendor, referer: http://192.168.6.251:90/
[Thu Feb 08 11:04:07.761255 2024] [authz_core:error] [pid 19648:tid 1244] [client 192.168.6.251:53305] AH01630: client denied by server configuration: E:/Kuldeep(Python)/Project/piinfo/staticfilesvendor, referer: http://192.168.6.251:90/
[Thu Feb 08 11:04:07.762254 2024] [authz_core:error] [pid 19648:tid 1248] [client 192.168.6.251:53304] AH01630: client denied by server configuration: E:/Kuldeep(Python)/Project/piinfo/staticfilesvendor, referer: http://192.168.6.251:90/
[Thu Feb 08 11:04:07.792255 2024] [authz_core:error] [pid 19648:tid 1244] [client 192.168.6.251:53305] AH01630: client denied by server configuration: E:/Kuldeep(Python)/Project/piinfo/staticfilesjs, referer: http://192.168.6.251:90/
[Thu Feb 08 11:04:07.792255 2024] [authz_core:error] [pid 19648:tid 1240] [client 192.168.6.251:53306] AH01630: client denied by server configuration: E:/Kuldeep(Python)/Project/piinfo/staticfilesimg, referer: http://192.168.6.251:90/
[Thu Feb 08 11:04:07.792255 2024] [authz_core:error] [pid 19648:tid 1224] [client 192.168.6.251:53307] AH01630: client denied by server configuration: E:/Kuldeep(Python)/Project/piinfo/staticfilesimg, referer: http://192.168.6.251:90/
[Thu Feb 08 11:04:07.793256 2024] [authz_core:error] [pid 19648:tid 1248] [client 192.168.6.251:53304] AH01630: client denied by server configuration: E:/Kuldeep(Python)/Project/piinfo/staticfilesimg, referer: http://192.168.6.251:90/
[Thu Feb 08 11:04:07.794255 2024] [authz_core:error] [pid 19648:tid 1212] [client 192.168.6.251:53309] AH01630: client denied by server configuration: E:/Kuldeep(Python)/Project/piinfo/staticfilesimg, referer: http://192.168.6.251:90/
[Thu Feb 08 11:04:07.794255 2024] [authz_core:error] [pid 19648:tid 1220] [client 192.168.6.251:53308] AH01630: client denied by server configuration: E:/Kuldeep(Python)/Project/piinfo/staticfilesimg, referer: http://192.168.6.251:90/
[Thu Feb 08 11:04:07.800261 2024] [authz_core:error] [pid 19648:tid 1244] [client 192.168.6.251:53305] AH01630: client denied by server configuration: E:/Kuldeep(Python)/Project/piinfo/staticfilesimg, referer: http://192.168.6.251:90/
[Thu Feb 08 11:04:07.801282 2024] [authz_core:error] [pid 19648:tid 1240] [client 192.168.6.251:53306] AH01630: client denied by server configuration: E:/Kuldeep(Python)/Project/piinfo/staticfilesimg, referer: http://192.168.6.251:90/
[Thu Feb 08 11:04:07.802254 2024] [authz_core:error] [pid 19648:tid 1224] [client 192.168.6.251:53307] AH01630: client denied by server configuration: E:/Kuldeep(Python)/Project/piinfo/staticfilesimg, referer: http://192.168.6.251:90/
[Thu Feb 08 11:04:07.803259 2024] [authz_core:error] [pid 19648:tid 1248] [client 192.168.6.251:53304] AH01630: client denied by server configuration: E:/Kuldeep(Python)/Project/piinfo/staticfilesimg, referer: http://192.168.6.251:90/
[Thu Feb 08 11:04:07.803259 2024] [authz_core:error] [pid 19648:tid 1212] [client 192.168.6.251:53309] AH01630: client denied by server configuration: E:/Kuldeep(Python)/Project/piinfo/staticfilesimg, referer: http://192.168.6.251:90/
[Thu Feb 08 11:04:07.803259 2024] [authz_core:error] [pid 19648:tid 1220] [client 192.168.6.251:53308] AH01630: client denied by server configuration: E:/Kuldeep(Python)/Project/piinfo/staticfilesimg, referer: http://192.168.6.251:90/
[Thu Feb 08 11:04:07.814261 2024] [authz_core:error] [pid 19648:tid 1240] [client 192.168.6.251:53306] AH01630: client denied by server configuration: E:/Kuldeep(Python)/Project/piinfo/staticfilesimg, referer: http://192.168.6.251:90/
[Thu Feb 08 11:04:07.814261 2024] [authz_core:error] [pid 19648:tid 1224] [client 192.168.6.251:53307] AH01630: client denied by server configuration: E:/Kuldeep(Python)/Project/piinfo/staticfilesimg, referer: http://192.168.6.251:90/
[Thu Feb 08 11:04:07.814261 2024] [authz_core:error] [pid 19648:tid 1244] [client 192.168.6.251:53305] AH01630: client denied by server configuration: E:/Kuldeep(Python)/Project/piinfo/staticfilesimg, referer: http://192.168.6.251:90/
[Thu Feb 08 11:04:07.829275 2024] [authz_core:error] [pid 19648:tid 1220] [client 192.168.6.251:53308] AH01630: client denied by server configuration: E:/Kuldeep(Python)/Project/piinfo/staticfilesimg, referer: http://192.168.6.251:90/
[Thu Feb 08 11:04:07.829275 2024] [authz_core:error] [pid 19648:tid 1212] [client 192.168.6.251:53309] AH01630: client denied by server configuration: E:/Kuldeep(Python)/Project/piinfo/staticfilesimg, referer: http://192.168.6.251:90/
[Thu Feb 08 11:04:07.829275 2024] [authz_core:error] [pid 19648:tid 1248] [client 192.168.6.251:53304] AH01630: client denied by server configuration: E:/Kuldeep(Python)/Project/piinfo/staticfilesimg, referer: http://192.168.6.251:90/
[Thu Feb 08 11:04:07.836254 2024] [authz_core:error] [pid 19648:tid 1244] [client 192.168.6.251:53305] AH01630: client denied by server configuration: E:/Kuldeep(Python)/Project/piinfo/staticfilesimg, referer: http://192.168.6.251:90/
[Thu Feb 08 11:04:39.650032 2024] [authz_core:error] [pid 12896:tid 1248] [client 192.168.6.251:53310] AH01630: client denied by server configuration: E:/Kuldeep(Python)/Project/piinfo/staticcss, referer: http://192.168.6.251:90/
[Thu Feb 08 11:04:39.653034 2024] [authz_core:error] [pid 12896:tid 1244] [client 192.168.6.251:53311] AH01630: client denied by server configuration: E:/Kuldeep(Python)/Project/piinfo/staticcss, referer: http://192.168.6.251:90/
[Thu Feb 08 11:04:39.657045 2024] [authz_core:error] [pid 12896:tid 1240] [client 192.168.6.251:53312] AH01630: client denied by server configuration: E:/Kuldeep(Python)/Project/piinfo/staticvendor, referer: http://192.168.6.251:90/
[Thu Feb 08 11:04:39.657045 2024] [authz_core:error] [pid 12896:tid 1232] [client 192.168.6.251:53313] AH01630: client denied by server configuration: E:/Kuldeep(Python)/Project/piinfo/staticvendor, referer: http://192.168.6.251:90/
[Thu Feb 08 11:04:39.657045 2024] [authz_core:error] [pid 12896:tid 1228] [client 192.168.6.251:53314] AH01630: client denied by server configuration: E:/Kuldeep(Python)/Project/piinfo/staticvendor, referer: http://192.168.6.251:90/
[Thu Feb 08 11:04:39.657045 2024] [authz_core:error] [pid 12896:tid 1220] [client 192.168.6.251:53315] AH01630: client denied by server configuration: E:/Kuldeep(Python)/Project/piinfo/staticcss, referer: http://192.168.6.251:90/
[Thu Feb 08 11:04:39.658033 2024] [authz_core:error] [pid 12896:tid 1248] [client 192.168.6.251:53310] AH01630: client denied by server configuration: E:/Kuldeep(Python)/Project/piinfo/staticcss, referer: http://192.168.6.251:90/
[Thu Feb 08 11:04:39.659033 2024] [authz_core:error] [pid 12896:tid 1244] [client 192.168.6.251:53311] AH01630: client denied by server configuration: E:/Kuldeep(Python)/Project/piinfo/staticcss, referer: http://192.168.6.251:90/
[Thu Feb 08 11:04:39.663031 2024] [authz_core:error] [pid 12896:tid 1240] [client 192.168.6.251:53312] AH01630: client denied by server configuration: E:/Kuldeep(Python)/Project/piinfo/staticcss, referer: http://192.168.6.251:90/
[Thu Feb 08 11:04:39.665032 2024] [authz_core:error] [pid 12896:tid 1232] [client 192.168.6.251:53313] AH01630: client denied by server configuration: E:/Kuldeep(Python)/Project/piinfo/staticcss, referer: http://192.168.6.251:90/
[Thu Feb 08 11:04:39.665032 2024] [authz_core:error] [pid 12896:tid 1228] [client 192.168.6.251:53314] AH01630: client denied by server configuration: E:/Kuldeep(Python)/Project/piinfo/staticcss, referer: http://192.168.6.251:90/
[Thu Feb 08 11:04:39.666032 2024] [authz_core:error] [pid 12896:tid 1220] [client 192.168.6.251:53315] AH01630: client denied by server configuration: E:/Kuldeep(Python)/Project/piinfo/staticjs, referer: http://192.168.6.251:90/
[Thu Feb 08 11:04:39.668032 2024] [authz_core:error] [pid 12896:tid 1240] [client 192.168.6.251:53312] AH01630: client denied by server configuration: E:/Kuldeep(Python)/Project/piinfo/staticimg, referer: http://192.168.6.251:90/
[Thu Feb 08 11:04:39.669033 2024] [authz_core:error] [pid 12896:tid 1244] [client 192.168.6.251:53311] AH01630: client denied by server configuration: E:/Kuldeep(Python)/Project/piinfo/staticimg, referer: http://192.168.6.251:90/
[Thu Feb 08 11:04:39.694033 2024] [authz_core:error] [pid 12896:tid 1244] [client 192.168.6.251:53311] AH01630: client denied by server configuration: E:/Kuldeep(Python)/Project/piinfo/staticvendor, referer: http://192.168.6.251:90/
[Thu Feb 08 11:04:39.694033 2024] [authz_core:error] [pid 12896:tid 1240] [client 192.168.6.251:53312] AH01630: client denied by server configuration: E:/Kuldeep(Python)/Project/piinfo/staticimg, referer: http://192.168.6.251:90/
[Thu Feb 08 11:04:39.694033 2024] [authz_core:error] [pid 12896:tid 1220] [client 192.168.6.251:53315] AH01630: client denied by server configuration: E:/Kuldeep(Python)/Project/piinfo/staticimg, referer: http://192.168.6.251:90/
[Thu Feb 08 11:04:39.695049 2024] [authz_core:error] [pid 12896:tid 1228] [client 192.168.6.251:53314] AH01630: client denied by server configuration: E:/Kuldeep(Python)/Project/piinfo/staticvendor, referer: http://192.168.6.251:90/
[Thu Feb 08 11:04:39.695049 2024] [authz_core:error] [pid 12896:tid 1232] [client 192.168.6.251:53313] AH01630: client denied by server configuration: E:/Kuldeep(Python)/Project/piinfo/staticvendor, referer: http://192.168.6.251:90/
[Thu Feb 08 11:04:39.696033 2024] [authz_core:error] [pid 12896:tid 1248] [client 192.168.6.251:53310] AH01630: client denied by server configuration: E:/Kuldeep(Python)/Project/piinfo/staticvendor, referer: http://192.168.6.251:90/
[Thu Feb 08 11:04:39.737031 2024] [authz_core:error] [pid 12896:tid 1248] [client 192.168.6.251:53310] AH01630: client denied by server configuration: E:/Kuldeep(Python)/Project/piinfo/staticjs, referer: http://192.168.6.251:90/
[Thu Feb 08 11:04:39.737031 2024] [authz_core:error] [pid 12896:tid 1232] [client 192.168.6.251:53313] AH01630: client denied by server configuration: E:/Kuldeep(Python)/Project/piinfo/staticimg, referer: http://192.168.6.251:90/
[Thu Feb 08 11:04:39.738074 2024] [authz_core:error] [pid 12896:tid 1228] [client 192.168.6.251:53314] AH01630: client denied by server configuration: E:/Kuldeep(Python)/Project/piinfo/staticimg, referer: http://192.168.6.251:90/
[Thu Feb 08 11:04:39.738074 2024] [authz_core:error] [pid 12896:tid 1220] [client 192.168.6.251:53315] AH01630: client denied by server configuration: E:/Kuldeep(Python)/Project/piinfo/staticimg, referer: http://192.168.6.251:90/
[Thu Feb 08 11:04:39.738074 2024] [authz_core:error] [pid 12896:tid 1240] [client 192.168.6.251:53312] AH01630: client denied by server configuration: E:/Kuldeep(Python)/Project/piinfo/staticimg, referer: http://192.168.6.251:90/
[Thu Feb 08 11:04:39.738074 2024] [authz_core:error] [pid 12896:tid 1244] [client 192.168.6.251:53311] AH01630: client denied by server configuration: E:/Kuldeep(Python)/Project/piinfo/staticimg, referer: http://192.168.6.251:90/
[Thu Feb 08 11:04:39.747031 2024] [authz_core:error] [pid 12896:tid 1244] [client 192.168.6.251:53311] AH01630: client denied by server configuration: E:/Kuldeep(Python)/Project/piinfo/staticimg, referer: http://192.168.6.251:90/
[Thu Feb 08 11:04:39.772031 2024] [authz_core:error] [pid 12896:tid 1240] [client 192.168.6.251:53312] AH01630: client denied by server configuration: E:/Kuldeep(Python)/Project/piinfo/staticimg, referer: http://192.168.6.251:90/
[Thu Feb 08 11:04:39.774080 2024] [authz_core:error] [pid 12896:tid 1220] [client 192.168.6.251:53315] AH01630: client denied by server configuration: E:/Kuldeep(Python)/Project/piinfo/staticimg, referer: http://192.168.6.251:90/
[Thu Feb 08 11:04:39.774080 2024] [authz_core:error] [pid 12896:tid 1228] [client 192.168.6.251:53314] AH01630: client denied by server configuration: E:/Kuldeep(Python)/Project/piinfo/staticimg, referer: http://192.168.6.251:90/
[Thu Feb 08 11:04:39.774080 2024] [authz_core:error] [pid 12896:tid 1232] [client 192.168.6.251:53313] AH01630: client denied by server configuration: E:/Kuldeep(Python)/Project/piinfo/staticimg, referer: http://192.168.6.251:90/
[Thu Feb 08 11:04:39.775029 2024] [authz_core:error] [pid 12896:tid 1248] [client 192.168.6.251:53310] AH01630: client denied by server configuration: E:/Kuldeep(Python)/Project/piinfo/staticimg, referer: http://192.168.6.251:90/
[Thu Feb 08 11:04:39.780032 2024] [authz_core:error] [pid 12896:tid 1220] [client 192.168.6.251:53315] AH01630: client denied by server configuration: E:/Kuldeep(Python)/Project/piinfo/staticimg, referer: http://192.168.6.251:90/
[Thu Feb 08 11:04:39.781060 2024] [authz_core:error] [pid 12896:tid 1232] [client 192.168.6.251:53313] AH01630: client denied by server configuration: E:/Kuldeep(Python)/Project/piinfo/staticimg, referer: http://192.168.6.251:90/
[Thu Feb 08 11:04:39.786030 2024] [authz_core:error] [pid 12896:tid 1248] [client 192.168.6.251:53310] AH01630: client denied by server configuration: E:/Kuldeep(Python)/Project/piinfo/staticimg, referer: http://192.168.6.251:90/
[Thu Feb 08 11:04:39.786030 2024] [authz_core:error] [pid 12896:tid 1228] [client 192.168.6.251:53314] AH01630: client denied by server configuration: E:/Kuldeep(Python)/Project/piinfo/staticimg, referer: http://192.168.6.251:90/
[Thu Feb 08 11:04:39.787130 2024] [authz_core:error] [pid 12896:tid 1240] [client 192.168.6.251:53312] AH01630: client denied by server configuration: E:/Kuldeep(Python)/Project/piinfo/staticimg, referer: http://192.168.6.251:90/
[Thu Feb 08 11:04:39.787130 2024] [authz_core:error] [pid 12896:tid 1244] [client 192.168.6.251:53311] AH01630: client denied by server configuration: E:/Kuldeep(Python)/Project/piinfo/staticimg, referer: http://192.168.6.251:90/
[Thu Feb 08 11:04:39.806090 2024] [authz_core:error] [pid 12896:tid 1248] [client 192.168.6.251:53310] AH01630: client denied by server configuration: E:/Kuldeep(Python)/Project/piinfo/staticimg, referer: http://192.168.6.251:90/
